Workbook

Sheet X-1
AE1: ZONASI | AF1: 0097062522 | AG1: 20527197 | AH1: ACHMAD RIZQON JANUAR | AI1: L
AE2: ZONASI | AF2: 0093351007 | AG2: 20583363 | AH2: Adintya Djasmine Aulia | AI2: P
AE3: ZONASI | AF3: 0065403876 | AG3: 20527197 | AH3: AMIEN FIRDAUS | AI3: L
A4: Tahun Pelajaran 2026 / 2027 | AE4: RAPORT | AF4: 0099607321 | AG4: 20527180 | AH4: AUFA FIKRI FIRDAUS | AI4: L
AE5: ZONASI | AF5: 0087421628 | AG5: 20527202 | AH5: Bagas Mahardika Putra | AI5: L
AE6: ZONASI | AF6: 0088629626 | AG6: 20527180 | AH6: BELVA PRATISARA DIYAS | AI6: P
A7: No | B7: NIS | C7: NISN | D7: Nama Siswa | E7: L/P | F7: Wali Kelas : | I7: SUFIANATUL NINGSIH, S.Pd | T7: NIP : | V7: 198901172023212000 | AE7: RAPORT | AF7: 0092639463 | AG7: 20527197 | AH7: DAFFA MAULIDAN PUTRA LAKSONO | AI7: L
F8: Tanggal | AE8: KIP | AF8: 0085034059 | AG8: 20566545 | AH8: Desvita Anggraini | AI8: P
AE9: RAPORT | AF9: 0082864028 | AG9: 20527193 | AH9: Dirgantara Fairuz Iftikhori | AI9: L
A10: 1 | B10: 15325 | C10: 0108174028 | D10: AFIFAH | E10: P | AE10: RAPORT | AF10: 0082847597 | AG10: 20527180 | AH10: FIYHIMA AINANI TAJRIYAN | AI10: P | AJ10: =UPPER(D10) -> AFIFAH | AZ10: 0108174028 | BA10: AFIFAH | BB10: P | BC10: SMP negeri 8 pamekasan | BD10: 90.49 | BE10: 63.34 | BF10: 79.63 | BG10: A | BH10: - | BJ10: 15325 | BK10: 0108174028 | BL10: AFIFAH | BM10: A01
A11: 2 | B11: 15337 | C11: 0107626584 | D11: AISYAH FAYYAD MAHIRA EFFENDI | E11: P | AE11: AKDMK | AF11: 0093695374 | AG11: 20528609 | AH11: GILANG ALFAHRIZI | AI11: L | AJ11: =UPPER(D11) -> AISYAH FAYYAD MAHIRA EFFENDI | AZ11: 0107626584 | BA11: AISYAH FAYYAD MAHIRA EFFENDI | BB11: P | BC11: SMP NEGERI 2 PAMEKASAN | BD11: 90.51 | BE11: 65.00 | BF11: 80.31 | BG11: A | BH11: - | BJ11: 15337 | BK11: 0107626584 | BL11: AISYAH FAYYAD MAHIRA EFFENDI | BM11: A02
A12: 3 | B12: 15342 | C12: 0113992796 | D12: ALFINA LAILY | E12: P | AE12: AKDMK | AF12: 0088601519 | AG12: 20583410 | AH12: HILMAN FUADI | AI12: L | AJ12: =UPPER(D12) -> ALFINA LAILY | AZ12: 0113992796 | BA12: ALFINA LAILY | BB12: P | BC12: SMPN 1 PAMEKASAN | BD12: 90.22 | BE12: 75 | BF12: 84.14 | BG12: A | BH12: (-) | BJ12: 15342 | BK12: 0113992796 | BL12: ALFINA LAILY | BM12: A03
A13: 4 | B13: 15348 | C13: 3106424990 | D13: ALVINO DWI ANDIKA | E13: L | AE13: KIP | AF13: 0092932213 | AG13: 20527185 | AH13: ISWAHYUDI ARIF SETIAWAN | AI13: L | AJ13: =UPPER(D13) -> ALVINO DWI ANDIKA | AZ13: 3106424990 | BA13: ALVINO DWI ANDIKA | BB13: L | BC13: SMP Negeri 5 Pamekasan | BD13: 86.54 | BE13: 80.00 | BF13: 83.92 | BG13: A | BH13: -Mendali perunggu pada lomba KMSI se kabupaten tahun 2023 -Mendali perak pada lomba KMSI se provinsi tahun 2023 -Mendali perunggu pada lomba KMSI se kabupaten tahun 2024 | BJ13: 15348 | BK13: 3106424990 | BL13: ALVINO DWI ANDIKA | BM13: A04
A14: 5 | B14: 15349 | C14: 0112191144 | D14: ALYA AZZAHRA HIDAYAT | E14: P | AE14: ZONASI | AF14: 0083224313 | AG14: 20527197 | AH14: LATIFA SALMA | AI14: P | AJ14: =UPPER(D14) -> ALYA AZZAHRA HIDAYAT | AZ14: 0112191144 | BA14: ALYA AZZAHRA HIDAYAT | BB14: P | BC14: SMPN 2 PAMEKASAN | BD14: 86.89 | BE14: 60 | BF14: 76.13 | BG14: A | BH14: - | BJ14: 15349 | BK14: 0112191144 | BL14: ALYA AZZAHRA HIDAYAT | BM14: A05
A15: 6 | B15: 15350 | C15: 0114950171 | D15: ALYSA PUTRI PUSTIKA | E15: P | AE15: RAPORT | AF15: 0098566431 | AG15: 20527197 | AH15: MARSYANAIRA VANESA CELIA | AI15: P | AJ15: =UPPER(D15) -> ALYSA PUTRI PUSTIKA | AZ15: 0114950171 | BA15: ALYSA PUTRI PUSTIKA | BB15: P | BC15: SMPN 1 PADEMAWU | BD15: 83.31 | BE15: 65 | BF15: 75.99 | BG15: A | BH15: - | BJ15: 15350 | BK15: 0114950171 | BL15: ALYSA PUTRI PUSTIKA | BM15: A06
A16: 7 | B16: 15374 | C16: 0114388600 | D16: AYEM SULISTYONING TYAS | E16: P | AE16: RAPORT | AF16: 0099315210 | AG16: 20528625 | AH16: MIFTAHUL FADLI DANIAR | AI16: L | AJ16: =UPPER(D16) -> AYEM SULISTYONING TYAS | AZ16: 0114388600 | BA16: AYEM SULISTYONING TYAS | BB16: P | BC16: SMP NEGERI 2 PADEMAWU | BD16: 91.00 | BE16: 60.00 | BF16: 78.60 | BG16: A | BH16: Juara 1 dari kelas 7-9 Penghargaan tahfidz juz 30 dan juz 1 | BJ16: 15374 | BK16: 0114388600 | BL16: AYEM SULISTYONING TYAS | BM16: A07
A17: 8 | B17: 15375 | C17: 0116997238 | D17: AZALIA MAHARATU SANTOSO | E17: P | AE17: ZONASI | AF17: 0099559196 | AG17: 20527180 | AH17: MOH FIKI ALAN FAJRI | AI17: L | AJ17: =UPPER(D17) -> AZALIA MAHARATU SANTOSO | AZ17: 0116997238 | BA17: AZALIA MAHARATU SANTOSO | BB17: P | BC17: SMPN 1 PAMEKASAN | BD17: 83.03 | BE17: 51.67 | BF17: 70.49 | BG17: A | BH17: - | BJ17: 15375 | BK17: 0116997238 | BL17: AZALIA MAHARATU SANTOSO | BM17: A08
A18: 9 | B18: 15378 | C18: 0119050789 | D18: AZZAHRA MUDANINGRUM WIBOWO | E18: P | AE18: ZONASI | AF18: 0087638152 | AG18: 20527197 | AH18: MOH RAFLI AMIRUL IMAN | AI18: L | AJ18: =UPPER(D18) -> AZZAHRA MUDANINGRUM WIBOWO | AZ18: 0119050789 | BA18: AZZAHRA MUDANINGRUM WIBOWO | BB18: P | BC18: SLTP Negeri 1 Pamekasan | BD18: 82.89 | BE18: 55.00 | BF18: 71.73 | BG18: A | BH18: - | BJ18: 15378 | BK18: 0119050789 | BL18: AZZAHRA MUDANINGRUM WIBOWO | BM18: A09
A19: 10 | B19: 15385 | C19: 0117465252 | D19: BERLIANA ARANIYAH SUBAIRI | E19: P | AE19: ZONASI | AF19: 0087990908 | AG19: 20527197 | AH19: MOH RISHAL HIDAYAT | AI19: L | AJ19: =UPPER(D19) -> BERLIANA ARANIYAH SUBAIRI | AZ19: 0117465252 | BA19: BERLIANA ARANIYAH SUBAIRI | BB19: P | BC19: SMP NEGERI 2 PAMEKASAN | BD19: 85.00 | BE19: 63.33 | BF19: 76.33 | BG19: A | BH19: - | BJ19: 15385 | BK19: 0117465252 | BL19: BERLIANA ARANIYAH SUBAIRI | BM19: A10
A20: 11 | B20: 15398 | C20: 0102397601 | D20: DAFA KANA SUWANDI | E20: L | AE20: ZONASI | AF20: 0096039518 | AG20: 20527197 | AH20: MOHMASYRUR | AI20: L | AJ20: =UPPER(D20) -> DAFA KANA SUWANDI | AZ20: 0102397601 | BA20: DAFA KANA SUWANDI | BB20: L | BC20: MTsN 2 PAMEKASAN | BD20: 82.37 | BE20: 40.00 | BF20: 65.42 | BG20: A | BH20: tidak ada | BJ20: 15398 | BK20: 0102397601 | BL20: DAFA KANA SUWANDI | BM20: A11
A21: 12 | B21: 15425 | C21: 0116574266 | D21: FATHARANI RAJBI WARDANA | E21: L | AE21: ZONASI | AF21: 0095615344 | AG21: 69816340 | AH21: MUHAMMAD FAKHRY HIDAYAT | AI21: L | AJ21: =UPPER(D21) -> FATHARANI RAJBI WARDANA | AZ21: 0116574266 | BA21: FATHARANI RAJBI WARDANA | BB21: L | BC21: MTSN 3 PAMEKASAN | BD21: 86.41 | BE21: 88.33 | BF21: 87.18 | BG21: A | BH21: KIAI juara 2(MA SUMBER BUNGUR PAKONG) | BJ21: 15425 | BK21: 0116574266 | BL21: FATHARANI RAJBI WARDANA | BM21: A12
A22: 13 | B22: 15442 | C22: 0101196604 | D22: GENDIS RAMADHANI PUTRI H | E22: P | AE22: ZONASI | AF22: 0083566346 | AG22: 20527197 | AH22: NADYA AZMI KHAIRUNNISA | AI22: P | AJ22: =UPPER(D22) -> GENDIS RAMADHANI PUTRI H | AZ22: 0101196604 | BA22: GENDIS RAMADHANI PUTRI H | BB22: P | BC22: SMPN 2 PAMEKASAN | BD22: 86.51 | BE22: 63.34 | BF22: 77.24 | BG22: A | BH22: - | BJ22: 15442 | BK22: 0101196604 | BL22: GENDIS RAMADHANI PUTRI H | BM22: A13
A23: 14 | B23: 15457 | C23: 0101218950 | D23: IKROM ALI | E23: L | AE23: NON AKD | AF23: 0081216364 | AG23: 69991338 | AH23: NAUFAL ALWAN HAKIM | AI23: L | AJ23: =UPPER(D23) -> IKROM ALI | AZ23: 0101218950 | BA23: IKROM ALI | BB23: L | BC23: SMPN 2 PAMEKASAN | BD23: 89.06 | BE23: 76.67 | BF23: 84.10 | BG23: A | BH23: - Juara Harapan 1 Pythagoras+22 (2026) Bhs. inggris - Juara Harapan 2 Amfibi+ (2026) Bhs. Inggris - Juara 2 AKSI (2026) Bhs. Inggris | BJ23: 15457 | BK23: 0101218950 | BL23: IKROM ALI | BM23: A14
A24: 15 | B24: 15460 | C24: 0105381495 | D24: ISNA ALVARETA DAMAYANTI | E24: P | AE24: T.ORTU | AF24: 0097690860 | AG24: 20364507 | AH24: NAZWA AULIA NUR ROSIDAH | AI24: P | AJ24: =UPPER(D24) -> ISNA ALVARETA DAMAYANTI | AZ24: 0105381495 | BA24: ISNA ALVARETA DAMAYANTI | BB24: P | BC24: SMP NEGERI 2 PAMEKASAN | BD24: 89.4 | BE24: 65 | BF24: 79.64 | BG24: A | BH24: Juara 1 Olimpiade Bahasa Inggris Catalyst 2026 | BJ24: 15460 | BK24: 0105381495 | BL24: ISNA ALVARETA DAMAYANTI | BM24: A15
A25: 16 | B25: 15471 | C25: 0102404656 | D25: KARIM MUSTHOFA BENZEMA RAHMAN | E25: L | AE25: ZONASI | AF25: 0087802844 | AG25: 20527180 | AH25: NUR IKHLAS ARIFIN | AI25: L | AJ25: =UPPER(D25) -> KARIM MUSTHOFA BENZEMA RAHMAN | AZ25: 0102404656 | BA25: KARIM MUSTHOFA BENZEMA RAHMAN | BB25: L | BC25: SMPN 1 Pamekasan | BD25: 84.34 | BE25: 66.67 | BF25: 77.27 | BG25: A | BH25: - | BJ25: 15471 | BK25: 0102404656 | BL25: KARIM MUSTHOFA BENZEMA RAHMAN | BM25: A16
A26: 17 | B26: 15478 | C26: 0118050569 | D26: KHOIRINI AULIANA SODIK | E26: P | AE26: ZONASI | AF26: 0089202875 | AG26: 20527193 | AH26: NURISCHA AHDANIA | AI26: P | AJ26: =UPPER(D26) -> KHOIRINI AULIANA SODIK | AZ26: 0118050569 | BA26: KHOIRINI AULIANA SODIK | BB26: P | BC26: SMPN 2 Pamekasan | BD26: 88.26 | BE26: 66.67 | BF26: 79.62 | BG26: A | BH26: - | BJ26: 15478 | BK26: 0118050569 | BL26: KHOIRINI AULIANA SODIK | BM26: A17
A27: 18 | B27: 15491 | C27: 0102293794 | D27: MAGHFIRATUL HAQIQIYAH | E27: P | AE27: KIP | AF27: 0086615669 | AG27: 20527202 | AH27: Oktarina Syawla Putri | AI27: P | AJ27: =UPPER(D27) -> MAGHFIRATUL HAQIQIYAH | AZ27: 0102293794 | BA27: MAGHFIRATUL HAQIQIYAH | BB27: P | BC27: SMP Negeri 2 Pamekasan | BD27: 88.54 | BE27: 71.67 | BF27: 81.79 | BG27: A | BH27: - | BJ27: 15491 | BK27: 0102293794 | BL27: MAGHFIRATUL HAQIQIYAH | BM27: A18
A28: 19 | B28: 15496 | C28: 0119102326 | D28: MAISHITA ZALFA ZAHIRA | E28: P | AE28: RAPORT | AF28: 3081834782 | AG28: 20528625 | AH28: RARA QONITA ROYHANI | AI28: P | AJ28: =UPPER(D28) -> MAISHITA ZALFA ZAHIRA | AZ28: 0119102326 | BA28: MAISHITA ZALFA ZAHIRA | BB28: P | BC28: SMP NEGERI 2 PAMEKASAN | BD28: 83.17 | BE28: 61.67 | BF28: 74.57 | BG28: A | BH28: - | BJ28: 15496 | BK28: 0119102326 | BL28: MAISHITA ZALFA ZAHIRA | BM28: A19
A29: 20 | B29: 15508 | C29: 0103517899 | D29: MEISYA MELINDA PUTRI | E29: P | AE29: ZONASI | AF29: 0086255643 | AG29: 20527180 | AH29: REVIANA ZAHRA | AI29: P | AJ29: =UPPER(D29) -> MEISYA MELINDA PUTRI | AZ29: 0103517899 | BA29: MEISYA MELINDA PUTRI | BB29: P | BC29: MTSs MATSARATUL HUDA | BD29: 86.66 | BE29: 45 | BF29: 70 | BG29: A | BH29: - | BJ29: 15508 | BK29: 0103517899 | BL29: MEISYA MELINDA PUTRI | BM29: A20
A30: 21 | B30: 15509 | C30: 0111386102 | D30: MEISYA PURNOMO | E30: P | AE30: NON AKD | AF30: 0095745897 | AG30: 20527193 | AH30: RIZKIANA INTANSARI | AI30: P | AJ30: =UPPER(D30) -> MEISYA PURNOMO | AZ30: 0111386102 | BA30: MEISYA PURNOMO | BB30: P | BC30: SMPN 4 TANJUNG | BD30: 86.46 | BE30: 66.66 | BF30: 87.77 | BG30: A | BH30: - | BJ30: 15509 | BK30: 0111386102 | BL30: MEISYA PURNOMO | BM30: A21
A31: 22 | B31: 15532 | C31: 0104258466 | D31: MOHAMMAD AZZAM FAKHRULLAH | E31: L | AE31: AKDMK | AF31: 0083907588 | AG31: 20527180 | AH31: RUH SYAFIRA CAHYANING PAWASA | AI31: P | AJ31: =UPPER(D31) -> MOHAMMAD AZZAM FAKHRULLAH | AZ31: 0104258466 | BA31: MOHAMMAD AZZAM FAKHRULLAH | BB31: L | BC31: SMPN 1 PAMEKASAN | BD31: 87.69 | BE31: 78.34 | BF31: 83.95 | BG31: A | BH31: 1. Medali perak matematika Final provinsi KMSI 2. Medali perunggu matematika OSI 15 Nasional 3. Medali perunggu IPA OSI 15 Nasional 4 Juara 2 matematika SMASCOM Se-Jawa timur | BJ31: 15532 | BK31: 0104258466 | BL31: MOHAMMAD AZZAM FAKHRULLAH | BM31: A22
A32: 23 | B32: 15536 | C32: 0111595573 | D32: MOHAMMAD IBRAN NAWAFIL | E32: L | AE32: ZONASI | AF32: 0083041624 | AG32: 20527197 | AH32: SALSABILA PUTRI HIDAYAT | AI32: P | AJ32: =UPPER(D32) -> MOHAMMAD IBRAN NAWAFIL | AZ32: 0111595573 | BA32: MOHAMMAD IBRAN NAWAFIL | BB32: L | BC32: MTS NEGERI 1 PAMEKASAN | BD32: 86.11 | BE32: 61.67 | BF32: 76.33 | BG32: A | BH32: - | BJ32: 15536 | BK32: 0111595573 | BL32: MOHAMMAD IBRAN NAWAFIL | BM32: A23
A33: 24 | B33: 15540 | C33: 0107873733 | D33: MOREYNO ISWAHYUDI | E33: L | AE33: RAPORT | AF33: 0109424194 | AG33: 20583367 | AH33: SARAH SALSABILA | AI33: P | AJ33: =UPPER(D33) -> MOREYNO ISWAHYUDI | AZ33: 0107873733 | BA33: MOREYNO ISWAHYUDI | BB33: L | BC33: SMP NEGERI 2 PAMEKASAN | BD33: 86.63 | BE33: 75.00 | BF33: 81.98 | BG33: A | BH33: - | BJ33: 15540 | BK33: 0107873733 | BL33: MOREYNO ISWAHYUDI | BM33: A24
A34: 25 | B34: 15554 | C34: 0106853256 | D34: MUTIARA NOER ISLAMI | E34: P | AE34: RAPORT | AF34: 0081315442 | AG34: 20527197 | AH34: SEPTI RAHMADIYANTI | AI34: P | AJ34: =UPPER(D34) -> MUTIARA NOER ISLAMI | AZ34: 0106853256 | BA34: MUTIARA NOER ISLAMI | BB34: P | BC34: MTs.Mftahul Qulub Polagan | BD34: 89.43 | BE34: 65 | BF34: 79.66 | BG34: A | BH34: - | BJ34: 15554 | BK34: 0106853256 | BL34: MUTIARA NOER ISLAMI | BM34: A25
A35: 26 | B35: 15565 | C35: 0113084419 | D35: NAJWA ZAHRA RAYHANA | E35: P | AE35: ZONASI | AF35: 0085713874 | AG35: 20527180 | AH35: TANIA KHANZA FIRNANDA RAMADHANI | AI35: P | AJ35: =UPPER(D35) -> NAJWA ZAHRA RAYHANA | AZ35: 0113084419 | BA35: NAJWA ZAHRA RAYHANA | BB35: P | BC35: SMPN 2 PAMEKASAN | BD35: 88.69 | BE35: 61.67 | BF35: 77.88 | BG35: A | BH35: - | BJ35: 15565 | BK35: 0113084419 | BL35: NAJWA ZAHRA RAYHANA | BM35: A26
A36: 27 | B36: 15599 | C36: 0104676748 | D36: RAISYA AURELIA JAKSANTO | E36: P | AE36: NON AKD | AF36: 0099637523 | AG36: 20527197 | AH36: Tulus Firmansyah | AI36: L | AJ36: =UPPER(D36) -> RAISYA AURELIA JAKSANTO | AZ36: 0104676748 | BA36: RAISYA AURELIA JAKSANTO | BB36: P | BC36: MTs. Ummul Quro Putri | BD36: 89.11 | BE36: 66.67 | BF36: 77.89 | BG36: A | BH36: Tidak ada | BJ36: 15599 | BK36: 0104676748 | BL36: RAISYA AURELIA JAKSANTO | BM36: A27
A37: 28 | B37: 15600 | C37: 31092433519 | D37: RAISYA TRI YUNIAR HERMITA SARI | E37: P | AJ37: =UPPER(D37) -> RAISYA TRI YUNIAR HERMITA SARI | AZ37: 31092433519 | BA37: RAISYA TRI YUNIAR HERMITA SARI | BB37: P | BC37: SMPN 3 Pamekasan | BD37: 81.43 | BE37: 41.67 | BF37: 65.53 | BG37: A | BH37: - | BJ37: 15600 | BK37: 31092433519 | BL37: RAISYA TRI YUNIAR HERMITA SARI | BM37: A28
A38: 29 | B38: 15614 | C38: 0113258602 | D38: RIZKY FEBRIYAN MAULANA | E38: L | AJ38: =UPPER(D38) -> RIZKY FEBRIYAN MAULANA | AZ38: 0113258602 | BA38: RIZKY FEBRIYAN MAULANA | BB38: L | BC38: MTsN 1 PAMEKASAN | BD38: 86.80 | BE38: 71.67 | BF38: 88.75 | BG38: A | BH38: - | BJ38: 15614 | BK38: 0113258602 | BL38: RIZKY FEBRIYAN MAULANA | BM38: A29
A39: 30 | B39: 15629 | C39: 0102482013 | D39: SAMARA MAJDA WACHDIN | E39: P | AJ39: =UPPER(D39) -> SAMARA MAJDA WACHDIN | AZ39: 0102482013 | BA39: SAMARA MAJDA WACHDIN | BB39: P | BC39: SMP NEGERI 1 PAMEKASAN | BD39: 88.00 | BE39: 73.34 | BF39: 82.14 | BG39: A | BH39: - | BJ39: 15629 | BK39: 0102482013 | BL39: SAMARA MAJDA WACHDIN | BM39: A30
A40: 31 | B40: 15631 | C40: 0118303142 | D40: SATRIA NOVAN PERWIRA | E40: L | AJ40: =UPPER(D40) -> SATRIA NOVAN PERWIRA | AZ40: 0118303142 | BA40: SATRIA NOVAN PERWIRA | BB40: L | BC40: smpn 1 pamekasan | BD40: 82.29 | BE40: 55.00 | BF40: 71.37 | BG40: A | BH40: tidak ada | BJ40: 15631 | BK40: 0118303142 | BL40: SATRIA NOVAN PERWIRA | BM40: A31
...

Sheet X-2
AF1: AKDMK | AG1: 0091162442 | AH1: 20566545 | AI1: ADELIA ZAHRA WIEGUNANDA | AJ1: P
AF2: RAPORT | AG2: 0098516635 | AH2: 20583363 | AI2: Ahmad Faiz Rahmatillah | AJ2: L
AF3: KIP | AG3: 0095865130 | AH3: 20537422 | AI3: AHMAD FARHAN HAKIKI | AJ3: L
A4: Tahun Pelajaran 2026 / 2027 | AF4: ZONASI | AG4: 0085516582 | AH4: 20527180 | AI4: AIZZA RAHMATIN NUR NADIN | AJ4: P
AF5: ZONASI | AG5: 0095986339 | AH5: 20527197 | AI5: ALDO SUKMA MAULIDZI | AJ5: L
AF6: NON AKD | AG6: 0082440195 | AH6: 20527180 | AI6: ARIF RAHMAN ALFATHIR | AJ6: L
A7: No | B7: NISN | C7: NISN | D7: Nama Siswa | E7: L/P | F7: Wali Kelas : | I7: JUWAIRIYAH, S.Pd | T7: NIP : | V7: 19770106 2006042013 | AF7: NON AKD | AG7: 0095153508 | AH7: 20527180 | AI7: ARSYIL CAHYA WIBISONO | AJ7: P
F8: Tanggal | AF8: RAPORT | AG8: 0083079329 | AH8: 20566545 | AI8: BUNGA EL SABRINA | AJ8: P
AF9: RAPORT | AG9: 0088600933 | AH9: 20527197 | AI9: CANDRA ADITIYA NURMANSAH | AJ9: L
A10: 1 | B10: 15322 | C10: 3104177826 | D10: ADINDA R NISYRIN AZZAHRA | E10: P | AF10: ZONASI | AG10: 0085720766 | AH10: 20527180 | AI10: CHIKO HARDELIO TAHER | AJ10: L | AL10: =UPPER(D10) -> ADINDA R NISYRIN AZZAHRA | AV10: 3104177826 | AW10: ADINDA R NISYRIN AZZAHRA | AX10: P | AY10: SMP Nurul Jadid | AZ10: 80.66 | BA10: 61.67 | BB10: 73.06 | BC10: B | BD10: Tahfidz | BF10: 15322 | BG10: 3104177826 | BH10: ADINDA R NISYRIN AZZAHRA
A11: 2 | B11: 15372 | C11: 0101969578 | D11: AVISQI SYAFIRULAH FIRMANSYAH | E11: L | AF11: ZONASI | AG11: 0082153282 | AH11: 20527197 | AI11: ELMAS SULTHON SALIM | AJ11: L | AL11: =UPPER(D11) -> AVISQI SYAFIRULAH FIRMANSYAH | AV11: 0101969578 | AW11: AVISQI SYAFIRULAH FIRMANSYAH | AX11: L | AY11: SMP NEGERI 2 PAMEKASAN | AZ11: 82.23 | BA11: 65.00 | BB11: 75.34 | BC11: B | BD11: (-) | BF11: 15372 | BG11: 0101969578 | BH11: AVISQI SYAFIRULAH FIRMANSYAH
A12: 3 | B12: 15373 | C12: 0117318632 | D12: AWLIDYA DINDA NABILA | E12: P | AF12: ZONASI | AG12: 0081076234 | AH12: 20527197 | AI12: FAGHIRA CAYLA PUTRI | AJ12: P | AL12: =UPPER(D12) -> AWLIDYA DINDA NABILA | AV12: ‘0117318632 | AW12: AWLIDYA DINDA NABILA | AX12: P | AY12: SMP Plus Nurul Hikmah Pamekasan | AZ12: 88.17 | BA12: 43.33 | BB12: 70.23 | BC12: B | BD12: - | BF12: 15373 | BG12: 0117318632 | BH12: AWLIDYA DINDA NABILA
A13: 4 | B13: 15403 | C13: 0106318464 | D13: DESI AISYAH ALIFA | E13: P | AF13: RAPORT | AG13: 0085164886 | AH13: 20527197 | AI13: FATHIMAH AZ ZAHRA | AJ13: P | AL13: =UPPER(D13) -> DESI AISYAH ALIFA | AV13: 0106318464 | AW13: DESI AISYAH ALIFA | AX13: P | AY13: SMP NEGERI 1 PAMEKASAN | AZ13: 88.31 | BA13: 71.67 | BB13: 81.65 | BC13: B | BD13: - | BF13: 15403 | BG13: 0106318464 | BH13: DESI AISYAH ALIFA
A14: 5 | B14: 15406 | C14: 0119634502 | D14: DIRA KARTIKA SARI | E14: P | AF14: ZONASI | AG14: 0093543547 | AH14: 20527197 | AI14: FENI ISTIGHFARINI | AJ14: P | AL14: =UPPER(D14) -> DIRA KARTIKA SARI | AV14: 0119634502 | AW14: DIRA KARTIKA SARI | AX14: P | AY14: SMP NEGERI 1 PAMEKASAN | AZ14: 86.46 | BA14: 78.33 | BB14: 83.21 | BC14: B | BD14: - | BF14: 15406 | BG14: 0119634502 | BH14: DIRA KARTIKA SARI
A15: 6 | B15: 15407 | C15: 0102200609 | D15: DZAKIA VANIA AUBERTA JAYADI | E15: P | AF15: ZONASI | AG15: 0087610741 | AH15: 20527197 | AI15: GUNTUR PRASTYO WIBOWO | AJ15: L | AL15: =UPPER(D15) -> DZAKIA VANIA AUBERTA JAYADI | AV15: 0102200609 | AW15: DZAKIA VANIA AUBERTA JAYADI | AX15: P | AY15: SMP NEGERI 2 PAMEKASAN | AZ15: 88.17 | BA15: 65.00 | BB15: 78.90 | BC15: B | BD15: - | BF15: 15407 | BG15: 0102200609 | BH15: DZAKIA VANIA AUBERTA JAYADI
A16: 7 | B16: 15422 | C16: 0111355772 | D16: FARDA AULIA KURNIA | E16: P | AF16: RAPORT | AG16: 0086660138 | AH16: 20527197 | AI16: Juwita Riski Amalia | AJ16: P | AL16: =UPPER(D16) -> FARDA AULIA KURNIA | AV16: 0111355772 | AW16: FARDA AULIA KURNIA | AX16: P | AY16: SMPN 1 LARANGAN | AZ16: 92.03 | BA16: 76.67 | BB16: 85.89 | BC16: B | BD16: 1. Meraih juara harapan 1 (4) dalam lomba PHYTAGORAS+22 yang diselenggarakan oleh SMAN 1 Pamekasan 2. Meraih medali emas tingkat provinsi, medali emas tingkat Kabupaten dan best mapel sejarah tingkat Kabupaten dalam lomba OLIPS ke 2 yang diselenggarakan oleh MGMP IPS Kabupaten Probolinggo 3. Meraih Juara 1 dalam lomba Olimpiade IPS yang diselenggarakan oleh MGMP IPS Pamekasan 4. Meraih Juara 1 dalam lomba MAFIKIBISA PLUS 25 bidang IPS yang diselenggarakan oleh OSIS MAN 2 Pamekasan (27 april) 5. Meraih Juara 2 dalam lomba MAFIKIBISA PLUS 25 bidang IPS yang diselenggarakan oleh OSIS MAN 2 Pamekasan (6 desember) 6. Meraih Juara 2 dalam lomba GOMA PLUS X 2025 bidang IPS yang diselenggarakan oleh OSIS MA ALFALAH 7. Meraih Juara 3 dalam lomba AKSI 2026 bidang IPS yang diselenggarakan oleh MAN 1 PAMEKASAN 8. Meraih Juara 3 dalam lomba AKSI 2025 bidang IPS yang diselenggarakan oleh MAN 1 PAMEKASAN 9. Meraih Juara harapan 1 (4) dalam lomba GOMA PLUS IX 2025 bidang IPS yang diselenggarakan oleh OSIS MA ALFALAH | BF16: 15422 | BG16: 0111355772 | BH16: FARDA AULIA KURNIA
A17: 8 | B17: 15424 | C17: 0116260978 | D17: FARHATUS SHOLIHAH | E17: P | AF17: ZONASI | AG17: 0089337623 | AH17: 20527197 | AI17: KEA APRILIA MEDIANA PUTRI | AJ17: P | AL17: =UPPER(D17) -> FARHATUS SHOLIHAH | AV17: 0116260978 | AW17: FARHATUS SHOLIHAH | AX17: P | AY17: SMP NEGERI 2 PENGANTENAN | AZ17: 88.71 | BA17: 70.00 | BB17: 81.23 | BC17: B | BD17: - | BF17: 15424 | BG17: 0116260978 | BH17: FARHATUS SHOLIHAH
A18: 9 | B18: 15427 | C18: 0109242753 | D18: FAYZA FITRI RAMADHANI | E18: P | AF18: KIP | AG18: 0082984202 | AH18: 20583410 | AI18: MALIKA APRILIA SYAFIUN | AJ18: P | AL18: =UPPER(D18) -> FAYZA FITRI RAMADHANI | AV18: 0109242753 | AW18: FAYZA FITRI RAMADHANI | AX18: P | AY18: SMP NEGERI 2 PAMEKASAN | AZ18: 89.54 | BA18: 83.33 | BB18: 87.06 | BC18: B | BD18: - | BF18: 15427 | BG18: 0109242753 | BH18: FAYZA FITRI RAMADHANI
A19: 10 | B19: 15429 | C19: 0113824295 | D19: FEBRIAN TRISNO PUTRA | E19: L | AF19: ZONASI | AG19: 0099057804 | AH19: 20527197 | AI19: MOH RIZKY ADITIANSYAH | AJ19: L | AL19: =UPPER(D19) -> FEBRIAN TRISNO PUTRA | AV19: 0113824295 | AW19: FEBRIAN TRISNO PUTRA | AX19: L | AY19: SMPN 3 PMK | AZ19: 81.14 | BA19: 78.34 | BB19: 80.02 | BC19: B | BD19: - | BF19: 15429 | BG19: 0113824295 | BH19: FEBRIAN TRISNO PUTRA
A20: 11 | B20: 15431 | C20: 0118805990 | D20: FELICIA LENITA JONATHAN | E20: P | AF20: ZONASI | AG20: 0093162650 | AH20: 20527180 | AI20: MOHAMMAD DHORIF AFLAH FAISAL | AJ20: L | AL20: =UPPER(D20) -> FELICIA LENITA JONATHAN | AV20: 0118805990 | AW20: FELICIA LENITA JONATHAN | AX20: P | AY20: MTSN 3 PAMEKASAN | AZ20: 90.3 | BA20: 61.67 | BB20: 78.85 | BC20: B | BD20: (-) | BF20: 15431 | BG20: 0118805990 | BH20: FELICIA LENITA JONATHAN
A21: 12 | B21: 15470 | C21: 0114204433 | D21: KAIRA BRIANA AQILLA SYUA | E21: P | AF21: ZONASI | AG21: 0086354265 | AH21: 20527197 | AI21: MUHAMMAD IQBAL RAIHANUN | AJ21: L | AL21: =UPPER(D21) -> KAIRA BRIANA AQILLA SYUA | AV21: 0114204433 | AW21: KAIRA BRIANA AQILLA SYUA | AX21: P | AY21: SMP Negeri 1 Pamekasan | AZ21: 89.46 | BA21: 58.34 | BB21: 77.01 | BC21: B | BD21: 1. Juara 3 Olimpiade Sastra Tingkat SMP/MTS/Sederajat Se Madura yang Diselenggarakan oleh Dinas Pendidikan dan Kebudayaan Kabupaten Pamekasan Pada Tanggal 04 Mei 2025 2. Medali Perunggu Level 4 Square Root Olympiad yang diselenggarakan oleh Omag Sinau Semar pada tanggal 23 Februari 2025 | BF21: 15470 | BG21: 0114204433 | BH21: KAIRA BRIANA AQILLA SYUA
A22: 13 | B22: 15479 | C22: 0113992432 | D22: KHOIRUL BARIYAH | E22: P | AF22: AKDMK | AG22: 0083243040 | AH22: 20566545 | AI22: MUHAMMAD RAMZY GUNAWAN | AJ22: L | AL22: =UPPER(D22) -> KHOIRUL BARIYAH | AV22: 0113992432 | AW22: KHOIRUL BARIYAH | AX22: P | AY22: MTS AL-MUZAKKi | AZ22: 84.06 | BA22: 0.00 | BB22: 50.44 | BC22: B | BD22: (-) | BF22: 15479 | BG22: 0113992432 | BH22: KHOIRUL BARIYAH
A23: 14 | B23: 15481 | C23: 0106604350 | D23: KRISNA ARKARNA | E23: L | AF23: RAPORT | AG23: 0091755500 | AH23: 20527197 | AI23: NAILA AZARINE RADHIA IRDIAWAN | AJ23: P | AL23: =UPPER(D23) -> KRISNA ARKARNA | AV23: 0106604350 | AW23: KRISNA ARKARNA | AX23: L | AY23: SMPN 2 PAMEKASAN | AZ23: 82.83 | BA23: 65.00 | BB23: 75.70 | BC23: B | BD23: - | BF23: 15481 | BG23: 0106604350 | BH23: KRISNA ARKARNA
A24: 15 | B24: 15484 | C24: 0115833274 | D24: LEISTYVIA MURZIDHA HAZIS | E24: P | AF24: AKDMK | AG24: 0092355423 | AH24: 20527197 | AI24: NASHIFATUL LAYAL | AJ24: L | AL24: =UPPER(D24) -> LEISTYVIA MURZIDHA HAZIS | AV24: 0115833274 | AW24: LEISTYVIA MURZIDHA HAZIS | AX24: P | AY24: SMP NEGERI 1 PAMEKASAN | AZ24: 84.97 | BA24: 58.33 | BB24: 74.31 | BC24: B | BD24: - | BF24: 15484 | BG24: 0115833274 | BH24: LEISTYVIA MURZIDHA HAZIS
A25: 16 | B25: 15500 | C25: 0117515615 | D25: MAULANA DZAKY ALMER | E25: L | AF25: ZONASI | AG25: 0084036504 | AH25: 20527180 | AI25: NAUFAL PUTRA HARDIANSYAH | AJ25: L | AL25: =UPPER(D25) -> MAULANA DZAKY ALMER | AV25: 0117515615 | AW25: MAULANA DZAKY ALMER | AX25: L | AY25: SMP Negeri 1 Pamekasan | AZ25: 89.74 | BA25: 66.67 | BB25: 80.51 | BC25: B | BD25: 1. Juara 1 IPS (COSMIS) tahun 2023 2. Juara 2 IPS (COSMIS) tahun 2024 3. Juara 2 IPS (Bisco) tahun 2025 4. Juara 2 IPS (SMASCOM) tahun 2025 5. Harapan 3 IPS (AKSI) tahun 2026 | BF25: 15500 | BG25: 0117515615 | BH25: MAULANA DZAKY ALMER
A26: 17 | B26: 15512 | C26: 0107323638 | D26: MERIZA NAILA ROHMAH | E26: P | AF26: ZONASI | AG26: 0089619651 | AH26: 20527197 | AI26: NOER RISQI RAMADHANI | AJ26: L | AL26: =UPPER(D26) -> MERIZA NAILA ROHMAH | AV26: 0107323638 | AW26: MERIZA NAILA ROHMAH | AX26: P | AY26: SMP NEGERI 1 PAMEKASAN | AZ26: 85.65 | BA26: 61.67 | BB26: 73.37 | BC26: B | BD26: - | BF26: 15512 | BG26: 0107323638 | BH26: MERIZA NAILA ROHMAH
A27: 18 | B27: 15513 | C27: 0109610550 | D27: MERY INDRIYANI | E27: P | AF27: ZONASI | AG27: 0092301710 | AH27: 20527180 | AI27: OLIVIA DAMAYANTI LUQMAN | AJ27: P | AL27: =UPPER(D27) -> MERY INDRIYANI | AV27: 0109610550 | AW27: MERY INDRIYANI | AX27: P | AY27: SMPN 1 PAMEKASAN | AZ27: 84.60 | BA27: 56.67 | BB27: 73.43 | BC27: B | BD27: - | BF27: 15513 | BG27: 0109610550 | BH27: MERY INDRIYANI
A28: 19 | B28: 15520 | C28: 0113580736 | D28: MOH DZILDJAN ARUNAKAFA DJ | E28: L | AF28: RAPORT | AG28: 0092111132 | AH28: 20527197 | AI28: R NEVAN BASWARA DAUD | AJ28: L | AL28: =UPPER(D28) -> MOH DZILDJAN ARUNAKAFA DJ | AV28: 0113580736 | AW28: MOH DZILDJAN ARUNAKAFA DJ | AX28: L | AY28: SMPN 2 PAMEKASAN | AZ28: 87.14 | BA28: 66.67 | BB28: 78.95 | BC28: B | BD28: - | BF28: 15520 | BG28: 0113580736 | BH28: MOH DZILDJAN ARUNAKAFA DJ
A29: 20 | B29: 15523 | C29: 0117692097 | D29: MOH ILHAM UBAIDILAH | E29: L | AF29: ZONASI | AG29: 0096209388 | AH29: 20583410 | AI29: RAFIKA PUTRI YUNIAR | AJ29: P | AL29: =UPPER(D29) -> MOH ILHAM UBAIDILAH | AV29: 0117692097 | AW29: MOH ILHAM UBAIDILAH | AX29: L | AY29: SMPN 1 Sampang | AZ29: 92.17 | BA29: 93.34 | BB29: 92.64 | BC29: B | BD29: Juara 3 lomba Phytagoras+22 bidang Matematika | BF29: 15523 | BG29: 0117692097 | BH29: MOH ILHAM UBAIDILAH
A30: 21 | B30: 15527 | C30: 3105710667 | D30: MOH YERIK HARSHA | E30: L | AF30: ZONASI | AG30: 0097120243 | AH30: 20527180 | AI30: SHEBIA KINANTI AURELLUNA | AJ30: P | AL30: =UPPER(D30) -> MOH YERIK HARSHA | AV30: 3105710667 | AW30: MOH YERIK HARSHA | AX30: L | AY30: smpn 1 galis | AZ30: 79.89 | BA30: 48.34 | BB30: 64.12 | BC30: B | BD30: - | BF30: 15527 | BG30: 3105710667 | BH30: MOH YERIK HARSHA
A31: 22 | B31: 15582 | C31: 0104392842 | D31: PRASEPTYAN PUTERA ABSULISTYAWAN | E31: L | AF31: ZONASI | AG31: 0083330053 | AH31: 20527197 | AI31: SHELFIA PUTRI RAMADHANI | AJ31: P | AL31: =UPPER(D31) -> PRASEPTYAN PUTERA ABSULISTYAWAN | AV31: 0104392842 | AW31: PRASEPTYAN PUTERA ABSULISTYAWAN | AX31: L | AY31: SMP NEGERI 2 PAMEKASAN | AZ31: 87.54 | BA31: 61.67 | BB31: 77.19 | BC31: B | BD31: (-) | BF31: 15582 | BG31: 0104392842 | BH31: PRASEPTYAN PUTERA ABSULISTYAWAN
A32: 23 | B32: 15596 | C32: 0114927577 | D32: RAFLI WAHYU SETYAWAN | E32: L | AF32: KIP | AG32: 0093513951 | AH32: 20527166 | AI32: Sitti Uswatun Hasanah | AJ32: P | AL32: =UPPER(D32) -> RAFLI WAHYU SETYAWAN | AV32: 0114927577 | AW32: RAFLI WAHYU SETYAWAN | AX32: L | AY32: SMPN 2 PAMEKASAN | AZ32: 84.23 | BA32: 68.34 | BB32: 77.87 | BC32: B | BD32: - | BF32: 15596 | BG32: 0114927577 | BH32: RAFLI WAHYU SETYAWAN
A33: 24 | B33: 15598 | C33: 0122446477 | D33: RAISHA PUTRI AYUNINDITA | E33: P | AF33: NON AKD | AG33: 0089793791 | AH33: 20527195 | AI33: SULTAN FARAS AS SIDIK | AJ33: L | AL33: =UPPER('X-8'!D21) -> FEBRINA KAYLILA RAHMAWATI | AV33: 0122446477 | AW33: RAISHA PUTRI AYUNINDITA | AX33: P | AY33: SMPN 2 PAMEKASAN | AZ33: 89.37 | BA33: 80 | BB33: 85.62 | BC33: B | BD33: 1. Olimpiade Omni Sains Indonesia ( OSI 2) thn 2025 ( Mapel Bahasa Inggris - Tingkat SMP ) 2. Olimpiade matematika, sains, bahasa inggris tahun 2026 (Mapel Bahasa Inggris - Level 4) | BF33: 15598 | BG33: 0122446477 | BH33: RAISHA PUTRI AYUNINDITA
A34: 25 | B34: 15611 | C34: 0103803597 | D34: RIFQI ALFAIRUS ALHAMDANI | E34: L | AF34: RAPORT | AG34: 0094292897 | AH34: 20527197 | AI34: TASNIM KHAIRULLAH HIDAYAT | AJ34: L | AL34: =UPPER(D34) -> RIFQI ALFAIRUS ALHAMDANI | AV34: 0103803597 | AW34: RIFQI ALFAIRUS ALHAMDANI | AX34: L | AY34: SMP NEGERI 1 Pamekasan | AZ34: 92.40 | BA34: 68.34 | BB34: 82.78 | BC34: B | BD34: - Juara 2 Phytagoras +21 Bidang IPS (SMAN 1 PAMEKASAN). - Juara 3 OLIPS tingkat SLTP/SMP/MTS Se-derajat se Jawa Bali tahun 2025 (HMPS Tadris Ilmu Pengetahuan Sosial Universitas islam Negeri Madura). - Juara 2 SMASCOM & SSO Bidang IPS tahun jenjang SMP/MTs sederajat se-Jawa-Bali tahun 2025 (SMAN 1 Trenggalek). - Juara 3 Olimpiade IPS tingkat SMP/MTS se-Madura tahun 2024 (MGMP IPS Kabupaten Pamekasan). - Juara 2 MAFIKIBISA PLUS'25 Bidang IPS tingkat SMP/MTs sederajat se-Madura tahun 2025 (MAN 2 PAMEKASAN). - Juara 2 KOMPAS +15 tahun 2024 (SMAN 1 Pamekasan). - Juara 2 GOMA PLUS IX 2025 Mapel Agama (MA AL-FALAH Sumber Gayam Kadur Pamekasan). | BF34: 15611 | BG34: 0103803597 | BH34: RIFQI ALFAIRUS ALHAMDANI
A35: 26 | B35: 15619 | C35: 0111790640 | D35: S QONITA HAMDY R | E35: P | AF35: RAPORT | AG35: 0093897835 | AH35: 20527197 | AI35: Vina Istiana | AJ35: P | AL35: =UPPER(D35) -> S QONITA HAMDY R | AV35: 0111790640 | AW35: S QONITA HAMDY R | AX35: P | AY35: SMP Plus Nurul Hikmah | AZ35: 86.77 | BA35: 70.00 | BB35: 80.05 | BC35: B | BD35: - | BF35: 15619 | BG35: 0111790640 | BH35: S QONITA HAMDY R
A36: 27 | B36: 15625 | C36: 0108237820 | D36: SAFRA HUBBY ELHAKIM | E36: P | AF36: T.ORTU | AG36: 0085106484 | AH36: 20527197 | AI36: VIRGI AZMI YUSSININGTYAS | AJ36: P | AL36: =UPPER(D36) -> SAFRA HUBBY ELHAKIM | AV36: 0108237820 | AW36: SAFRA HUBBY ELHAKIM | AX36: P | AY36: MTS Multazam | AZ36: 87.40 | BA36: 63.34 | BB36: 77.78 | BC36: B | BD36: - | BF36: 15625 | BG36: 0108237820 | BH36: SAFRA HUBBY ELHAKIM
A37: 28 | B37: 15628 | C37: 0117202197 | D37: SAKINATIN NUR LAILA HANAFI | E37: P | AL37: =UPPER(D37) -> SAKINATIN NUR LAILA HANAFI | AV37: 0117202197 | AW37: SAKINATIN NUR LAILA HANAFI | AX37: P | AY37: MTSn 3 Pamekasan | AZ37: 90.84 | BA37: 71.67 | BB37: 83.17 | BC37: B | BD37: juara 2 lomba IPA se-Kabupaten Pamekasan dalam rangka Hari Guru Nasional | BF37: 15628 | BG37: 0117202197 | BH37: SAKINATIN NUR LAILA HANAFI
A38: 29 | B38: 15633 | C38: 0111744586 | D38: SHABRINA AZKA IMANA | E38: P | AL38: =UPPER(D38) -> SHABRINA AZKA IMANA | AV38: 0111744586 | AW38: SHABRINA AZKA IMANA | AX38: P | AY38: SMP NEGERI 2 PAMEKASAN | AZ38: 83.20 | BA38: 51.67 | BB38: 70.59 | BC38: B | BD38: - | BF38: 15633 | BG38: 0111744586 | BH38: SHABRINA AZKA IMANA
A39: 30 | B39: 15647 | C39: 0101368280 | D39: ULFA RAUDHATUS SOLEHAH E | E39: P | AL39: =UPPER(D39) -> ULFA RAUDHATUS SOLEHAH E | AV39: 0101368280 | AW39: ULFA RAUDHATUS SOLEHAH E | AX39: P | AY39: SMPN 2 PAMEKASAN | AZ39: 90.11 | BA39: 71.67 | BB39: 82.73 | BC39: B | BD39: (-) | BF39: 15647 | BG39: 0101368280 | BH39: ULFA RAUDHATUS SOLEHAH E
A40: 31 | B40: 15651 | C40: 0108312959 | D40: VIDYRA ANNAJWA SYAFITRI | E40: P | AL40: =UPPER(D40) -> VIDYRA ANNAJWA SYAFITRI | AV40: 0108312959 | AW40: VIDYRA ANNAJWA SYAFITRI | AX40: P | AY40: SMP NEGERI 2 PAMEKASAN | AZ40: 89.91 | BA40: 65.00 | BB40: 79.95 | BC40: B | BD40: - | BF40: 15651 | BG40: 0108312959 | BH40: VIDYRA ANNAJWA SYAFITRI
...

Sheet X-3
AF1: ZONASI | AG1: 0099987267 | AH1: 20527180 | AI1: ABD HAMID MANAF | AJ1: L
AF2: ZONASI | AG2: 0082986450 | AH2: 20527197 | AI2: ACH IMAM MURTADHO | AJ2: L
AF3: RAPORT | AG3: 0093908702 | AH3: 20527197 | AI3: ADLYANSYAH BUDIMAN | AJ3: L
A4: Tahun Pelajaran 2026 / 2027 | AF4: ZONASI | AG4: 0095256057 | AH4: 60729406 | AI4: AKBAR RAHMATULLAH RAMADHAN | AJ4: L
AF5: ZONASI | AG5: 0093440845 | AH5: 20527169 | AI5: ALLENA GIOVANNY SUGIARTO | AJ5: P
AF6: RAPORT | AG6: 0089803534 | AH6: 20527180 | AI6: ALYSSA RISMA PARAMITHA | AJ6: P
A7: No | B7: NIS | C7: NISN | D7: Nama Siswa | E7: L/P | F7: Wali Kelas : | I7: ERLY NOER AISYAH, S.Si. | T7: NIP : | V7: 198407302024212000 | AF7: ZONASI | AG7: 0082607776 | AH7: 20527197 | AI7: ANDI ZAKY DANISH FIRMANSYAH | AJ7: L
F8: Tanggal | AF8: RAPORT | AG8: 0095437804 | AH8: 20531242 | AI8: Asyra Mardhodillah Shafa | AJ8: P
AF9: AKDMK | AG9: 0081651505 | AH9: 20527197 | AI9: AURIGA SYAFHA FAIRUZ SYAHREZA | AJ9: P
A10: 1 | B10: 15320 | C10: 0116875613 | D10: ADIENDA CANTIKA YUDHISTIRA | E10: P | AF10: RAPORT | AG10: 3094339612 | AH10: 20566545 | AI10: BUMI SUKMAWATI | AJ10: P | AM10: =UPPER(D10) -> ADIENDA CANTIKA YUDHISTIRA | AT10: 0116875613 | AU10: ADIENDA CANTIKA YUDHISTIRA | AV10: P | AW10: SMP Negeri 2 Pamekasan | AX10: 85.37 | AY10: 60.00 | AZ10: 75.22 | BA10: C | BB10: - | BD10: 15320 | BE10: 0116875613 | BF10: ADIENDA CANTIKA YUDHISTIRA | BG10: C01
A11: 2 | B11: 15324 | C11: 0109084702 | D11: AFFAN MAULANA ISHAQ | E11: L | AF11: ZONASI | AG11: 0089501886 | AH11: 20527193 | AI11: DHIMAS ADHA TRI SUSANTO | AJ11: L | AM11: =UPPER(D11) -> AFFAN MAULANA ISHAQ | AT11: 0109084702 | AU11: AFFAN MAULANA ISHAQ | AV11: L | AW11: SMP NEGRI 1 PAMEKASAN | AX11: 82.17 | AY11: 53.34 | AZ11: 70.64 | BA11: C | BB11: (-) | BD11: 15324 | BE11: 0109084702 | BF11: AFFAN MAULANA ISHAQ | BG11: C02
A12: 3 | B12: 15326 | C12: 0105523137 | D12: AFINA FILZAH KHAIRANA RACHMAN | E12: P | AF12: RAPORT | AG12: 0089987994 | AH12: 20527197 | AI12: FARDAN ABDILLAH NUR FIRDAUS | AJ12: L | AM12: =UPPER(D12) -> AFINA FILZAH KHAIRANA RACHMAN | AT12: 0105523137 | AU12: AFINA FILZAH KHAIRANA RACHMAN | AV12: P | AW12: SMPN 2 PAMEKASAN | AX12: 89.2 | AY12: 68.34 | AZ12: 80.86 | BA12: C | BB12: - | BD12: 15326 | BE12: 0105523137 | BF12: AFINA FILZAH KHAIRANA RACHMAN | BG12: C03
A13: 4 | B13: 15327 | C13: 0109145031 | D13: AFUZA GHANIAH KHAIRINA RACHMAN | E13: P | AF13: ZONASI | AG13: 0083785128 | AH13: 69980589 | AI13: HANIK AWALIYATUN NANDINI | AJ13: P | AM13: =UPPER(D13) -> AFUZA GHANIAH KHAIRINA RACHMAN | AT13: 0109145031 | AU13: AFUZA GHANIAH KHAIRINA RACHMAN | AV13: P | AW13: SMPN 2 PAMEKASAN | AX13: 89.34 | AY13: 63.34 | AZ13: 78.94 | BA13: C | BB13: (-) | BD13: 15327 | BE13: 0109145031 | BF13: AFUZA GHANIAH KHAIRINA RACHMAN | BG13: C04
A14: 5 | B14: 15331 | C14: 0102511323 | D14: AHMAD GHAISAN NAVIZ RAMADANI | E14: L | AF14: KIP | AG14: 0096593970 | AH14: 20527197 | AI14: HASNAH AL AFIYAH | AJ14: L | AM14: =UPPER(D14) -> AHMAD GHAISAN NAVIZ RAMADANI | AT14: 0102511323 | AU14: AHMAD GHAISAN NAVIZ RAMADANI | AV14: L | AW14: IIS SMP PROGRESSIVE BUMI SHALAWAT | AX14: 88.31 | AY14: 71.67 | AZ14: 81.65 | BA14: C | BB14: JUARA 1 OLIMPIADE BAHASA INDONESIA OLIMPIADE RIHAND CREATIVE BY UNIVERSITAS NEGERI MALANG | BD14: 15331 | BE14: 0102511323 | BF14: AHMAD GHAISAN NAVIZ RAMADANI | BG14: C05
A15: 6 | B15: 15362 | C15: 0114675356 | D15: ARIQOH SALSABILA RAMADHANI | E15: P | AF15: RAPORT | AG15: 0104564202 | AH15: 20583367 | AI15: KAYLA AIKO MARITZA | AJ15: P | AM15: =UPPER(D15) -> ARIQOH SALSABILA RAMADHANI | AT15: 0114675356 | AU15: ARIQOH SALSABILA RAMADHANI | AV15: P | AW15: SMP negeri 5 Pamekasan | AX15: 84.52 | AY15: 70 | AZ15: 78.71 | BA15: C | BB15: - | BD15: 15362 | BE15: 0114675356 | BF15: ARIQOH SALSABILA RAMADHANI | BG15: C06
A16: 7 | B16: 15386 | C16: 0114593863 | D16: BEZALEEL KEZIO BUDIJONO | E16: L | AF16: RAPORT | AG16: 0091869182 | AH16: 20527197 | AI16: MAJENDRA FAREL RIZKY HARIYANTO | AJ16: L | AM16: =UPPER(D16) -> BEZALEEL KEZIO BUDIJONO | AT16: 0114593863 | AU16: BEZALEEL KEZIO BUDIJONO | AV16: L | AW16: SMP NEGERI 2 PAMEKASAN | AX16: 89.37 | AY16: 58.34 | AZ16: 76.96 | BA16: C | BB16: - | BD16: 15386 | BE16: 0114593863 | BF16: BEZALEEL KEZIO BUDIJONO | BG16: C07
A17: 8 | B17: 15390 | C17: 0109772634 | D17: BINANDA SABRINA PUTRI KASYAFANI | E17: P | AF17: A.GURU | AG17: 0091835952 | AH17: 20527197 | AI17: Merisa Anggi Yulia Putri | AJ17: P | AM17: =UPPER(D17) -> BINANDA SABRINA PUTRI KASYAFANI | AT17: 0109772634 | AU17: BINANDA SABRINA PUTRI KASYAFANI | AV17: P | AW17: SMPN 2 Pamekasan | AX17: 91.89 | AY17: 76.67 | AZ17: 85.80 | BA17: C | BB17: - | BD17: 15390 | BE17: 0109772634 | BF17: BINANDA SABRINA PUTRI KASYAFANI | BG17: C08
A18: 9 | B18: 15413 | C18: 0106741833 | D18: FAIDAH ZALIMAR FUATUNSAKINAH | E18: P | AF18: ZONASI | AG18: 0093197545 | AH18: 20527180 | AI18: MILZI ALIFIA MAULIDA | AJ18: P | AM18: =UPPER(D18) -> FAIDAH ZALIMAR FUATUNSAKINAH | AT18: 0106741833 | AU18: FAIDAH ZALIMAR FUATUNSAKINAH | AV18: P | AW18: SMPN 1 Pamekasan | AX18: 93.20 | AY18: 91.67 | AZ18: 92.59 | BA18: C | BB18: juara 2 MCR dan LRP 2023, juara 1 Leo X Limit Tahun 2023, juara 2 The Competition'9 Mepel Matematika Tahun 2024, juara 3 "COMPASS VII" Tahun 2024, juara 1 OSN-K Mapel Matematika Tahun 2024, juara 3 Kompetisi Sains Madrasah Tahun 2024, juara 3 APOTEMA Tahun 2024, juara 1 Olimpiade Matematika Vektor Nasional 2025, juara 1 Olimpika Exploration V Tingkat SMP/MTS Sederajat Tahun 2024, juara 3 AMFIBI Mapel Matematika Tahun 2025, juara 1 Olimpiade Matematika (Khawarizm Competition) Tahun 2025, juara 1 MAFIKIBISA plus'25 Bidang Matematika Tahun 2025, juara 2 Kegiatan AL Uswah Treasure Hunt (AUSTERN) 2.0 Tahun 2025, juara 1 optima tahun 2026 dan juara 1 sigma unira tahun 2026 | BD18: 15413 | BE18: 0106741833 | BF18: FAIDAH ZALIMAR FUATUNSAKINAH | BG18: C09
A19: 10 | B19: 15415 | C19: 0115578774 | D19: FAIRUS HIDAYAH PRAWIDA | E19: P | AF19: AKDMK | AG19: 0082501965 | AH19: 20527166 | AI19: MOH GILANG MAULANA | AJ19: L | AM19: =UPPER(D19) -> FAIRUS HIDAYAH PRAWIDA | AT19: 0115578774 | AU19: FAIRUS HIDAYAH PRAWIDA | AV19: P | AW19: SMPN 2 Pamekasan | AX19: 91.2 | AY19: 76.67 | AZ19: 85.39 | BA19: C | BB19: (-) | BD19: 15415 | BE19: 0115578774 | BF19: FAIRUS HIDAYAH PRAWIDA | BG19: C10
A20: 11 | B20: 15416 | C20: 0106635170 | D20: FAISHAL BISRI ANSHORY | E20: L | AF20: RAPORT | AG20: 0087858823 | AH20: 20527197 | AI20: MOH SAHRUL MAULIDI | AJ20: L | AM20: =UPPER(D20) -> FAISHAL BISRI ANSHORY | AT20: 0106635170 | AU20: FAISHAL BISRI ANSHORY | AV20: L | AW20: SMP PUNCAK DARUS SALAM | AX20: 87.03 | AY20: 63.33 | AZ20: 77.55 | BA20: C | BB20: - | BD20: 15416 | BE20: 0106635170 | BF20: FAISHAL BISRI ANSHORY | BG20: C11
A21: 12 | B21: 15426 | C21: 0115830566 | D21: FATHIR PRATAMA ARIEF | E21: L | AF21: ZONASI | AG21: 0098382897 | AH21: 20527180 | AI21: MOHAMMAD IQBAL RISTRIANTO | AJ21: L | AM21: =UPPER(D21) -> FATHIR PRATAMA ARIEF | AT21: 0115830566 | AU21: FATHIR PRATAMA ARIEF | AV21: L | AW21: SMPN 1 PAMEKASAN | AX21: 82.03 | AY21: 60.00 | AZ21: 73.22 | BA21: C | BB21: - | BD21: 15426 | BE21: 0115830566 | BF21: FATHIR PRATAMA ARIEF | BG21: C12
A22: 13 | B22: 15445 | C22: 0107041594 | D22: GHAYDA AURYNA AZZARIA | E22: P | AF22: ZONASI | AG22: 0084713270 | AH22: 20527197 | AI22: MUHAMMAD YUSUF ADI PRATAMA | AJ22: L | AM22: =UPPER(D22) -> GHAYDA AURYNA AZZARIA | AT22: 0107041594 | AU22: GHAYDA AURYNA AZZARIA | AV22: P | AW22: SMP NEGERI 2 PAMEKASAN | AX22: 88.09 | AY22: 70 | AZ22: 80.85 | BA22: C | BB22: (-) | BD22: 15445 | BE22: 0107041594 | BF22: GHAYDA AURYNA AZZARIA | BG22: C13
A23: 14 | B23: 15449 | C23: 0113441591 | D23: GIOVANNI AURELIA FIDI FRONDEDY | E23: P | AF23: ZONASI | AG23: 0091521750 | AH23: 20527180 | AI23: NAFIL BERYL FAIRUZ | AJ23: L | AM23: =UPPER(D23) -> GIOVANNI AURELIA FIDI FRONDEDY | AT23: 0113441591 | AU23: GIOVANNI AURELIA FIDI FRONDEDY | AV23: P | AW23: SMPN 1 Sumenep | AX23: 91.20 | AY23: 63.34 | AZ23: 80.06 | BA23: C | BB23: - | BD23: 15449 | BE23: 0113441591 | BF23: GIOVANNI AURELIA FIDI FRONDEDY | BG23: C14
A24: 15 | B24: 15456 | C24: 0113481013 | D24: HUMAIRA A TAUFANI | E24: P | AF24: RAPORT | AG24: 3082973214 | AH24: 20528625 | AI24: NAUFAL RAHMATULLOH N A | AJ24: L | AM24: =UPPER(D24) -> HUMAIRA A TAUFANI | AT24: 0113481013 | AU24: HUMAIRA A TAUFANI | AV24: P | AW24: SMP plus Nurul Hikmah | AX24: 85.94 | AY24: 68.33 | AZ24: 78.90 | BA24: C | BB24: - | BD24: 15456 | BE24: 0113481013 | BF24: HUMAIRA A TAUFANI | BG24: C15
A25: 16 | B25: 15498 | C25: 0114940252 | D25: MARETA DWI MELANDRI | E25: P | AF25: KIP | AG25: 0091667325 | AH25: 20527202 | AI25: Naura Wilda Safitri | AJ25: P | AM25: =UPPER(D25) -> MARETA DWI MELANDRI | AT25: 0114940252 | AU25: MARETA DWI MELANDRI | AV25: P | AW25: Smpn 1 pademawu | AX25: 83.14 | AY25: 50.00 | AZ25: 69.88 | BA25: C | BB25: Ipa | BD25: 15498 | BE25: 0114940252 | BF25: MARETA DWI MELANDRI | BG25: C16
A26: 17 | B26: 15503 | C26: 0106532271 | D26: MAULIDIA NABILA SAFITRI | E26: P | AF26: RAPORT | AG26: 0097064727 | AH26: 20527197 | AI26: NAYLA SHAFA AZZAHRA | AJ26: P | AM26: =UPPER(D26) -> MAULIDIA NABILA SAFITRI | AT26: 0106532271 | AU26: MAULIDIA NABILA SAFITRI | AV26: P | AW26: SMP NEGERI 2 PAMEKASAN | AX26: 89.00 | AY26: 66.67 | AZ26: 80.07 | BA26: D | BB26: - | BD26: 15503 | BE26: 0106532271 | BF26: MAULIDIA NABILA SAFITRI | BG26: C17
A27: 18 | B27: 15506 | C27: 0105246267 | D27: MEGA PANGESTU | E27: P | AF27: ZONASI | AG27: 0093422775 | AH27: 20527197 | AI27: RAFEYFA ZALFA ZAHIRA | AJ27: P | AM27: =UPPER(#REF!) -> #REF! | AT27: 0105246267 | AU27: MEGA PANGESTU | AV27: P | AW27: SMP NEGERI 2 PAMEKASAN | AX27: 88.09 | AY27: 60.00 | AZ27: 76.85 | BA27: C | BB27: - | BD27: 15506 | BE27: 0105246267 | BF27: MEGA PANGESTU | BG27: C18
A28: 19 | B28: 15515 | C28: 0116019188 | D28: MOH AINUR ROFIQI | E28: L | AF28: NON AKD | AG28: 3080968608 | AH28: 70027854 | AI28: RAFIF KEMAL AZIZI | AJ28: L | AM28: =UPPER(D28) -> MOH AINUR ROFIQI | AT28: 0116019188 | AU28: MOH AINUR ROFIQI | AV28: L | AW28: MTs Nahdliyatul Islamiyah | AX28: 81.37 | AY28: 58.34 | AZ28: - | BA28: C | BB28: Juara 1 Kompetisi PAI dan Sains (KOMPAS) se-Madura Juara 2 HGN MAN 2 Pamekasan Juara 3 Pidato Bahasa Inggris PORSENI | BD28: 15515 | BE28: 0116019188 | BF28: MOH AINUR ROFIQI | BG28: C19
A29: 20 | B29: 15525 | C29: 0109107539 | D29: MOH JULIANTO ALFARIZI | E29: L | AF29: ZONASI | AG29: 0099672333 | AH29: 20527197 | AI29: RAHMI HUMAIRA | AJ29: P | AM29: =UPPER(D29) -> MOH JULIANTO ALFARIZI | AT29: 0109107539 | AU29: MOH JULIANTO ALFARIZI | AV29: L | AW29: SMPN 8 PAMEKASAN | AX29: 85.40 | AY29: 66.67 | AZ29: 77.91 | BA29: C | BB29: - | BD29: 15525 | BE29: 0109107539 | BF29: MOH JULIANTO ALFARIZI | BG29: C20
A30: 21 | B30: 15526 | C30: 3106372563 | D30: MOH RIZKI RADITYA UMAM | E30: L | AF30: NON AKD | AG30: 0096094178 | AH30: 20527180 | AI30: RAIS AULIA ATTAMIMY WIJAYA | AJ30: L | AM30: =UPPER(D30) -> MOH RIZKI RADITYA UMAM | AT30: 3106372563 | AU30: MOH RIZKI RADITYA UMAM | AV30: L | AW30: SMPN 1 PAMEKASAN | AX30: 90.86 | AY30: 78.34 | AZ30: 85.85 | BA30: C | BB30: JUARA 1 matematika PHYTAGORAS 2026, JUARA 1 matematika beregu leo×limit 2023, JUARA 1 matematika beregu 2024 ,juara 1 matematika beregu leo×limit 2025, juara harapan 1 metematika beregu omvn 2025, juara 2 matematika khawarizm competition 2024, Juara 3 matematika khawarizm competition 2025, juara 1 matematika beregu iof, juara 3 matematika SSO 2024, juara 3 matematika SSO 2024, juara 2 matematika sso 2026 Juara 1 Matematika Samed Plus 2025 Juara 2 Matematika Cosmos VII 2023 Juara Harapan 1 Mafikibisa Plus 2025 Juara IV Matematika MACINTOS 2025 Juara Harapan 1 Matematika Khawarizm competition 2026 Juara Harapan 2 Matematika Sigma Units 2024 | BD30: 15526 | BE30: 3106372563 | BF30: MOH RIZKI RADITYA UMAM | BG30: C21
A31: 22 | B31: 15560 | C31: 0116941093 | D31: NAILA ISTNAINI ZAHRA | E31: P | AF31: AKDMK | AG31: 0093455270 | AH31: 20527185 | AI31: REFATIA MIRZA VALENSI | AJ31: P | AM31: =UPPER(D31) -> NAILA ISTNAINI ZAHRA | AT31: 0116941093 | AU31: NAILA ISTNAINI ZAHRA | AV31: P | AW31: SMP NEGERI 2 PAMEKASAN | AX31: 85.51 | AY31: 61.67 | AZ31: 75.97 | BA31: C | BB31: tidak ada | BD31: 15560 | BE31: 0116941093 | BF31: NAILA ISTNAINI ZAHRA | BG31: C22
A32: 23 | B32: 15564 | C32: 3116785893 | D32: NAJWA AISSYATI ISMAN | E32: P | AF32: ZONASI | AG32: 0089426877 | AH32: 20527197 | AI32: SABRINA KIRANA AYU SUPRIYADI | AJ32: P | AM32: =UPPER(D32) -> NAJWA AISSYATI ISMAN | AT32: 3116785893 | AU32: NAJWA AISSYATI ISMAN | AV32: P | AW32: MTS DDI Masakambing | AX32: 81.93 | AY32: 38.33 | AZ32: 64.49 | BA32: C | BB32: Tidak ada | BD32: 15564 | BE32: 3116785893 | BF32: NAJWA AISSYATI ISMAN | BG32: C23
A33: 24 | B33: 15566 | C33: 0102399771 | D33: NASTAMA TRI ADITYA FASHA | E33: L | AF33: ZONASI | AG33: 0086479528 | AH33: 20583411 | AI33: SELVIA RAMADHANI | AJ33: P | AM33: =UPPER(D33) -> NASTAMA TRI ADITYA FASHA | AT33: 0102399771 | AU33: NASTAMA TRI ADITYA FASHA | AV33: L | AW33: SMPN 1 PAMEKASAN | AX33: 80.31 | AY33: 30.00 | AZ33: 60.19 | BA33: C | BB33: - | BD33: 15566 | BE33: 0102399771 | BF33: NASTAMA TRI ADITYA FASHA | BG33: C24
A34: 25 | B34: 15571 | C34: 0113204752 | D34: NAZLATUR RAHMAH | E34: P | AF34: ZONASI | AG34: 0087393847 | AH34: 20527185 | AI34: SHAHIBUL KAMALI RAHMAT HIDAYAT | AJ34: L | AM34: =UPPER(D34) -> NAZLATUR RAHMAH | AT34: 0113204752 | AU34: NAZLATUR RAHMAH | AV34: P | AW34: SMP PLUS NURUL HIKMAH | AX34: 86.57 | AY34: 70.00 | AZ34: 79.94 | BA34: C | BB34: - | BD34: 15571 | BE34: 0113204752 | BF34: NAZLATUR RAHMAH | BG34: C25
A35: 26 | B35: 15573 | C35: 0118414476 | D35: NIZAR AHZA ALAZZAM | E35: L | AF35: ZONASI | AG35: 0097102519 | AH35: 20527180 | AI35: SHIVA MAULIDYA PRASETIYO | AJ35: P | AM35: =UPPER(D35) -> NIZAR AHZA ALAZZAM | AT35: 0118414476 | AU35: NIZAR AHZA ALAZZAM | AV35: L | AW35: SMPN 1 Pamekasan | AX35: 91.14 | AY35: 80.00 | AZ35: 86.68 | BA35: C | BB35: Tidak ada | BD35: 15573 | BE35: 0118414476 | BF35: NIZAR AHZA ALAZZAM | BG35: C26
A36: 27 | B36: 15583 | C36: 0103189746 | D36: PURI AYU PUTRI BILQIS | E36: P | AF36: NON AKD | AG36: 0093962965 | AH36: 20583363 | AI36: SITI MAISHUROH ASSYIFA | AJ36: P | AM36: =UPPER(D36) -> PURI AYU PUTRI BILQIS | AT36: 0103189746 | AU36: PURI AYU PUTRI BILQIS | AV36: P | AW36: SMPN 1 PAMEKASAN | AX36: 90.89 | AY36: 71.67 | AZ36: 83.2 | BA36: C | BB36: - juara harapan 1 mapel ips, cosmis-viii - juara harapan 1 mapel ips, gamis competition'5 | BD36: 15583 | BE36: 0103189746 | BF36: PURI AYU PUTRI BILQIS | BG36: C27
A37: 28 | B37: 15588 | C37: 0104950261 | D37: PUTRY DESWIETA LADY AWALIA | E37: P | AM37: =UPPER(D37) -> PUTRY DESWIETA LADY AWALIA | AT37: 0104950261 | AU37: PUTRY DESWIETA LADY AWALIA | AV37: P | AW37: SMPN 2 PAMEKASAN | AX37: 84.80 | AY37: 56.67 | AZ37: 73.55 | BA37: C | BB37: - | BD37: 15588 | BE37: 0104950261 | BF37: PUTRY DESWIETA LADY AWALIA | BG37: C28
A38: 29 | B38: 15592 | C38: 0117957178 | D38: R FAKHRI ADLI NASHSHAR | E38: L | AM38: =UPPER(D38) -> R FAKHRI ADLI NASHSHAR | AT38: 0117957178 | AU38: R FAKHRI ADLI NASHSHAR | AV38: L | AW38: SMPN 2 PAMEKASAN | AX38: 86.75 | AY38: 56..67 | AZ38: 72.50 | BA38: C | BB38: tidak ada | BD38: 15592 | BE38: 0117957178 | BF38: R FAKHRI ADLI NASHSHAR | BG38: C29
A39: 30 | B39: 15593 | C39: 0105301606 | D39: RA SAFARAZ AUFA AZALIA | E39: P | AM39: =UPPER(D39) -> RA SAFARAZ AUFA AZALIA | AT39: 0105301606 | AU39: RA SAFARAZ AUFA AZALIA | AV39: P | AW39: SMPN 1 PAMEKASAN | AX39: 88.37 | AY39: 60.00 | AZ39: 77.02 | BA39: C | BB39: - | BD39: 15593 | BE39: 0105301606 | BF39: RA SAFARAZ AUFA AZALIA | BG39: C30
A40: 31 | B40: 15594 | C40: 0109047528 | D40: RAFI AGUNG PRAMANA | E40: L | AM40: =UPPER(D40) -> RAFI AGUNG PRAMANA | AT40: 0109047528 | AU40: RAFI AGUNG PRAMANA | AV40: L | AW40: SMPN 2 PAMEKASAN | AX40: 90.8 | AY40: 65 | AZ40: 80.48 | BA40: C | BB40: - | BD40: 15594 | BE40: 0109047528 | BF40: RAFI AGUNG PRAMANA | BG40: C31
...

Sheet X-4
AE1: RAPORT | AF1: 0096776269 | AG1: 20527197 | AH1: AISYAH ANA HARIYANTO | AI1: P
AE2: ZONASI | AF2: 0084641835 | AG2: 20566545 | AH2: AKRAM ARKANANTA FIRDAUS | AI2: L
AE3: ZONASI | AF3: 0083172664 | AG3: 20527180 | AH3: AL FATIH WAHYU BASALAMAH | AI3: L
A4: Tahun Pelajaran 2026 / 2027 | AE4: KIP | AF4: 0089933258 | AG4: 20527166 | AH4: ANDREA NAUFAL SETIAWAN | AI4: L
AE5: AKDMK | AF5: 0095415650 | AG5: 20527197 | AH5: APRILIA NURIL QOMARI | AI5: P
AE6: ZONASI | AF6: 0094693693 | AG6: 20566545 | AH6: AURA NADHIF HENDRA SYAHPUTRA | AI6: P
A7: No | B7: NIS | C7: NISN | D7: Nama Siswa | E7: L/P | F7: Wali Kelas : | I7: MOH. LUTFI KARIM, S.Si | T7: NIP : | V7: 199105032024211000 | AE7: ZONASI | AF7: 0098143816 | AG7: 20527180 | AH7: AZIMU NASYWA YATRIN | AI7: P
F8: Tanggal | AE8: RAPORT | AF8: 0082558863 | AG8: 20527185 | AH8: Bambang Fariaji | AI8: L
AE9: RAPORT | AF9: 0083494373 | AG9: 20527197 | AH9: CARISSA DWI PUTRI LARASATI | AI9: P
A10: 1 | B10: 15318 | C10: 0115900723 | D10: ABDULLAH HAKAM AL GHIFARI | E10: L | AE10: AKDMK | AF10: 0098040950 | AG10: 20527180 | AH10: CHRISTOFFER CONSTANTINE SANTOSO | AI10: L | AM10: =UPPER('X-7'!D10) -> AIDA DESTIYANA PUTRI | AV10: 0115900723 | AW10: ABDULLAH HAKAM AL GHIFARI | AX10: L | AY10: SMPN 2 PAMEKASAN | AZ10: 81.26 | BA10: 45 | BB10: 66.76 | BC10: D | BD10: tidak ada | BG10: 15318 | BH10: 0115900723 | BI10: ABDULLAH HAKAM AL GHIFARI | BJ10: D01
A11: 2 | B11: 15351 | C11: 0116058220 | D11: AMELIA PUTRI SRI RAHAYU | E11: P | AE11: ZONASI | AF11: 0091164419 | AG11: 20527197 | AH11: FATIMAH KASYAF FANIE WAHAB | AI11: P | AM11: =UPPER('X-10'!D14) -> ANDINI UTAMI ARYPUTRI | AV11: 0116058220 | AW11: AMELIA PUTRI SRI RAHAYU | AX11: P | AY11: SMPN 8 Pamekasan | AZ11: 91.86 | BA11: 63.34 | BB11: 80.45 | BC11: D | BD11: Juara 2 FTBI Carakan Madura | BG11: 15351 | BH11: 0116058220 | BI11: AMELIA PUTRI SRI RAHAYU | BJ11: D02
A12: 3 | B12: 15356 | C12: 0108111782 | D12: ANISA MARATUS SHOLEHAH | E12: P | AE12: ZONASI | AF12: 0086888062 | AG12: 20527197 | AH12: HUMAIR DZIKRI SYAHLANA | AI12: L | AM12: =UPPER('X-7'!D12) -> ALMIRA BASHITA KURNIAWAN | AV12: 0108111782 | AW12: ANISA MARATUS SHOLEHAH | AX12: P | AY12: MtsN 1 Pamekasan | AZ12: 88.48 | BA12: 55.00 | BB12: 75.09 | BC12: D | BD12: - | BG12: 15356 | BH12: 0108111782 | BI12: ANISA MARATUS SHOLEHAH | BJ12: D03
A13: 4 | B13: 15367 | C13: 0113664330 | D13: AUDRIA CALYA PUTRI SANTOSO | E13: P | AE13: ZONASI | AF13: 3089324280 | AG13: 20566545 | AH13: Keyzha Lucyana Adhia Rinda | AI13: P | AM13: =UPPER('X-7'!D13) -> BAGAS DWI BUSRI YAQIN | AV13: 0113664330 | AW13: AUDRIA CALYA PUTRI SANTOSO | AX13: P | AY13: SMPN 2 PAMEKASAN | AZ13: 90.86 | BA13: 63.33 | BB13: 79.85 | BC13: D | BD13: - | BG13: 15367 | BH13: 0113664330 | BI13: AUDRIA CALYA PUTRI SANTOSO | BJ13: D04
A14: 5 | B14: 15380 | C14: 0111948346 | D14: BAGAS DHELTA SABILA | E14: L | AE14: ZONASI | AF14: 0084247358 | AG14: 20527197 | AH14: LINDHA SYAFITRI | AI14: P | AM14: =UPPER('X-7'!D14) -> CARISA DAFITRI EFFENDI | AV14: 0111948346 | AW14: BAGAS DHELTA SABILA | AX14: L | AY14: SMP NEGERI 1 PAMEKASAN | AZ14: 90.09 | BA14: 71.67 | BB14: 82.72 | BC14: D | BD14: - | BG14: 15380 | BH14: 0111948346 | BI14: BAGAS DHELTA SABILA | BJ14: D05
A15: 6 | B15: 15393 | C15: 0119037165 | D15: CHARADINA FALIH UTAMI | E15: P | AE15: RAPORT | AF15: 0098583778 | AG15: 20583367 | AH15: LIVIA AURATUS ORYZA SATIVA | AI15: P | AM15: =UPPER('X-7'!D15) -> DAANISH RAFFI ALFARISI | AV15: 0119037165 | AW15: CHARADINA FALIH UTAMI | AX15: P | AY15: SMP NEGERI 1 PAMEKASAN | AZ15: 87.49 | BA15: 75 | BB15: 82.49 | BC15: D | BD15: (-) | BG15: 15393 | BH15: 0119037165 | BI15: CHARADINA FALIH UTAMI | BJ15: D06
A16: 7 | B16: 15400 | C16: 0106704469 | D16: DANIEL DWI PRASETYO ARIFIN | E16: L | AE16: RAPORT | AF16: 0084705460 | AG16: 20583367 | AH16: M ABYAN FAITH FAWAZEE | AI16: L | AM16: =UPPER('X-10'!D38) -> PUTERA IRJAYANI RAHMAN | AV16: 0106704469 | AW16: DANIEL DWI PRASETYO ARIFIN | AX16: L | AY16: SMPN 1 PAMEKASAN | AZ16: 86.29 | BA16: 51.67 | BB16: 72.44 | BC16: D | BD16: - | BG16: 15400 | BH16: 0106704469 | BI16: DANIEL DWI PRASETYO ARIFIN | BJ16: D07
A17: 8 | B17: 15405 | C17: 0106291799 | D17: DHIMAS AHMAD SULTHONI | E17: L | AE17: RAPORT | AF17: 0085989808 | AG17: 20527197 | AH17: MEIDY ARYANTO WIGUNA | AI17: L | AM17: =UPPER('X-7'!D17) -> DELISHA SABRINA PUTRI SURYA | AV17: 0106291799 | AW17: DHIMAS AHMAD SULTHONI | AX17: L | AY17: SMP Plus Nurul Hikmah | AZ17: 87.26 | BA17: 61.67 | BB17: 77.02 | BC17: D | BD17: (-) | BG17: 15405 | BH17: 0106291799 | BI17: DHIMAS AHMAD SULTHONI | BJ17: D08
A18: 9 | B18: 15408 | C18: 0108696856 | D18: ELLISA HABIBAH | E18: P | AE18: ZONASI | AF18: 0092567020 | AG18: 20579418 | AH18: MOH ADITYA MAULANA PUTRA | AI18: L | AM18: =UPPER('X-7'!D18) -> FAIHA NADA ZALFA | AV18: 0108696856 | AW18: ELLISA HABIBAH | AX18: P | AY18: SMP NEGERI 7 PAMEKASAN | AZ18: 83.51 | BA18: 65.00 | BB18: 76.11 | BC18: D | BD18: - | BG18: 15408 | BH18: 0108696856 | BI18: ELLISA HABIBAH | BJ18: D09
A19: 10 | B19: 15418 | C19: 0114428936 | D19: FAIZA AQILA MECCA | E19: P | AE19: ZONASI | AF19: 0089276032 | AG19: 20527197 | AH19: MOH AFGAN BARLIYANTO | AI19: L | AM19: =UPPER('X-7'!D19) -> FITRIA ASIFATUS ZAHRO | AV19: 0114428936 | AW19: FAIZA AQILA MECCA | AX19: P | AY19: SMP Negeri 2 Pamekasan | AZ19: 91.2 | BA19: 76.67 | BB19: 85.39 | BC19: D | BD19: - Juara 1 Olimpiade Bahasa Indonesia (OBI) Se-Madura yang diselenggarakan oleh Himaba FKIP UNIRA. | BG19: 15418 | BH19: 0114428936 | BI19: FAIZA AQILA MECCA | BJ19: D10
A20: 11 | B20: 15420 | C20: 0104596735 | D20: FARADIBA CARISSA PUTRI | E20: P | AE20: NON AKD | AF20: 0085784500 | AG20: 20527195 | AH20: MOH ALFAN KURNIAWAN | AI20: L | AM20: =UPPER('X-7'!D20) -> FITRIYAH | AV20: 0104596735 | AW20: FARADIBA CARISSA PUTRI | AX20: P | AY20: SMPN 2 Pamekasan | AZ20: 86.11 | BA20: 65.00 | BB20: 77.67 | BC20: D | BD20: - | BG20: 15420 | BH20: 0104596735 | BI20: FARADIBA CARISSA PUTRI | BJ20: D11
A21: 12 | B21: 15435 | C21: 0114795074 | D21: FIJRI MEIDY ROZITA | E21: P | AE21: ZONASI | AF21: 0092307512 | AG21: 20527180 | AH21: MOH ARAFA DWI PURWANTO | AI21: L | AM21: =UPPER('X-7'!D21) -> GIBRAN ABDILLAH DHOVAIRY | AV21: 0114795074 | AW21: FIJRI MEIDY ROZITA | AX21: P | AY21: SMPN 8 Pamekasan | AZ21: 91.03 | BA21: 71.67 | BB21: 83.29 | BC21: D | BD21: - | BG21: 15435 | BH21: 0114795074 | BI21: FIJRI MEIDY ROZITA | BJ21: D12
A22: 13 | B22: 15437 | C22: 0119559729 | D22: FITRI ANNISA SOLIHAH | E22: P | AE22: RAPORT | AF22: 0095526227 | AG22: 20528625 | AH22: MOH REZA FEBRILIYANTO | AI22: L | AM22: =UPPER('X-7'!D22) -> IZZA SAYRA QIRANI | AV22: 0119559729 | AW22: FITRI ANNISA SOLIHAH | AX22: P | AY22: MTS NAHDLIYATUL ISLAMIYAH | AZ22: 76.03 | BA22: 40.00 | BB22: 61.62 | BC22: D | BD22: (-) | BG22: 15437 | BH22: 0119559729 | BI22: FITRI ANNISA SOLIHAH | BJ22: D13
A23: 14 | B23: 15440 | C23: 0118922095 | D23: FRANDA DIVINA CARISSA TAN | E23: P | AE23: ZONASI | AF23: 0093901388 | AG23: 20527180 | AH23: MOHAMMAD GHAVIN AZZARYA TAMRIN | AI23: L | AM23: =UPPER('X-7'!D23) -> JUNDIYULHAQ ALMUJADID | AV23: 0118922095 | AW23: FRANDA DIVINA CARISSA TAN | AX23: P | AY23: SMPN 2 PAMEKASAN | AZ23: 88.40 | BA23: 65 | BB23: 79.04 | BC23: D | BD23: - | BG23: 15440 | BH23: 0118922095 | BI23: FRANDA DIVINA CARISSA TAN | BJ23: D14
A24: 15 | B24: 15452 | C24: 0105498999 | D24: HAFIIZH NURBILLA | E24: L | AE24: ZONASI | AF24: 0094661980 | AG24: 20527180 | AH24: MOHAMMAD RIZQI FADILAH | AI24: L | AM24: =UPPER('X-7'!D24) -> KARINA ULYA HARYADI | AV24: 0105498999 | AW24: HAFIIZH NURBILLA | AX24: L | AY24: SMP NEGERI 2 PAMEKASAN | AZ24: 85.69 | BA24: 58.33 | BB24: 74.75 | BC24: D | BD24: TIDAK ADA | BG24: 15452 | BH24: 0105498999 | BI24: HAFIIZH NURBILLA | BJ24: D15
A25: 16 | B25: 15473 | C25: 0111772899 | D25: KAYLA ANUGERAH RAMADHANI | E25: P | AE25: ZONASI | AF25: 0088261483 | AG25: 20566545 | AH25: MUHAMMAD IQBAL LISMARTA | AI25: L | AM25: =UPPER('X-7'!D25) -> KHAIZURAN RABBANI AHNAF | AV25: 0111772899 | AW25: KAYLA ANUGERAH RAMADHANI | AX25: P | AY25: SMPN 2 PAMEKASAN | AZ25: 90.97 | BA25: 80.00 | BB25: 86.58 | BC25: D | BD25: 1. Juara 3 OSN IPS tingkat Kabupaten 2. Peringkat 7 OSN IPS tingkat kabupaten 3. Peringkat 2 Pelatihan Pra- OSN-P 2025 tingkat Provinsi(Erick institut) 4. Semi-Finalis Phytagoras +21 (IPS) se-Madura(smansa) 5. Semi-Finalis Phytagoras +22 (Bahasa Inggris) se-Madura (smansa) | BG25: 15473 | BH25: 0111772899 | BI25: KAYLA ANUGERAH RAMADHANI | BJ25: D16
A26: 17 | B26: 15475 | C26: 0101928629 | D26: KEIZA ALMIRA RAMADHANI ROFAN | E26: P | AE26: RAPORT | AF26: 3099461393 | AG26: 20528625 | AH26: MULIA ANNISA SETYA WARDANI | AI26: P | AM26: =UPPER('X-7'!#REF!) -> #REF! | AV26: 0101928629 | AW26: KEIZA ALMIRA RAMADHANI ROFAN | AX26: P | AY26: SMP NEGERI 2 PAMEKASAN | AZ26: 89.34 | BA26: 50.00 | BB26: 73.60 | BC26: D | BD26: Juara 2 Story Telling Competition, Finalis Provinsi Jawa Timur Matematika LEVEL 4. | BG26: 15475 | BH26: 0101928629 | BI26: KEIZA ALMIRA RAMADHANI ROFAN | BJ26: D17
A27: 18 | B27: 15480 | C27: 0119485437 | D27: KINARA SEPTRI FITRIA | E27: P | AE27: NON AKD | AF27: 0081535841 | AG27: 20527197 | AH27: NADHIFA SUCIANI HUWAIDA | AI27: P | AM27: =UPPER('X-10'!D45) -> ZAKI AGATHA | AV27: 0119485437 | AW27: KINARA SEPTRI FITRIA | AX27: P | AY27: SMP PLUS NURUL HIKMAH | AZ27: 88.06 | BA27: 60.00 | BB27: 76.84 | BC27: D | BD27: - | BG27: 15480 | BH27: 0119485437 | BI27: KINARA SEPTRI FITRIA | BJ27: D18
A28: 19 | B28: 15485 | C28: 0101304244 | D28: LIVIANA ZAHROTUL AMALIYAH | E28: P | AE28: RAPORT | AF28: 0083375001 | AG28: 20527197 | AH28: NAZIFA SALSABILA | AI28: P | AM28: =UPPER('X-7'!D28) -> LYNA ELZA RAMADANI | AV28: 0101304244 | AW28: LIVIANA ZAHROTUL AMALIYAH | AX28: P | AY28: SMP NEGERI 1 PAMEKASAN | AZ28: 92.06 | BA28: 70.00 | BB28: 83.24 | BC28: D | BD28: 1. JUARA 1 MAPEL FISIKA DALAM AJANG “PEKAN RAYA ILMIAH (PRI)” UIN SYARIF HIDAYATULLAH TK.NASIONAL 2025 2. JUARA 1 MAPEL IPA DALAM AJANG “SCIENCE SALATIGA OLYMPIAD (SSO)” UIN SALATIGA TK.NASIONAL 2025 3. JUARA 3 MAPEL IPA DALAM AJANG “OLIENCE” UIN SUNAN AMPEL SURABAYA TK.PROVINSI 2024 4. JUARA HARAPAN 1 MAPEL IPA DALAM AJANG “CHROMOSOM” UNIVERSITAS TRUNOJOYO MADURA SE-SURABAYA DAN MADURA 2025 5. JUARA HARAPAN 2 IPA DALAM AJANG “CHROMOSOM” UNIVERSITAS TRUNOJOYO MADURA SE-SURABAYA DAN MADURA 2024 6. MEDALI PERAK IPA DALAM AJANG “OSIRIS” SMAUBP AMANATUL UMMAH TK.NASIONAL 2025 7. JUARA 2 BIOLOGI DALAM AJANG “S2LC”SMALA SE-JAWA DAN BALI 2024 8. JUARA 1 IPA DALAM AJANG “SAMED PLUS” SE-MADURA 2025 9. JUARA 2 IPA DALAM AJANG “SAMED PLUS”SE-MADURA 2024 10. JUARA 2 ESAI TK.KABUPATEN 2024 11. JUARA 2 CERPEN DALAM AJANG FTBI TK.KABUPATEN 2025 12. PERINGKAT 7 OLIMPIADE SAINS NASIONAL (OSN) MAPEL IPA 2024 13. PERINGKAT 7 LOMBA MENULIS ESAI TK.KABUPATEN 2025 14. JUARA HARAPAN 2 MATHEMATICS AND SCIENCE ON SMADA (MACINTOS) TK.PROVINSI 2025 | BG28: 15485 | BH28: 0101304244 | BI28: LIVIANA ZAHROTUL AMALIYAH | BJ28: D19
A29: 20 | B29: 15495 | C29: 0106943785 | D29: MAHSYARIS ALVERRO RIZQI SYAHDIANRA | E29: L | AE29: ZONASI | AF29: 0087193172 | AG29: 20527197 | AH29: NUR SYARIF | AI29: L | AM29: =UPPER('X-7'!D29) -> M FAUZUL RAHMAN IRDIANSYAH | AV29: 0106943785 | AW29: MAHSYARIS ALVERRO RIZQI SYAHDIANRA | AX29: L | AY29: SMPN 1 Pamekasan | AZ29: 93.03 | BA29: 90.00 | BB29: 91.82 | BC29: D | BD29: Juara 2 PHYTA Bahasa Inggris | BG29: 15495 | BH29: 0106943785 | BI29: MAHSYARIS ALVERRO RIZQI SYAHDIANRA | BJ29: D20
A30: 21 | B30: 15507 | C30: 0109027972 | D30: MEILINDA PUTRI WIDIANITA | E30: P | AE30: A.GURU | AF30: 0088070697 | AG30: 20527197 | AH30: R AYU NOURA AZKIA | AI30: P | AM30: =UPPER('X-5'!D13) -> AISAH SABRINA SALSABIYLA | AV30: 0109027972 | AW30: MEILINDA PUTRI WIDIANITA | AX30: P | AY30: smpn 2 pamekasan | AZ30: 87.11 | BA30: 52 | BB30: 72.93 | BC30: D | BD30: - | BG30: 15507 | BH30: 0109027972 | BI30: MEILINDA PUTRI WIDIANITA | BJ30: D21
A31: 22 | B31: 15519 | C31: 0103443988 | D31: MOH CHOKY AHZANUR KUSNADI | E31: L | AE31: ZONASI | AF31: 0098997217 | AG31: 20527197 | AH31: R RAIHANUN FEBRIYANA SUGIHARTO | AI31: P | AM31: =UPPER('X-9'!D19) -> BELLY WIJAYA PRATAMA | AV31: 0103443988 | AW31: MOH CHOKY AHZANUR KUSNADI | AX31: L | AY31: SMPN 1 PAMEKASAN | AZ31: 82.51 | BA31: 50.00 | BB31: 69.51 | BC31: D | BD31: - | BG31: 15519 | BH31: 0103443988 | BI31: MOH CHOKY AHZANUR KUSNADI | BJ31: D22
A32: 23 | B32: 15531 | C32: 0104091877 | D32: MOHAMMAD ANAS AMRULLAH | E32: L | AE32: AKDMK | AF32: 0083012066 | AG32: 20529915 | AH32: REISYA SATYA AYU PRAMESWARI | AI32: P | AM32: =UPPER('X-7'!D33) -> MUHAMMAD RAFI ABDULLAH | AV32: 0104091877 | AW32: MOHAMMAD ANAS AMRULLAH | AX32: L | AY32: SMPN 1 PAMEKASAN | AZ32: 83.86 | BA32: 76.67 | BB32: 80.98 | BC32: D | BD32: - | BG32: 15531 | BH32: 0104091877 | BI32: MOHAMMAD ANAS AMRULLAH | BJ32: D23
A33: 24 | B33: 15543 | C33: 0127097427 | D33: MUHAMMAD ARIQ ULWAN | E33: L | AE33: ZONASI | AF33: 0088888355 | AG33: 20583367 | AH33: SAVIRA ELDIANA | AI33: P | AM33: =UPPER('X-7'!D34) -> MUHAMMAD RIZQI ZAMZAMI | AV33: 0127097427 | AW33: MUHAMMAD ARIQ ULWAN | AX33: L | AY33: MTsN 3 PAMEKASAN | AZ33: 90.58 | BA33: 68.33 | BB33: 81.68 | BC33: D | BD33: (-) | BG33: 15543 | BH33: 0127097427 | BI33: MUHAMMAD ARIQ ULWAN | BJ33: D24
