Workbook

Sheet semua kls
AE1: ZONASI | AF1: 0097062522 | AG1: 20527197 | AH1: ACHMAD RIZQON JANUAR | AI1: L
AE2: ZONASI | AF2: 0093351007 | AG2: 20583363 | AH2: Adintya Djasmine Aulia | AI2: P
AE3: ZONASI | AF3: 0065403876 | AG3: 20527197 | AH3: AMIEN FIRDAUS | AI3: L
A4: Tahun Pelajaran 2025 / 2026 | AE4: RAPORT | AF4: 0099607321 | AG4: 20527180 | AH4: AUFA FIKRI FIRDAUS | AI4: L
AE5: ZONASI | AF5: 0087421628 | AG5: 20527202 | AH5: Bagas Mahardika Putra | AI5: L
AE6: ZONASI | AF6: 0088629626 | AG6: 20527180 | AH6: BELVA PRATISARA DIYAS | AI6: P
A7: No | B7: NIS | C7: NISN | D7: Nama Siswa | E7: L/P | F7: Wali Kelas : | I7: RATNAWATI SUDIARSIH, S.S.i | T7: NIP : | V7: 19780412 200604 2 018 | AE7: RAPORT | AF7: 0092639463 | AG7: 20527197 | AH7: DAFFA MAULIDAN PUTRA LAKSONO | AI7: L
F8: TGL : | N8: TGL : | V8: TGL : | AE8: KIP | AF8: 0085034059 | AG8: 20566545 | AH8: Desvita Anggraini | AI8: P
F9: 1 | G9: 2 | H9: 3 | I9: 4 | J9: 5 | K9: 6 | L9: 7 | M9: 8 | N9: 1 | O9: 2 | P9: 3 | Q9: 4 | R9: 5 | S9: 6 | T9: 7 | U9: 8 | V9: 1 | W9: 2 | X9: 3 | Y9: 4 | Z9: 5 | AA9: 6 | AB9: 7 | AC9: 8 | AE9: RAPORT | AF9: 0082864028 | AG9: 20527193 | AH9: Dirgantara Fairuz Iftikhori | AI9: L
A10: 1 | B10: 14596 | C10: 0097062522 | D10: ACHMAD RIZQON JANUAR | E10: L | G10: A | AE10: RAPORT | AF10: 0082847597 | AG10: 20527180 | AH10: FIYHIMA AINANI TAJRIYAN | AI10: P | AJ10: =UPPER(D10) -> ACHMAD RIZQON JANUAR | AY10: 1 | AZ10: 14591 | BA10: 0082986450 | BB10: ACH IMAM MURTADHO | BC10: L | BD10: A
A11: 2 | B11: 14600 | C11: 0088648714 | D11: ADINDA ZIFANNA OKTAFIA | E11: P | G11: A | AE11: AKDMK | AF11: 0093695374 | AG11: 20528609 | AH11: GILANG ALFAHRIZI | AI11: L | AJ11: =UPPER(D11) -> ADINDA ZIFANNA OKTAFIA | AY11: 2 | AZ11: 14601 | BA11: 0093351007 | BB11: ADINTYA DJASMINE AULIA | BC11: P | BD11: A
A12: 3 | B12: 14603 | C12: 0099522649 | D12: ADLI YUSUF ALIFDI | E12: L | G12: A | AE12: AKDMK | AF12: 0088601519 | AG12: 20583410 | AH12: HILMAN FUADI | AI12: L | AJ12: =UPPER(D12) -> ADLI YUSUF ALIFDI | AY12: 3 | AZ12: 14602 | BA12: 0087175500 | BB12: ADLI MOURA ADYTIA RAUF | BC12: L | BD12: A
A13: 4 | B13: 14609 | C13: 0096776269 | D13: AISYAH ANA HARIYANTO | E13: P | G13: A | AE13: KIP | AF13: 0092932213 | AG13: 20527185 | AH13: ISWAHYUDI ARIF SETIAWAN | AI13: L | AJ13: =UPPER(D13) -> AISYAH ANA HARIYANTO | AY13: 4 | AZ13: 14603 | BA13: 0099522649 | BB13: ADLI YUSUF ALIFDI | BC13: L | BD13: A
A14: 6 | B14: 14611 | C14: 0086109051 | D14: AISYAH AZZAHRA | E14: P | G14: A | AE14: ZONASI | AF14: 0083224313 | AG14: 20527197 | AH14: LATIFA SALMA | AI14: P | AJ14: =UPPER(D14) -> AISYAH AZZAHRA | AY14: 5 | AZ14: 14614 | BA14: 0095256057 | BB14: AKBAR RAHMATULLAH RAMADHAN | BC14: L | BD14: A
A15: 7 | B15: 14631 | C15: 3099859817 | D15: ANAS NUR ASMORI | E15: L | G15: A | AE15: RAPORT | AF15: 0098566431 | AG15: 20527197 | AH15: MARSYANAIRA VANESA CELIA | AI15: P | AJ15: =UPPER(D15) -> ANAS NUR ASMORI | AY15: 6 | AZ15: 14616 | BA15: 0084641835 | BB15: AKRAM ARKANANTA FIRDAUS | BC15: L | BD15: A
A16: 3 | B16: 14635 | C16: 0089933258 | D16: ANDREA NAUFAL SETIAWAN | E16: L | G16: A | AE16: RAPORT | AF16: 0099315210 | AG16: 20528625 | AH16: MIFTAHUL FADLI DANIAR | AI16: L | AJ16: =UPPER(D16) -> ANDREA NAUFAL SETIAWAN | AY16: 7 | AZ16: 14619 | BA16: 0095986339 | BB16: ALDO SUKMA MAULIDZI | BC16: L | BD16: A
A17: 9 | B17: 14640 | C17: 0095088946 | D17: ARIANNA FATHIA LATHIEFANI | E17: P | G17: A | AE17: ZONASI | AF17: 0099559196 | AG17: 20527180 | AH17: MOH FIKI ALAN FAJRI | AI17: L | AJ17: =UPPER(D17) -> ARIANNA FATHIA LATHIEFANI | AY17: 8 | AZ17: 14621 | BA17: 0096013702 | BB17: ALISHA RAMADHANI POERNOMO | BC17: P | BD17: A
A18: 3 | B18: 14643 | C18: 0083337131 | D18: ARINI ULFA HIDAYATI | E18: P | G18: A | AE18: ZONASI | AF18: 0087638152 | AG18: 20527197 | AH18: MOH RAFLI AMIRUL IMAN | AI18: L | AJ18: =UPPER(D18) -> ARINI ULFA HIDAYATI | AY18: 9 | AZ18: 14628 | BA18: 0083093788 | BB18: AMELIA RIZKI RAMADHANI SURYANTO | BC18: P | BD18: A
A19: 5 | B19: 14646 | C19: 0094498632 | D19: ARYA DEFIAN AL FARABI | E19: L | G19: A | AE19: ZONASI | AF19: 0087990908 | AG19: 20527197 | AH19: MOH RISHAL HIDAYAT | AI19: L | AJ19: =UPPER(D19) -> ARYA DEFIAN AL FARABI | AY19: 10 | AZ19: 14660 | BA19: 0098143816 | BB19: AZIMU NASYWA YATRIN | BC19: P | BD19: A
A20: 12 | B20: 14657 | C20: 0081651505 | D20: AURIGA SYAFHA FAIRUZ SYAHREZA | E20: L | G20: A | AE20: ZONASI | AF20: 0096039518 | AG20: 20527197 | AH20: MOHMASYRUR | AI20: L | AJ20: =UPPER(D20) -> AURIGA SYAFHA FAIRUZ SYAHREZA | AY20: 11 | AZ20: 14663 | BA20: 0088629626 | BB20: BELVA PRATISARA DIYAS | BC20: P | BD20: A
A21: 8 | B21: 14679 | C21: 0098040950 | D21: CHRISTOFFER CONSTANTINE SANTOSO | E21: L | G21: A | AE21: ZONASI | AF21: 0095615344 | AG21: 69816340 | AH21: MUHAMMAD FAKHRY HIDAYAT | AI21: L | AJ21: =UPPER(D21) -> CHRISTOFFER CONSTANTINE SANTOSO | AY21: 12 | AZ21: 14664 | BA21: 0093463371 | BB21: BENNETT WANG | BC21: L | BD21: A
... A27: 17 | B27: 14743 | C27: 0104564202 | D27: KAYLA AIKO MARITZA | E27: P | G27: A | AE27: KIP | AF27: 0086615669 | AG27: 20527202 | AH27: Oktarina Syawla Putri | AI27: P | AJ27: =UPPER(D27) -> KAYLA AIKO MARITZA | AY27: 18 | AZ27: 14713 | BA27: 0156061180 | BB27: FIRZA AMIRA EL FAIZA | BC27: P | BD27: A
A28: 12 | B28: 14764 | C28: 0085428877 | D28: MALIKA ALFATIA PUTRI | E28: P | G28: A | AE28: RAPORT | AF28: 3081834782 | AG28: 20528625 | AH28: RARA QONITA ROYHANI | AI28: P | AJ28: =UPPER(D28) -> MALIKA ALFATIA PUTRI | AY28: 19 | AZ28: 14728 | BA28: 0084133818 | BB28: HIFANI DWI ARFIANSYAH | BC28: L | BD28: A
A29: 20 | B29: 14767 | C29: 0083556423 | D29: MARVEL GILBERT VILIANTO | E29: L | G29: A | AE29: ZONASI | AF29: 0086255643 | AG29: 20527180 | AH29: REVIANA ZAHRA | AI29: P | AJ29: =UPPER(D29) -> MARVEL GILBERT VILIANTO | AY29: 20 | AZ29: 14746 | BA29: 3089324280 | BB29: KEYZHA LUCYANA ADHIA RINDA | BC29: P | BD29: A
A30: 21 | B30: 14790 | C30: 0099057804 | D30: MOH RIZKY ADITIANSYAH | E30: L | G30: A | AE30: NON AKD | AF30: 0095745897 | AG30: 20527193 | AH30: RIZKIANA INTANSARI | AI30: P | AJ30: =UPPER(D30) -> MOH RIZKY ADITIANSYAH | AY30: 21 | AZ30: 14765 | BA30: 0082984202 | BB30: MALIKA APRILIA SYAFIUN | BC30: P | BD30: A
A31: 22 | B31: 14793 | C31: 0093607543 | D31: MOH ZACKY MAULANA FIRDAUSI | E31: L | G31: A | AE31: AKDMK | AF31: 0083907588 | AG31: 20527180 | AH31: RUH SYAFIRA CAHYANING PAWASA | AI31: P | AJ31: =UPPER(D31) -> MOH ZACKY MAULANA FIRDAUSI | AY31: 22 | AZ31: 14768 | BA31: 0092796237 | BB31: MAULANA AINUL YAQIN | BC31: L | BD31: A
A32: 27 | B32: 14796 | C32: 0081411031 | D32: MOHAMMAD ALVI SYAHRIN | E32: L | G32: A | AE32: ZONASI | AF32: 0083041624 | AG32: 20527197 | AH32: SALSABILA PUTRI HIDAYAT | AI32: P | AJ32: =UPPER(D32) -> MOHAMMAD ALVI SYAHRIN | AY32: 23 | AZ32: 14772 | BA32: 0081442566 | BB32: MEITA NAJMI BERLIANTI | BC32: P | BD32: A
A33: 19 | B33: 14820 | C33: 0094289783 | D33: MUHAMMAD NADHIF AZARIA PUTRA | E33: L | G33: A | AE33: RAPORT | AF33: 0109424194 | AG33: 20583367 | AH33: SARAH SALSABILA | AI33: P | AJ33: =UPPER(D33) -> MUHAMMAD NADHIF AZARIA PUTRA | AY33: 24 | AZ33: 14799 | BA33: 0093901388 | BB33: MOHAMMAD GHAVIN AZZARYA TAMRIN | BC33: L | BD33: A
A34: 20 | B34: 14824 | C34: 0083986747 | D34: MUHAMMAD RIZQI MAULIDI | E34: L | G34: A | AE34: RAPORT | AF34: 0081315442 | AG34: 20527197 | AH34: SEPTI RAHMADIYANTI | AI34: P | AJ34: =UPPER(D34) -> MUHAMMAD RIZQI MAULIDI | AY34: 25 | AZ34: 14809 | BA34: 0098327801 | BB34: MUHAMMAD FAKHRULLAH AGIEL | BC34: L | BD34: A
A35: 29 | B35: 14836 | C35: 0093580431 | D35: NALANDA SYAHBANIA ARDHIANSYAH | E35: P | G35: A | AE35: ZONASI | AF35: 0085713874 | AG35: 20527180 | AH35: TANIA KHANZA FIRNANDA RAMADHANI | AI35: P | AJ35: =UPPER(D35) -> NALANDA SYAHBANIA ARDHIANSYAH | AY35: 26 | AZ35: 14821 | BA35: 0093657785 | BB35: MUHAMMAD NIBRAS FACHRULLAH | BC35: L | BD35: A
A36: 31 | B36: 14855 | C36: 0086800316 | D36: NUR RIZQA ZANJABILA | E36: P | G36: A | AE36: NON AKD | AF36: 0099637523 | AG36: 20527197 | AH36: Tulus Firmansyah | AI36: L | AJ36: =UPPER(D36) -> NUR RIZQA ZANJABILA | AY36: 27 | AZ36: 14839 | BA36: 0081216364 | BB36: NAUFAL ALWAN HAKIM | BC36: L | BD36: A
A37: 29 | B37: 14858 | C37: 0088066553 | D37: NURINDA NOVIANTI | E37: P | G37: A | AJ37: =UPPER(D37) -> NURINDA NOVIANTI | AY37: 28 | AZ37: 14843 | BA37: 0091667325 | BB37: NAURA WILDA SAFITRI | BC37: P | BD37: A
A38: 29 | B38: 14866 | C38: 0092243247 | D38: PATO ALTHAF MULYAWAN | E38: L | G38: A | AJ38: =UPPER(D38) -> PATO ALTHAF MULYAWAN | AY38: 29 | AZ38: 14847 | BA38: 0081449501 | BB38: NAYLA CLARESTA MEDISTYA | BC38: P | BD38: A
A39: 25 | B39: 14870 | C39: 0096807022 | D39: PUTRI RIZKI FAMADANI | E39: P | G39: A | AJ39: =UPPER(D39) -> PUTRI RIZKI FAMADANI | AY39: 30 | AZ39: 14848 | BA39: 0097064727 | BB39: NAYLA SHAFA AZZAHRA | BC39: P | BD39: A
A40: 30 | B40: 14871 | C40: 0098997217 | D40: R RAIHANUN FEBRIYANA SUGIHARTO | E40: P | G40: A | AJ40: =UPPER(D40) -> R RAIHANUN FEBRIYANA SUGIHARTO | AY40: 31 | AZ40: 14850 | BA40: 0097690860 | BB40: NAZWA AULIA NUR ROSIDAH | BC40: P | BD40: A
A41: 30 | B41: 14881 | C41: 0096094178 | D41: RAIS AULIA ATTAMIMY WIJAYA | E41: L | G41: A | AJ41: =UPPER(D41) -> RAIS AULIA ATTAMIMY WIJAYA | AY41: 32 | AZ41: 14863 | BA41: 0091784100 | BB41: OWEN FILIPO SANTOSO | BC41: L | BD41: A
A42: 29 | B42: 14886 | C42: 3081834782 | D42: RARA QONITA ROYHANI | E42: P | G42: A | AJ42: =UPPER(D42) -> RARA QONITA ROYHANI | AY42: 33 | AZ42: 14901 | BA42: 0081550255 | BB42: SABRINA YASMIN FIRYAL SISWANTO | BC42: P | BD42: A
A43: 34 | B43: 14894 | C43: 0099773502 | D43: RIANA MAULIDIA | E43: P | G43: A | AJ43: =UPPER(D43) -> RIANA MAULIDIA | AY43: 34 | AZ43: 14908 | BA43: 0088888355 | BB43: SAVIRA ELDIANA | BC43: P | BD43: A
A44: 36 | B44: 14934 | C44: 0089463780 | D44: UMI KULSUM WARDANI | E44: P | G44: A | AJ44: =UPPER(D44) -> UMI KULSUM WARDANI | AY44: 35 | AZ44: 14937 | BA44: 0093897835 | BB44: VINA ISTIANA | BC44: P | BD44: A
A45: 4 | B45: 14940 | C45: 0085106484 | D45: VIRGI AZMI YUSSININGTYAS | E45: P | G45: A | AJ45: =UPPER(D45) -> VIRGI AZMI YUSSININGTYAS | AY45: 36 | AZ45: 14947 | BA45: 0083715423 | BB45: ZAUMAR ABDURRAHMAN RITONGA | BC45: L | BD45: A
...

Sheet KELAS
AE1: ZONASI | AF1: 0097062522 | AG1: 20527197 | AH1: ACHMAD RIZQON JANUAR | AI1: L
AE2: ZONASI | AF2: 0093351007 | AG2: 20583363 | AH2: Adintya Djasmine Aulia | AI2: P
AE3: ZONASI | AF3: 0065403876 | AG3: 20527197 | AH3: AMIEN FIRDAUS | AI3: L
A4: Tahun Pelajaran 2024 / 2025 | AE4: RAPORT | AF4: 0099607321 | AG4: 20527180 | AH4: AUFA FIKRI FIRDAUS | AI4: L
AE5: ZONASI | AF5: 0087421628 | AG5: 20527202 | AH5: Bagas Mahardika Putra | AI5: L
AE6: ZONASI | AF6: 0088629626 | AG6: 20527180 | AH6: BELVA PRATISARA DIYAS | AI6: P
A7: No | B7: NIS | C7: NISN | D7: Nama Siswa | E7: L/P | F7: Wali Kelas : | I7: SOEGIHARTO B.P., S.Pd. | T7: NIP : | V7: 197008312006041004 - III/c | AE7: RAPORT | AF7: 0092639463 | AG7: 20527197 | AH7: DAFFA MAULIDAN PUTRA LAKSONO | AI7: L
F8: TGL : | N8: TGL : | V8: TGL : | AE8: KIP | AF8: 0085034059 | AG8: 20566545 | AH8: Desvita Anggraini | AI8: P
F9: 1 | G9: 2 | H9: 3 | I9: 4 | J9: 5 | K9: 6 | L9: 7 | M9: 8 | N9: 1 | O9: 2 | P9: 3 | Q9: 4 | R9: 5 | S9: 6 | T9: 7 | U9: 8 | V9: 1 | W9: 2 | X9: 3 | Y9: 4 | Z9: 5 | AA9: 6 | AB9: 7 | AC9: 8 | AE9: RAPORT | AF9: 0082864028 | AG9: 20527193 | AH9: Dirgantara Fairuz Iftikhori | AI9: L
A10: 1 | B10: 14591 | C10: 0082986450 | D10: ACH IMAM MURTADHO | E10: L | AD10: A | AE10: RAPORT | AF10: 0082847597 | AG10: 20527180 | AH10: FIYHIMA AINANI TAJRIYAN | AI10: P | AJ10: =UPPER(D10) -> ACH IMAM MURTADHO
A11: 2 | B11: 14601 | C11: 0093351007 | D11: ADINTYA DJASMINE AULIA | E11: P | AD11: A | AE11: AKDMK | AF11: 0093695374 | AG11: 20528609 | AH11: GILANG ALFAHRIZI | AI11: L | AJ11: =UPPER(D11) -> ADINTYA DJASMINE AULIA
A12: 3 | B12: 14602 | C12: 0087175500 | D12: ADLI MOURA ADYTIA RAUF | E12: L | AD12: A | AE12: AKDMK | AF12: 0088601519 | AG12: 20583410 | AH12: HILMAN FUADI | AI12: L | AJ12: =UPPER(D12) -> ADLI MOURA ADYTIA RAUF
A13: 4 | B13: 14603 | C13: 0099522649 | D13: ADLI YUSUF ALIFDI | E13: L | AD13: A | AE13: KIP | AF13: 0092932213 | AG13: 20527185 | AH13: ISWAHYUDI ARIF SETIAWAN | AI13: L | AJ13: =UPPER(D13) -> ADLI YUSUF ALIFDI
A14: 5 | B14: 14614 | C14: 0095256057 | D14: AKBAR RAHMATULLAH RAMADHAN | E14: L | AD14: A | AE14: ZONASI | AF14: 0083224313 | AG14: 20527197 | AH14: LATIFA SALMA | AI14: P | AJ14: =UPPER(D14) -> AKBAR RAHMATULLAH RAMADHAN
A15: 6 | B15: 14616 | C15: 0084641835 | D15: AKRAM ARKANANTA FIRDAUS | E15: L | AD15: A | AE15: RAPORT | AF15: 0098566431 | AG15: 20527197 | AH15: MARSYANAIRA VANESA CELIA | AI15: P | AJ15: =UPPER(D15) -> AKRAM ARKANANTA FIRDAUS
A16: 7 | B16: 14619 | C16: 0095986339 | D16: ALDO SUKMA MAULIDZI | E16: L | AD16: A | AE16: RAPORT | AF16: 0099315210 | AG16: 20528625 | AH16: MIFTAHUL FADLI DANIAR | AI16: L | AJ16: =UPPER(D16) -> ALDO SUKMA MAULIDZI
A17: 8 | B17: 14621 | C17: 0096013702 | D17: ALISHA RAMADHANI POERNOMO | E17: P | AD17: A | AE17: ZONASI | AF17: 0099559196 | AG17: 20527180 | AH17: MOH FIKI ALAN FAJRI | AI17: L | AJ17: =UPPER(D17) -> ALISHA RAMADHANI POERNOMO
A18: 9 | B18: 14628 | C18: 0083093788 | D18: AMELIA RIZKI RAMADHANI SURYANTO | E18: P | AD18: A | AE18: ZONASI | AF18: 0087638152 | AG18: 20527197 | AH18: MOH RAFLI AMIRUL IMAN | AI18: L | AJ18: =UPPER(D18) -> AMELIA RIZKI RAMADHANI SURYANTO
A19: 10 | B19: 14660 | C19: 0098143816 | D19: AZIMU NASYWA YATRIN | E19: P | AD19: A | AE19: ZONASI | AF19: 0087990908 | AG19: 20527197 | AH19: MOH RISHAL HIDAYAT | AI19: L | AJ19: =UPPER(D19) -> AZIMU NASYWA YATRIN
A20: 11 | B20: 14663 | C20: 0088629626 | D20: BELVA PRATISARA DIYAS | E20: P | AD20: A | AE20: ZONASI | AF20: 0096039518 | AG20: 20527197 | AH20: MOHMASYRUR | AI20: L | AJ20: =UPPER(D20) -> BELVA PRATISARA DIYAS
A21: 12 | B21: 14664 | C21: 0093463371 | D21: BENNETT WANG | E21: L | AD21: A | AE21: ZONASI | AF21: 0095615344 | AG21: 69816340 | AH21: MUHAMMAD FAKHRY HIDAYAT | AI21: L | AJ21: =UPPER(D21) -> BENNETT WANG
... A27: 18 | B27: 14713 | C27: 0156061180 | D27: FIRZA AMIRA EL FAIZA | E27: P | AD27: A | AE27: KIP | AF27: 0086615669 | AG27: 20527202 | AH27: Oktarina Syawla Putri | AI27: P | AJ27: =UPPER(D27) -> FIRZA AMIRA EL FAIZA
A28: 19 | B28: 14728 | C28: 0084133818 | D28: HIFANI DWI ARFIANSYAH | E28: L | AD28: A | AE28: RAPORT | AF28: 3081834782 | AG28: 20528625 | AH28: RARA QONITA ROYHANI | AI28: P | AJ28: =UPPER(D28) -> HIFANI DWI ARFIANSYAH
A29: 20 | B29: 14746 | C29: 3089324280 | D29: KEYZHA LUCYANA ADHIA RINDA | E29: P | AD29: A | AE29: ZONASI | AF29: 0086255643 | AG29: 20527180 | AH29: REVIANA ZAHRA | AI29: P | AJ29: =UPPER(D29) -> KEYZHA LUCYANA ADHIA RINDA
A30: 21 | B30: 14765 | C30: 0082984202 | D30: MALIKA APRILIA SYAFIUN | E30: P | AD30: A | AE30: NON AKD | AF30: 0095745897 | AG30: 20527193 | AH30: RIZKIANA INTANSARI | AI30: P | AJ30: =UPPER(D30) -> MALIKA APRILIA SYAFIUN
A31: 22 | B31: 14768 | C31: 0092796237 | D31: MAULANA AINUL YAQIN | E31: L | AD31: A | AE31: AKDMK | AF31: 0083907588 | AG31: 20527180 | AH31: RUH SYAFIRA CAHYANING PAWASA | AI31: P | AJ31: =UPPER(D31) -> MAULANA AINUL YAQIN
A32: 23 | B32: 14772 | C32: 0081442566 | D32: MEITA NAJMI BERLIANTI | E32: P | AD32: A | AE32: ZONASI | AF32: 0083041624 | AG32: 20527197 | AH32: SALSABILA PUTRI HIDAYAT | AI32: P | AJ32: =UPPER(D32) -> MEITA NAJMI BERLIANTI
A33: 24 | B33: 14799 | C33: 0093901388 | D33: MOHAMMAD GHAVIN AZZARYA TAMRIN | E33: L | AD33: A | AE33: RAPORT | AF33: 0109424194 | AG33: 20583367 | AH33: SARAH SALSABILA | AI33: P | AJ33: =UPPER(D33) -> MOHAMMAD GHAVIN AZZARYA TAMRIN
A34: 25 | B34: 14809 | C34: 0098327801 | D34: MUHAMMAD FAKHRULLAH AGIEL | E34: L | AD34: A | AE34: RAPORT | AF34: 0081315442 | AG34: 20527197 | AH34: SEPTI RAHMADIYANTI | AI34: P | AJ34: =UPPER(D34) -> MUHAMMAD FAKHRULLAH AGIEL
A35: 26 | B35: 14821 | C35: 0093657785 | D35: MUHAMMAD NIBRAS FACHRULLAH | E35: L | AD35: A | AE35: ZONASI | AF35: 0085713874 | AG35: 20527180 | AH35: TANIA KHANZA FIRNANDA RAMADHANI | AI35: P | AJ35: =UPPER(D35) -> MUHAMMAD NIBRAS FACHRULLAH
A36: 27 | B36: 14839 | C36: 0081216364 | D36: NAUFAL ALWAN HAKIM | E36: L | AD36: A | AE36: NON AKD | AF36: 0099637523 | AG36: 20527197 | AH36: Tulus Firmansyah | AI36: L | AJ36: =UPPER(D36) -> NAUFAL ALWAN HAKIM
A37: 28 | B37: 14843 | C37: 0091667325 | D37: NAURA WILDA SAFITRI | E37: P | AD37: A | AJ37: =UPPER(D37) -> NAURA WILDA SAFITRI
A38: 29 | B38: 14847 | C38: 0081449501 | D38: NAYLA CLARESTA MEDISTYA | E38: P | AD38: A | AJ38: =UPPER(D38) -> NAYLA CLARESTA MEDISTYA
A39: 30 | B39: 14848 | C39: 0097064727 | D39: NAYLA SHAFA AZZAHRA | E39: P | AD39: A | AJ39: =UPPER(D39) -> NAYLA SHAFA AZZAHRA
A40: 31 | B40: 14850 | C40: 0097690860 | D40: NAZWA AULIA NUR ROSIDAH | E40: P | AD40: A | AJ40: =UPPER(D40) -> NAZWA AULIA NUR ROSIDAH
A41: 32 | B41: 14863 | C41: 0091784100 | D41: OWEN FILIPO SANTOSO | E41: L | AD41: A | AJ41: =UPPER(D41) -> OWEN FILIPO SANTOSO
A42: 33 | B42: 14901 | C42: 0081550255 | D42: SABRINA YASMIN FIRYAL SISWANTO | E42: P | AD42: A | AJ42: =UPPER(D42) -> SABRINA YASMIN FIRYAL SISWANTO
A43: 34 | B43: 14908 | C43: 0088888355 | D43: SAVIRA ELDIANA | E43: P | AD43: A | AJ43: =UPPER(D43) -> SAVIRA ELDIANA
A44: 35 | B44: 14937 | C44: 0093897835 | D44: VINA ISTIANA | E44: P | AD44: A | AJ44: =UPPER(D44) -> VINA ISTIANA
A45: 36 | B45: 14947 | C45: 0083715423 | D45: ZAUMAR ABDURRAHMAN RITONGA | E45: L | AD45: A | AJ45: =UPPER(D45) -> ZAUMAR ABDURRAHMAN RITONGA
...

Sheet no-induk
AE1: ZONASI | AF1: 0097062522 | AG1: 20527197 | AH1: ACHMAD RIZQON JANUAR | AI1: L
AE2: ZONASI | AF2: 0093351007 | AG2: 20583363 | AH2: Adintya Djasmine Aulia | AI2: P
AE3: ZONASI | AF3: 0065403876 | AG3: 20527197 | AH3: AMIEN FIRDAUS | AI3: L
A4: Tahun Pelajaran 2024 / 2025 | AE4: RAPORT | AF4: 0099607321 | AG4: 20527180 | AH4: AUFA FIKRI FIRDAUS | AI4: L
AE5: ZONASI | AF5: 0087421628 | AG5: 20527202 | AH5: Bagas Mahardika Putra | AI5: L
AE6: ZONASI | AF6: 0088629626 | AG6: 20527180 | AH6: BELVA PRATISARA DIYAS | AI6: P
A7: No | B7: NIS | C7: NISN | D7: Nama Siswa | E7: L/P | F7: Wali Kelas : | I7: SOEGIHARTO B.P., S.Pd. | T7: NIP : | V7: 197008312006041004 - III/c | AE7: RAPORT | AF7: 0092639463 | AG7: 20527197 | AH7: DAFFA MAULIDAN PUTRA LAKSONO | AI7: L
F8: TGL : | N8: TGL : | V8: TGL : | AE8: KIP | AF8: 0085034059 | AG8: 20566545 | AH8: Desvita Anggraini | AI8: P
F9: 1 | G9: 2 | H9: 3 | I9: 4 | J9: 5 | K9: 6 | L9: 7 | M9: 8 | N9: 1 | O9: 2 | P9: 3 | Q9: 4 | R9: 5 | S9: 6 | T9: 7 | U9: 8 | V9: 1 | W9: 2 | X9: 3 | Y9: 4 | Z9: 5 | AA9: 6 | AB9: 7 | AC9: 8 | AE9: RAPORT | AF9: 0082864028 | AG9: 20527193 | AH9: Dirgantara Fairuz Iftikhori | AI9: L
A10: 1 | B10: 14589 | C10: 0099987267 | D10: ABD HAMID MANAF | E10: L | AD10: D | AE10: RAPORT | AF10: 0082847597 | AG10: 20527180 | AH10: FIYHIMA AINANI TAJRIYAN | AI10: P | AJ10: =UPPER(D10) -> ABD HAMID MANAF
A11: 2 | B11: 14590 | C11: 0095463618 | D11: ABDURRAHMAN | E11: L | AD11: D | AE11: AKDMK | AF11: 0093695374 | AG11: 20528609 | AH11: GILANG ALFAHRIZI | AI11: L | AJ11: =UPPER(D11) -> ABDURRAHMAN
A12: 3 | B12: 14591 | C12: 0082986450 | D12: ACH IMAM MURTADHO | E12: L | AD12: A | AE12: AKDMK | AF12: 0088601519 | AG12: 20583410 | AH12: HILMAN FUADI | AI12: L | AJ12: =UPPER(D12) -> ACH IMAM MURTADHO
A13: 4 | B13: 14592 | C13: 0096081695 | D13: ACH NURUL HIDAYAT | E13: L | AD13: D | AE13: KIP | AF13: 0092932213 | AG13: 20527185 | AH13: ISWAHYUDI ARIF SETIAWAN | AI13: L | AJ13: =UPPER(D13) -> ACH NURUL HIDAYAT
A14: 5 | B14: 14593 | C14: 0087980048 | D14: ACH RIZKY RAMADHANA R | E14: L | AD14: H | AE14: ZONASI | AF14: 0083224313 | AG14: 20527197 | AH14: LATIFA SALMA | AI14: P | AJ14: =UPPER(D14) -> ACH RIZKY RAMADHANA R
A15: 6 | B15: 14594 | C15: 0092559700 | D15: ACHMAD AFIM INTI ISTIQAM | E15: L | AD15: I | AE15: RAPORT | AF15: 0098566431 | AG15: 20527197 | AH15: MARSYANAIRA VANESA CELIA | AI15: P | AJ15: =UPPER(D15) -> ACHMAD AFIM INTI ISTIQAM
A16: 7 | B16: 14595 | C16: 0097637507 | D16: ACHMAD RAFI AKBAR | E16: L | AD16: J | AE16: RAPORT | AF16: 0099315210 | AG16: 20528625 | AH16: MIFTAHUL FADLI DANIAR | AI16: L | AJ16: =UPPER(D16) -> ACHMAD RAFI AKBAR
A17: 8 | B17: 14596 | C17: 0097062522 | D17: ACHMAD RIZQON JANUAR | E17: L | AD17: F | AE17: ZONASI | AF17: 0099559196 | AG17: 20527180 | AH17: MOH FIKI ALAN FAJRI | AI17: L | AJ17: =UPPER(D17) -> ACHMAD RIZQON JANUAR
A18: 9 | B18: 14597 | C18: 0091162442 | D18: ADELIA ZAHRA WIEGUNANDA | E18: P | AD18: I | AE18: ZONASI | AF18: 0087638152 | AG18: 20527197 | AH18: MOH RAFLI AMIRUL IMAN | AI18: L | AJ18: =UPPER(D18) -> ADELIA ZAHRA WIEGUNANDA
A19: 10 | B19: 14598 | C19: 0097358875 | D19: ADILA RASYADAH RAHMAN | E19: P | AD19: I | AE19: ZONASI | AF19: 0087990908 | AG19: 20527197 | AH19: MOH RISHAL HIDAYAT | AI19: L | AJ19: =UPPER(D19) -> ADILA RASYADAH RAHMAN
A20: 11 | B20: 14599 | C20: 0088105454 | D20: ADINDA AYU RISTIANTI | E20: P | AD20: I | AE20: ZONASI | AF20: 0096039518 | AG20: 20527197 | AH20: MOHMASYRUR | AI20: L | AJ20: =UPPER(D20) -> ADINDA AYU RISTIANTI
A21: 12 | B21: 14600 | C21: 0088648714 | D21: ADINDA ZIFANNA OKTAFIA | E21: P | AD21: H | AE21: ZONASI | AF21: 0095615344 | AG21: 69816340 | AH21: MUHAMMAD FAKHRY HIDAYAT | AI21: L | AJ21: =UPPER(D21) -> ADINDA ZIFANNA OKTAFIA
... A27: 18 | B27: 14606 | C27: 3082095795 | D27: AGUSDHANI WAFRI | E27: L | AD27: H | AE27: KIP | AF27: 0086615669 | AG27: 20527202 | AH27: Oktarina Syawla Putri | AI27: P | AJ27: =UPPER(D27) -> AGUSDHANI WAFRI
A28: 19 | B28: 14607 | C28: 0098516635 | D28: AHMAD FAIZ RAHMATILLAH | E28: L | AD28: E | AE28: RAPORT | AF28: 3081834782 | AG28: 20528625 | AH28: RARA QONITA ROYHANI | AI28: P | AJ28: =UPPER(D28) -> AHMAD FAIZ RAHMATILLAH
A29: 20 | B29: 14608 | C29: 0095865130 | D29: AHMAD FARHAN HAKIKI | E29: L | AD29: J | AE29: ZONASI | AF29: 0086255643 | AG29: 20527180 | AH29: REVIANA ZAHRA | AI29: P | AJ29: =UPPER(D29) -> AHMAD FARHAN HAKIKI
A30: 21 | B30: 14609 | C30: 0096776269 | D30: AISYAH ANA HARIYANTO | E30: P | AD30: E | AE30: NON AKD | AF30: 0095745897 | AG30: 20527193 | AH30: RIZKIANA INTANSARI | AI30: P | AJ30: =UPPER(D30) -> AISYAH ANA HARIYANTO
A31: 22 | B31: 14610 | C31: 0091238339 | D31: AISYAH ANI HARIYANTO | E31: P | AD31: J | AE31: AKDMK | AF31: 0083907588 | AG31: 20527180 | AH31: RUH SYAFIRA CAHYANING PAWASA | AI31: P | AJ31: =UPPER(D31) -> AISYAH ANI HARIYANTO
A32: 23 | B32: 14611 | C32: 0086109051 | D32: AISYAH AZZAHRA | E32: P | AD32: D | AE32: ZONASI | AF32: 0083041624 | AG32: 20527197 | AH32: SALSABILA PUTRI HIDAYAT | AI32: P | AJ32: =UPPER(D32) -> AISYAH AZZAHRA
A33: 24 | B33: 14612 | C33: 0085516582 | D33: AIZZA RAHMATIN NUR NADIN | E33: P | AD33: I | AE33: RAPORT | AF33: 0109424194 | AG33: 20583367 | AH33: SARAH SALSABILA | AI33: P | AJ33: =UPPER(D33) -> AIZZA RAHMATIN NUR NADIN
A34: 25 | B34: 14613 | C34: 0093808972 | D34: AJESIA PRABU ANGGORO HARIYANTO | E34: L | AD34: J | AE34: RAPORT | AF34: 0081315442 | AG34: 20527197 | AH34: SEPTI RAHMADIYANTI | AI34: P | AJ34: =UPPER(D34) -> AJESIA PRABU ANGGORO HARIYANTO
A35: 26 | B35: 14614 | C35: 0095256057 | D35: AKBAR RAHMATULLAH RAMADHAN | E35: L | AD35: A | AE35: ZONASI | AF35: 0085713874 | AG35: 20527180 | AH35: TANIA KHANZA FIRNANDA RAMADHANI | AI35: P | AJ35: =UPPER(D35) -> AKBAR RAHMATULLAH RAMADHAN
A36: 27 | B36: 14615 | C36: 0092554098 | D36: AKH. RASYA EFENDI PUTRA | E36: L | AD36: H | AE36: NON AKD | AF36: 0099637523 | AG36: 20527197 | AH36: Tulus Firmansyah | AI36: L | AJ36: =UPPER(D36) -> AKH. RASYA EFENDI PUTRA
A37: 28 | B37: 14616 | C37: 0084641835 | D37: AKRAM ARKANANTA FIRDAUS | E37: L | AD37: A | AJ37: =UPPER(D37) -> AKRAM ARKANANTA FIRDAUS
A38: 29 | B38: 14617 | C38: 0087180491 | D38: AKSA AHMAD | E38: L | AD38: G | AJ38: =UPPER(D38) -> AKSA AHMAD
A39: 30 | B39: 14618 | C39: 0083172664 | D39: AL FATIH WAHYU BASALAMAH | E39: L | AD39: B | AJ39: =UPPER(D39) -> AL FATIH WAHYU BASALAMAH
A40: 31 | B40: 14619 | C40: 0095986339 | D40: ALDO SUKMA MAULIDZI | E40: L | AD40: A | AJ40: =UPPER(D40) -> ALDO SUKMA MAULIDZI
A41: 32 | B41: 14620 | C41: 0102524441 | D41: ALFISA SYAHIRA SUTIKNO | E41: P | AD41: H | AJ41: =UPPER(D41) -> ALFISA SYAHIRA SUTIKNO
A42: 33 | B42: 14621 | C42: 0096013702 | D42: ALISHA RAMADHANI POERNOMO | E42: P | AD42: A | AJ42: =UPPER(D42) -> ALISHA RAMADHANI POERNOMO
A43: 34 | B43: 14622 | C43: 0083060697 | D43: ALLAFA ALYYUS SULTANSYAH WIDJAYA | E43: L | AD43: B | AJ43: =UPPER(D43) -> ALLAFA ALYYUS SULTANSYAH WIDJAYA
A44: 35 | B44: 14623 | C44: 0093440845 | D44: ALLENA GIOVANNY SUGIARTO | E44: P | AD44: B | AJ44: =UPPER(D44) -> ALLENA GIOVANNY SUGIARTO
A45: 36 | B45: 14624 | C45: 0105298760 | D45: ALVINA RIZKI ANDINI | E45: P | AD45: E | AJ45: =UPPER(D45) -> ALVINA RIZKI ANDINI
...

Sheet XII-A-1
AE1: ZONASI | AF1: 0097062522 | AG1: 20527197 | AH1: ACHMAD RIZQON JANUAR | AI1: L
AE2: ZONASI | AF2: 0093351007 | AG2: 20583363 | AH2: Adintya Djasmine Aulia | AI2: P
AE3: ZONASI | AF3: 0065403876 | AG3: 20527197 | AH3: AMIEN FIRDAUS | AI3: L
A4: Tahun Pelajaran 2026 / 2027 | AE4: RAPORT | AF4: 0099607321 | AG4: 20527180 | AH4: AUFA FIKRI FIRDAUS | AI4: L
AE5: ZONASI | AF5: 0087421628 | AG5: 20527202 | AH5: Bagas Mahardika Putra | AI5: L
AE6: ZONASI | AF6: 0088629626 | AG6: 20527180 | AH6: BELVA PRATISARA DIYAS | AI6: P
A7: No | B7: NIS | C7: NISN | D7: Nama Siswa | E7: L/P | F7: Wali Kelas : | I7: RATNAWATI SUDIARSIH, S.S.i | T7: NIP : | V7: 19780412 200604 2 018 | AE7: RAPORT | AF7: 0092639463 | AG7: 20527197 | AH7: DAFFA MAULIDAN PUTRA LAKSONO | AI7: L
F8: Tanggal | AE8: KIP | AF8: 0085034059 | AG8: 20566545 | AH8: Desvita Anggraini | AI8: P
F9: 1 | G9: 2 | H9: 3 | I9: 4 | J9: 5 | K9: 6 | L9: 7 | M9: 8 | N9: 1 | O9: 2 | P9: 3 | Q9: 4 | R9: 5 | S9: 6 | T9: 7 | U9: 8 | V9: 1 | W9: 2 | X9: 3 | Y9: 4 | Z9: 5 | AA9: 6 | AB9: 7 | AC9: 8 | AE9: RAPORT | AF9: 0082864028 | AG9: 20527193 | AH9: Dirgantara Fairuz Iftikhori | AI9: L
A10: 1 | B10: 14596 | C10: 0097062522 | D10: ACHMAD RIZQON JANUAR | E10: L | AE10: RAPORT | AF10: 0082847597 | AG10: 20527180 | AH10: FIYHIMA AINANI TAJRIYAN | AI10: P | AJ10: =UPPER(D10) -> ACHMAD RIZQON JANUAR | AZ10: 1 | BA10: 0097062522 / 14596 | BB10: ACHMAD RIZQON JANUAR | BC10: L
A11: 2 | B11: 14600 | C11: 0088648714 | D11: ADINDA ZIFANNA OKTAFIA | E11: P | AE11: AKDMK | AF11: 0093695374 | AG11: 20528609 | AH11: GILANG ALFAHRIZI | AI11: L | AJ11: =UPPER(D11) -> ADINDA ZIFANNA OKTAFIA | AZ11: 2 | BA11: 0088648714 / 14600 | BB11: ADINDA ZIFANNA OKTAFIA | BC11: P
A12: 3 | B12: 14603 | C12: 0099522649 | D12: ADLI YUSUF ALIFDI | E12: L | AE12: AKDMK | AF12: 0088601519 | AG12: 20583410 | AH12: HILMAN FUADI | AI12: L | AJ12: =UPPER(D12) -> ADLI YUSUF ALIFDI | AZ12: 3 | BA12: 0099522649 / 14603 | BB12: ADLI YUSUF ALIFDI | BC12: L
A13: 4 | B13: 14609 | C13: 0096776269 | D13: AISYAH ANA HARIYANTO | E13: P | AE13: KIP | AF13: 0092932213 | AG13: 20527185 | AH13: ISWAHYUDI ARIF SETIAWAN | AI13: L | AJ13: =UPPER(D13) -> AISYAH ANA HARIYANTO | AZ13: 4 | BA13: 0096776269 / 14609 | BB13: AISYAH ANA HARIYANTO | BC13: P
A14: 5 | B14: 14611 | C14: 0086109051 | D14: AISYAH AZZAHRA | E14: P | AE14: ZONASI | AF14: 0083224313 | AG14: 20527197 | AH14: LATIFA SALMA | AI14: P | AJ14: =UPPER(D14) -> AISYAH AZZAHRA | AZ14: 5 | BA14: 0086109051 / 14611 | BB14: AISYAH AZZAHRA | BC14: P
A15: 6 | B15: 14631 | C15: 3099859817 | D15: ANAS NUR ASMORI | E15: L | AE15: RAPORT | AF15: 0098566431 | AG15: 20527197 | AH15: MARSYANAIRA VANESA CELIA | AI15: P | AJ15: =UPPER(D15) -> ANAS NUR ASMORI | AZ15: 6 | BA15: 3099859817 / 14631 | BB15: ANAS NUR ASMORI | BC15: L
A16: 7 | B16: 14635 | C16: 0089933258 | D16: ANDREA NAUFAL SETIAWAN | E16: L | AE16: RAPORT | AF16: 0099315210 | AG16: 20528625 | AH16: MIFTAHUL FADLI DANIAR | AI16: L | AJ16: =UPPER(D16) -> ANDREA NAUFAL SETIAWAN | AZ16: 7 | BA16: 0089933258 / 14635 | BB16: ANDREA NAUFAL SETIAWAN | BC16: L
A17: 8 | B17: 14640 | C17: 0095088946 | D17: ARIANNA FATHIA LATHIEFANI | E17: P | AE17: ZONASI | AF17: 0099559196 | AG17: 20527180 | AH17: MOH FIKI ALAN FAJRI | AI17: L | AJ17: =UPPER(D17) -> ARIANNA FATHIA LATHIEFANI | AZ17: 8 | BA17: 0095088946 / 14640 | BB17: ARIANNA FATHIA LATHIEFANI | BC17: P
A18: 9 | B18: 14643 | C18: 0083337131 | D18: ARINI ULFA HIDAYATI | E18: P | AE18: ZONASI | AF18: 0087638152 | AG18: 20527197 | AH18: MOH RAFLI AMIRUL IMAN | AI18: L | AJ18: =UPPER(D18) -> ARINI ULFA HIDAYATI | AZ18: 9 | BA18: 0083337131 / 14643 | BB18: ARINI ULFA HIDAYATI | BC18: P
A19: 10 | B19: 14646 | C19: 0094498632 | D19: ARYA DEFIAN AL FARABI | E19: L | AE19: ZONASI | AF19: 0087990908 | AG19: 20527197 | AH19: MOH RISHAL HIDAYAT | AI19: L | AJ19: =UPPER(D19) -> ARYA DEFIAN AL FARABI | AZ19: 10 | BA19: 0094498632 / 14646 | BB19: ARYA DEFIAN AL FARABI | BC19: L
A20: 11 | B20: 14657 | C20: 0081651505 | D20: AURIGA SYAFHA FAIRUZ SYAHREZA | E20: L | AE20: ZONASI | AF20: 0096039518 | AG20: 20527197 | AH20: MOHMASYRUR | AI20: L | AJ20: =UPPER(D20) -> AURIGA SYAFHA FAIRUZ SYAHREZA | AZ20: 11 | BA20: 0081651505 / 14657 | BB20: AURIGA SYAFHA FAIRUZ SYAHREZA | BC20: L
A21: 12 | B21: 14700 | C21: 0097949164 | D21: FAKHRILLAH HASAN | E21: L | AE21: ZONASI | AF21: 0083566346 | AG21: 20527197 | AH21: NADYA AZMI KHAIRUNNISA | AI21: P | AJ21: =UPPER(D21) -> FAKHRILLAH HASAN | AZ21: 13 | BA21: 0097949164 / 14700 | BB21: FAKHRILLAH HASAN | BC21: L
... A26: 17 | B26: 14743 | C26: 0104564202 | D26: KAYLA AIKO MARITZA | E26: P | AE26: KIP | AF26: 0086615669 | AG26: 20527202 | AH26: Oktarina Syawla Putri | AI26: P | AJ26: =UPPER(D26) -> KAYLA AIKO MARITZA | AZ26: 18 | BA26: 0104564202 / 14743 | BB26: KAYLA AIKO MARITZA | BC26: P
A27: 18 | B27: 14764 | C27: 0085428877 | D27: MALIKA ALFATIA PUTRI | E27: P | AE27: RAPORT | AF27: 3081834782 | AG27: 20528625 | AH27: RARA QONITA ROYHANI | AI27: P | AJ27: =UPPER(D27) -> MALIKA ALFATIA PUTRI | AZ27: 19 | BA27: 0085428877 / 14764 | BB27: MALIKA ALFATIA PUTRI | BC27: P
A28: 19 | B28: 14767 | C28: 0083556423 | D28: MARVEL GILBERT VILIANTO | E28: L | AE28: ZONASI | AF28: 0086255643 | AG28: 20527180 | AH28: REVIANA ZAHRA | AI28: P | AJ28: =UPPER(D28) -> MARVEL GILBERT VILIANTO | AZ28: 20 | BA28: 0083556423 / 14767 | BB28: Marvel Gilbert Vilianto | BC28: L
A29: 20 | B29: 14790 | C29: 0099057804 | D29: MOH RIZKY ADITIANSYAH | E29: L | AE29: NON AKD | AF29: 0095745897 | AG29: 20527193 | AH29: RIZKIANA INTANSARI | AI29: P | AJ29: =UPPER(D29) -> MOH RIZKY ADITIANSYAH | AZ29: 21 | BA29: 0099057804 / 14790 | BB29: MOH RIZKY ADITIANSYAH | BC29: L
A30: 21 | B30: 14793 | C30: 0093607543 | D30: MOH ZACKY MAULANA FIRDAUSI | E30: L | AE30: AKDMK | AF30: 0083907588 | AG30: 20527180 | AH30: RUH SYAFIRA CAHYANING PAWASA | AI30: P | AJ30: =UPPER(D30) -> MOH ZACKY MAULANA FIRDAUSI | AZ30: 22 | BA30: 0093607543 / 14793 | BB30: MOH ZACKY MAULANA FIRDAUSI | BC30: L
A31: 22 | B31: 14820 | C31: 0094289783 | D31: MUHAMMAD NADHIF AZARIA PUTRA | E31: L | AE31: RAPORT | AF31: 0109424194 | AG31: 20583367 | AH31: SARAH SALSABILA | AI31: P | AJ31: =UPPER(D31) -> MUHAMMAD NADHIF AZARIA PUTRA | AZ31: 24 | BA31: 0094289783 / 14820 | BB31: Muhammad Nadhif Azaria Putra | BC31: L
A32: 23 | B32: 14824 | C32: 0083986747 | D32: MUHAMMAD RIZQI MAULIDI | E32: L | AE32: RAPORT | AF32: 0081315442 | AG32: 20527197 | AH32: SEPTI RAHMADIYANTI | AI32: P | AJ32: =UPPER(D32) -> MUHAMMAD RIZQI MAULIDI | AZ32: 25 | BA32: 0083986747 / 14824 | BB32: MUHAMMAD RIZQI MAULIDI | BC32: L
A33: 24 | B33: 14836 | C33: 0093580431 | D33: NALANDA SYAHBANIA ARDHIANSYAH | E33: P | AE33: ZONASI | AF33: 0085713874 | AG33: 20527180 | AH33: TANIA KHANZA FIRNANDA RAMADHANI | AI33: P | AJ33: =UPPER(D33) -> NALANDA SYAHBANIA ARDHIANSYAH | AZ33: 26 | BA33: 0093580431 / 14836 | BB33: NALANDA SYAHBANIA ARDHIANSYAH | BC33: P
A34: 25 | B34: 14855 | C34: 0086800316 | D34: NUR RIZQA ZANJABILA | E34: P | AE34: NON AKD | AF34: 0099637523 | AG34: 20527197 | AH34: Tulus Firmansyah | AI34: L | AJ34: =UPPER(D34) -> NUR RIZQA ZANJABILA | AZ34: 27 | BA34: 0086800316 / 14855 | BB34: NUR RIZQA ZANJABILA | BC34: P
A35: 26 | B35: 14858 | C35: 0088066553 | D35: NURINDA NOVIANTI | E35: P | AJ35: =UPPER(D35) -> NURINDA NOVIANTI | AZ35: 28 | BA35: 0088066553 / 14858 | BB35: NURINDA NOVIANTI | BC35: P
A36: 27 | B36: 14866 | C36: 0092243247 | D36: PATO ALTHAF MULYAWAN | E36: L | AJ36: =UPPER(D36) -> PATO ALTHAF MULYAWAN | AZ36: 29 | BA36: 0092243247 / 14866 | BB36: PATO ALTHAF MULYAWAN | BC36: L
A37: 28 | B37: 14870 | C37: 0096807022 | D37: PUTRI RIZKI FAMADANI | E37: P | AJ37: =UPPER(D37) -> PUTRI RIZKI FAMADANI | AZ37: 30 | BA37: 0096807022 / 14870 | BB37: PUTRI RIZKI FAMADANI | BC37: P
A38: 29 | B38: 14871 | C38: 0098997217 | D38: R RAIHANUN FEBRIYANA SUGIHARTO | E38: P | AJ38: =UPPER(D38) -> R RAIHANUN FEBRIYANA SUGIHARTO | AZ38: 31 | BA38: 0098997217 / 14871 | BB38: R. RAIHANUN FEBRIYANA SUGIHARTO | BC38: P
A39: 30 | B39: 14881 | C39: 0096094178 | D39: RAIS AULIA ATTAMIMY WIJAYA | E39: L | AJ39: =UPPER(D39) -> RAIS AULIA ATTAMIMY WIJAYA | AZ39: 32 | BA39: 0096094178 / 14881 | BB39: RAIS AULIA ATTAMIMY WIJAYA | BC39: L
A40: 31 | B40: 14886 | C40: 3081834782 | D40: RARA QONITA ROYHANI | E40: P | AJ40: =UPPER(D40) -> RARA QONITA ROYHANI | AZ40: 33 | BA40: 3081834782 / 14886 | BB40: RARA QONITA ROYHANI | BC40: P
A41: 32 | B41: 14894 | C41: 0099773502 | D41: RIANA MAULIDIA | E41: P | AJ41: =UPPER(D41) -> RIANA MAULIDIA | AZ41: 34 | BA41: 0099773502 / 14894 | BB41: RIANA MAULIDIA | BC41: P
A42: 33 | B42: 14934 | C42: 0089463780 | D42: UMI KULSUM WARDANI | E42: P | AJ42: =UPPER(D42) -> UMI KULSUM WARDANI | AZ42: 35 | BA42: 0089463780 / 14934 | BB42: UMI KULSUM WARDANI | BC42: P
A43: 34 | B43: 14940 | C43: 0085106484 | D43: VIRGI AZMI YUSSININGTYAS | E43: P | AJ43: =UPPER(D43) -> VIRGI AZMI YUSSININGTYAS | AZ43: 36 | BA43: 0085106484 / 14940 | BB43: VIRGI AZMI YUSSININGTYAS | BC43: P
A44: Paraf | D44: L : | E44: =COUNTIFS($E$10:$E$43,"L") -> 16 | AJ44: =UPPER(D44) -> L :
...

Sheet XII-A-2
AF1: AKDMK | AG1: 0091162442 | AH1: 20566545 | AI1: ADELIA ZAHRA WIEGUNANDA | AJ1: P
AF2: RAPORT | AG2: 0098516635 | AH2: 20583363 | AI2: Ahmad Faiz Rahmatillah | AJ2: L
AF3: KIP | AG3: 0095865130 | AH3: 20537422 | AI3: AHMAD FARHAN HAKIKI | AJ3: L
A4: Tahun Pelajaran 2026 / 2027 | AF4: ZONASI | AG4: 0085516582 | AH4: 20527180 | AI4: AIZZA RAHMATIN NUR NADIN | AJ4: P
AF5: ZONASI | AG5: 0095986339 | AH5: 20527197 | AI5: ALDO SUKMA MAULIDZI | AJ5: L
AF6: NON AKD | AG6: 0082440195 | AH6: 20527180 | AI6: ARIF RAHMAN ALFATHIR | AJ6: L
A7: No | B7: NISN | C7: NISN | D7: Nama Siswa | E7: L/P | F7: Wali Kelas : | I7: RORO RIRIS PRAWITASARI H.S.Pd | T7: NIP : | V7: 19871026 202321 2 014 | AF7: NON AKD | AG7: 0095153508 | AH7: 20527180 | AI7: ARSYIL CAHYA WIBISONO | AJ7: P
F8: Tanggal | AF8: RAPORT | AG8: 0083079329 | AH8: 20566545 | AI8: BUNGA EL SABRINA | AJ8: P
AF9: RAPORT | AG9: 0088600933 | AH9: 20527197 | AI9: CANDRA ADITIYA NURMANSAH | AJ9: L | AV9: b
A10: 1 | B10: 14601 | C10: 0093351007 | D10: ADINTYA DJASMINE AULIA | E10: P | AF10: ZONASI | AG10: 0085720766 | AH10: 20527180 | AI10: CHIKO HARDELIO TAHER | AJ10: L | AL10: =UPPER(D10) -> ADINTYA DJASMINE AULIA | AU10: 1 | AV10: 0093351007 / 14601 | AW10: Adintya Djasmine Aulia | AX10: P
A11: 2 | B11: 14624 | C11: 0105298760 | D11: ALVINA RIZKI ANDINI | E11: P | AF11: ZONASI | AG11: 0082153282 | AH11: 20527197 | AI11: ELMAS SULTHON SALIM | AJ11: L | AL11: =UPPER(D11) -> ALVINA RIZKI ANDINI | AU11: 2 | AV11: 0105298760 / 14624 | AW11: ALVINA RIZKI ANDINI | AX11: P
A12: 3 | B12: 14641 | C12: 0082440195 | D12: ARIF RAHMAN ALFATHIR | E12: L | AF12: ZONASI | AG12: 0081076234 | AH12: 20527197 | AI12: FAGHIRA CAYLA PUTRI | AJ12: P | AL12: =UPPER(D12) -> ARIF RAHMAN ALFATHIR | AU12: 3 | AV12: 0082440195 / 14641 | AW12: ARIF RAHMAN ALFATHIR | AX12: L
A13: 4 | B13: 14649 | C13: 0095437804 | D13: ASYRA MARDHODILLAH SHAFA | E13: P | AF13: RAPORT | AG13: 0085164886 | AH13: 20527197 | AI13: FATHIMAH AZ ZAHRA | AJ13: P | AL13: =UPPER(D13) -> ASYRA MARDHODILLAH SHAFA | AU13: 4 | AV13: 0095437804 / 14649 | AW13: Asyra Mardhodillah Shafa | AX13: P
A14: 5 | B14: 14651 | C14: 0088166851 | D14: AULIA FAIZAH | E14: P | AF14: ZONASI | AG14: 0093543547 | AH14: 20527197 | AI14: FENI ISTIGHFARINI | AJ14: P | AL14: =UPPER(D14) -> AULIA FAIZAH | AU14: 5 | AV14: 0088166851 / 14651 | AW14: AULIA FAIZAH | AX14: P
A15: 6 | B15: 14668 | C15: 0087658356 | D15: BIMA SATRIA PUTRA RISMAWAN | E15: L | AF15: ZONASI | AG15: 0087610741 | AH15: 20527197 | AI15: GUNTUR PRASTYO WIBOWO | AJ15: L | AL15: =UPPER(D15) -> BIMA SATRIA PUTRA RISMAWAN | AU15: 6 | AV15: 0087658356 / 14668 | AW15: BIMA SATRIA PUTRA RISMAWAN | AX15: L
A16: 7 | B16: 14672 | C16: 3094339612 | D16: BUMI SUKMAWATI | E16: P | AF16: RAPORT | AG16: 0086660138 | AH16: 20527197 | AI16: Juwita Riski Amalia | AJ16: P | AL16: =UPPER(D16) -> BUMI SUKMAWATI | AU16: 7 | AV16: 3094339612 / 14672 | AW16: BUMI SUKMAWATI | AX16: P
A17: 8 | B17: 14681 | C17: 0092639463 | D17: DAFFA MAULIDAN PUTRA LAKSONO | E17: L | AF17: ZONASI | AG17: 0089337623 | AH17: 20527197 | AI17: KEA APRILIA MEDIANA PUTRI | AJ17: P | AL17: =UPPER(D17) -> DAFFA MAULIDAN PUTRA LAKSONO | AU17: 8 | AV17: 0092639463 / 14681 | AW17: DAFFA MAULIDAN PUTRA LAKSONO | AX17: L
A18: 9 | B18: 14684 | C18: 0085034059 | D18: DESVITA ANGGRAINI | E18: P | AF18: KIP | AG18: 0082984202 | AH18: 20583410 | AI18: MALIKA APRILIA SYAFIUN | AJ18: P | AL18: =UPPER(D18) -> DESVITA ANGGRAINI | AU18: 9 | AV18: 0085034059 / 14684 | AW18: Desvita Anggraini | AX18: P
A19: 10 | B19: 14685 | C19: 0091631646 | D19: DEVANI BAGUS ZAKIYAN | E19: L | AF19: ZONASI | AG19: 0099057804 | AH19: 20527197 | AI19: MOH RIZKY ADITIANSYAH | AJ19: L | AL19: =UPPER(D19) -> DEVANI BAGUS ZAKIYAN | AU19: 10 | AV19: 0091631646 / 14685 | AW19: DEVANI BAGUS ZAKIYAN | AX19: L
A20: 11 | B20: 14702 | C20: 0093488510 | D20: FARAND M YUNUS AL FARIZY | E20: L | AF20: ZONASI | AG20: 0093162650 | AH20: 20527180 | AI20: MOHAMMAD DHORIF AFLAH FAISAL | AJ20: L | AL20: =UPPER(D20) -> FARAND M YUNUS AL FARIZY | AU20: 11 | AV20: 0093488510 / 14702 | AW20: FARAND M. YUNUS AL FARIZY | AX20: L
A21: 12 | B21: 14724 | C21: 0083785128 | D21: HANIK AWALIYATUN NANDINI | E21: P | AF21: ZONASI | AG21: 0086354265 | AH21: 20527197 | AI21: MUHAMMAD IQBAL RAIHANUN | AJ21: L | AL21: =UPPER(D21) -> HANIK AWALIYATUN NANDINI | AU21: 12 | AV21: 0083785128 / 14724 | AW21: HANIK AWALIYATUN NANDINI | AX21: P
... A32: 23 | B32: 14827 | C32: 0087918586 | D32: NABILA DAVID | E32: P | AF32: KIP | AG32: 0093513951 | AH32: 20527166 | AI32: Sitti Uswatun Hasanah | AJ32: P | AL32: =UPPER(D32) -> NABILA DAVID | AU32: 23 | AV32: 0087918586 / 14827 | AW32: NABILA DAVID | AX32: P
A33: 24 | B33: 14829 | C33: 0081535841 | D33: NADHIFA SUCIANI HUWAIDA | E33: P | AF33: NON AKD | AG33: 0089793791 | AH33: 20527195 | AI33: SULTAN FARAS AS SIDIK | AJ33: L | AL33: =UPPER('XII-B-1'!D22) -> KAYSAN AISEL ASYROF | AU33: 24 | AV33: 0081535841 / 14829 | AW33: NADHIFA SUCIANI HUWAIDA | AX33: P
A34: 25 | B34: 14851 | C34: 0093665863 | D34: NISRINA SALIM NUR ASY SYIFA | E34: P | AF34: RAPORT | AG34: 0094292897 | AH34: 20527197 | AI34: TASNIM KHAIRULLAH HIDAYAT | AJ34: L | AL34: =UPPER(D34) -> NISRINA SALIM NUR ASY SYIFA | AU34: 25 | AV34: 0093665863 / 14851 | AW34: NISRINA SALIM NUR ASY SYIFA | AX34: P
A35: 26 | B35: 14861 | C35: 0086615669 | D35: OKTARINA SYAWLA PUTRI | E35: P | AF35: RAPORT | AG35: 0093897835 | AH35: 20527197 | AI35: Vina Istiana | AJ35: P | AL35: =UPPER(D35) -> OKTARINA SYAWLA PUTRI | AU35: 26 | AV35: 0086615669 / 14861 | AW35: Oktarina Syawla Putri | AX35: P
A36: 27 | B36: 14862 | C36: 0092301710 | D36: OLIVIA DAMAYANTI LUQMAN | E36: P | AF36: T.ORTU | AG36: 0085106484 | AH36: 20527197 | AI36: VIRGI AZMI YUSSININGTYAS | AJ36: P | AL36: =UPPER(D36) -> OLIVIA DAMAYANTI LUQMAN | AU36: 27 | AV36: 0092301710 / 14862 | AW36: OLIVIA DAMAYANTI LUQMAN | AX36: P
A37: 28 | B37: 14865 | C37: 0082402810 | D37: PASHA DWI CHANDRADINATA | E37: L | AL37: =UPPER(D37) -> PASHA DWI CHANDRADINATA | AU37: 28 | AV37: 0082402810 / 14865 | AW37: PASHA DWI CHANDRADINATA | AX37: L
A38: 29 | B38: 14868 | C38: 0083245302 | D38: PRAMUDYA YUSUF SAPUTRA | E38: L | AL38: =UPPER(D38) -> PRAMUDYA YUSUF SAPUTRA | AU38: 29 | AV38: 0083245302 / 14868 | AW38: PRAMUDYA YUSUF SAPUTRA | AX38: L
A39: 30 | B39: 14885 | C39: 0087162622 | D39: RANGGA YUSIKA DEWANTARA | E39: L | AL39: =UPPER(D39) -> RANGGA YUSIKA DEWANTARA | AU39: 30 | AV39: 0087162622 / 14885 | AW39: RANGGA YUSIKA DEWANTARA | AX39: L
A40: 31 | B40: 14905 | C40: 0095300336 | D40: SANJAYA MALIK MAULANA | E40: L | AL40: =UPPER(D40) -> SANJAYA MALIK MAULANA | AU40: 31 | AV40: 0095300336 / 14905 | AW40: SANJAYA MALIK MAULANA | AX40: L
A41: 32 | B41: 14911 | C41: 0099249982 | D41: SELVIANA FEBIYANTI | E41: P | AL41: =UPPER(D41) -> SELVIANA FEBIYANTI | AU41: 32 | AV41: 0099249982 / 14911 | AW41: Selviana Febiyanti | AX41: P
A42: 33 | B42: 14915 | C42: 0083330053 | D42: SHELFIA PUTRI RAMADHANI | E42: P | AL42: =UPPER(D42) -> SHELFIA PUTRI RAMADHANI | AU42: 33 | AV42: 0083330053 / 14915 | AW42: SHELFIA PUTRI RAMADHANI | AX42: P
A43: 34 | B43: 14920 | C43: 0093513951 | D43: SITTI USWATUN HASANAH | E43: P | AL43: =UPPER(D43) -> SITTI USWATUN HASANAH | AU43: 34 | AV43: 0093513951 / 14920 | AW43: Sitti Uswatun Hasanah | AX43: P
A44: 35 | B44: 14927 | C44: 0077719009 | D44: SYAVIYOLA YENITHA CAHYONO | E44: P | AL44: =UPPER(D44) -> SYAVIYOLA YENITHA CAHYONO | AU44: 35 | AV44: 0077719009 / 14927 | AW44: SYAVIYOLA YENITHA CAHYONO | AX44: P
A45: 36 | B45: 14947 | C45: 0083715423 | D45: ZAUMAR ABDURRAHMAN RITONGA | E45: L | AL45: =UPPER(D45) -> ZAUMAR ABDURRAHMAN RITONGA | AU45: 36 | AV45: 0083715423 / 14947 | AW45: ZAUMAR ABDURRAHMAN RITONGA | AX45: L
A46: Paraf | D46: L : | E46: =COUNTIFS($E$10:$E$45,"L") -> 18
A47: Guru | D47: P : | E47: =COUNTIFS($E$10:$E$45,"P") -> 18
E48: =E46+E47 -> 36

Sheet XII-A-3
AF1: ZONASI | AG1: 0099987267 | AH1: 20527180 | AI1: ABD HAMID MANAF | AJ1: L
AF2: ZONASI | AG2: 0082986450 | AH2: 20527197 | AI2: ACH IMAM MURTADHO | AJ2: L
AF3: RAPORT | AG3: 0093908702 | AH3: 20527197 | AI3: ADLYANSYAH BUDIMAN | AJ3: L
A4: Tahun Pelajaran 2026 / 2027 | AF4: ZONASI | AG4: 0095256057 | AH4: 60729406 | AI4: AKBAR RAHMATULLAH RAMADHAN | AJ4: L
AF5: ZONASI | AG5: 0093440845 | AH5: 20527169 | AI5: ALLENA GIOVANNY SUGIARTO | AJ5: P
AF6: RAPORT | AG6: 0089803534 | AH6: 20527180 | AI6: ALYSSA RISMA PARAMITHA | AJ6: P
A7: No | B7: NIS | C7: NISN | D7: Nama Siswa | E7: L/P | F7: Wali Kelas : | I7: AMIRA YAHYA, M.Pd | T7: NIP : | V7: 19860304 200903 2 001 | AF7: ZONASI | AG7: 0082607776 | AH7: 20527197 | AI7: ANDI ZAKY DANISH FIRMANSYAH | AJ7: L
F8: Tanggal | AF8: RAPORT | AG8: 0095437804 | AH8: 20531242 | AI8: Asyra Mardhodillah Shafa | AJ8: P
AF9: AKDMK | AG9: 0081651505 | AH9: 20527197 | AI9: AURIGA SYAFHA FAIRUZ SYAHREZA | AJ9: P
A10: 1 | B10: 14618 | C10: 0083172664 | D10: AL FATIH WAHYU BASALAMAH | E10: L | AF10: RAPORT | AG10: 3094339612 | AH10: 20566545 | AI10: BUMI SUKMAWATI | AJ10: P | AM10: =UPPER(D10) -> AL FATIH WAHYU BASALAMAH | AT10: 1 | AU10: 0083172664 / 14618 | AV10: AL FATIH WAHYU BASALAMAH | AW10: L
A11: 2 | B11: 14633 | C11: 0082607776 | D11: ANDI ZAKY DANISH FIRMANSYAH | E11: L | AF11: ZONASI | AG11: 0089501886 | AH11: 20527193 | AI11: DHIMAS ADHA TRI SUSANTO | AJ11: L | AM11: =UPPER(D11) -> ANDI ZAKY DANISH FIRMANSYAH | AT11: 2 | AU11: 0082607776 / 14633 | AV11: ANDI ZAKY DANISH FIRMANSYAH | AW11: L
A12: 3 | B12: 14642 | C12: 0098581750 | D12: ARIKA ABADIA HAMAS | E12: P | AF12: RAPORT | AG12: 0089987994 | AH12: 20527197 | AI12: FARDAN ABDILLAH NUR FIRDAUS | AJ12: L | AM12: =UPPER(D12) -> ARIKA ABADIA HAMAS | AT12: 3 | AU12: 0098581750 / 14642 | AV12: Arika Abadia Hamas | AW12: P
A13: 4 | B13: 14654 | C13: 0094693693 | D13: AURA NADHIF HENDRA SYAHPUTRA | E13: L | AF13: ZONASI | AG13: 0083785128 | AH13: 69980589 | AI13: HANIK AWALIYATUN NANDINI | AJ13: P | AM13: =UPPER(D13) -> AURA NADHIF HENDRA SYAHPUTRA | AT13: 4 | AU13: 0094693693 / 14654 | AV13: AURA NADHIF HENDRA SYAHPUTRA | AW13: L
A14: 5 | B14: 14680 | C14: 0092560616 | D14: CICILYA LISTY NABILA S | E14: P | AF14: KIP | AG14: 0096593970 | AH14: 20527197 | AI14: HASNAH AL AFIYAH | AJ14: L | AM14: =UPPER(D14) -> CICILYA LISTY NABILA S | AT14: 5 | AU14: 0092560616 / 14680 | AV14: CICILYA LISTY NABILA S | AW14: P
A15: 6 | B15: 14683 | C15: 0096931249 | D15: DAVIN PRAMANA PUTRA YULIANTO | E15: L | AF15: RAPORT | AG15: 0104564202 | AH15: 20583367 | AI15: KAYLA AIKO MARITZA | AJ15: P | AM15: =UPPER(D15) -> DAVIN PRAMANA PUTRA YULIANTO | AT15: 6 | AU15: 0096931249 / 14683 | AV15: DAVIN PRAMANA PUTRA YULIANTO | AW15: L
A16: 7 | B16: 14705 | C16: 0093461236 | D16: FATHAN MUBINA | E16: L | AF16: RAPORT | AG16: 0091869182 | AH16: 20527197 | AI16: MAJENDRA FAREL RIZKY HARIYANTO | AJ16: L | AM16: =UPPER(D16) -> FATHAN MUBINA | AT16: 7 | AU16: 0093461236 / 14705 | AV16: FATHAN MUBINA | AW16: L
A17: 8 | B17: 14707 | C17: 0091164419 | D17: FATIMAH KASYAF FANIE WAHAB | E17: P | AF17: A.GURU | AG17: 0091835952 | AH17: 20527197 | AI17: Merisa Anggi Yulia Putri | AJ17: P | AM17: =UPPER(D17) -> FATIMAH KASYAF FANIE WAHAB | AT17: 8 | AU17: 0091164419 / 14707 | AV17: FATIMAH KASYAF FANIE WAHAB | AW17: P
A18: 9 | B18: 14717 | C18: 0088529897 | D18: GILANG AKBAR SYAHPUTRA NASSO | E18: L | AF18: ZONASI | AG18: 0093197545 | AH18: 20527180 | AI18: MILZI ALIFIA MAULIDA | AJ18: P | AM18: =UPPER(D18) -> GILANG AKBAR SYAHPUTRA NASSO | AT18: 9 | AU18: 0088529897 / 14717 | AV18: GILANG AKBAR SYAHPUTRA NASSO | AW18: L
A19: 10 | B19: 14740 | C19: 0086147736 | D19: JEVIAN STYA PRATAMA | E19: L | AF19: RAPORT | AG19: 0087858823 | AH19: 20527197 | AI19: MOH SAHRUL MAULIDI | AJ19: L | AM19: =UPPER(D19) -> JEVIAN STYA PRATAMA | AT19: 11 | AU19: 0086147736 / 14740 | AV19: JEVIAN STYA PRATAMA | AW19: L
A20: 11 | B20: 14750 | C20: 0094952897 | D20: KHAZWA FARIH IMTIYAZ MINDAS | E20: P | AF20: ZONASI | AG20: 0098382897 | AH20: 20527180 | AI20: MOHAMMAD IQBAL RISTRIANTO | AJ20: L | AM20: =UPPER(D20) -> KHAZWA FARIH IMTIYAZ MINDAS | AT20: 12 | AU20: 0094952897 / 14750 | AV20: Khazwa Farih Imtiyaz Mindas | AW20: P
A21: 12 | B21: 14751 | C21: 0087377583 | D21: LALA HERMANDA | E21: P | AF21: ZONASI | AG21: 0084713270 | AH21: 20527197 | AI21: MUHAMMAD YUSUF ADI PRATAMA | AJ21: L | AM21: =UPPER(D21) -> LALA HERMANDA | AT21: 13 | AU21: 0087377583 / 14751 | AV21: LALA HERMANDA | AW21: P
A22: 13 | B22: 14759 | C22: 0084705460 | D22: M ABYAN FAITH FAWAZEE | E22: L | AF22: ZONASI | AG22: 0091521750 | AH22: 20527180 | AI22: NAFIL BERYL FAIRUZ | AJ22: L | AM22: =UPPER(D22) -> M ABYAN FAITH FAWAZEE | AT22: 14 | AU22: 0084705460 / 14759 | AV22: M. ABYAN FAITH FAWAZEE | AW22: L
A23: 14 | B23: 14765 | C23: 0082984202 | D23: MALIKA APRILIA SYAFIUN | E23: P | AF23: RAPORT | AG23: 3082973214 | AH23: 20528625 | AI23: NAUFAL RAHMATULLOH N A | AJ23: L | AM23: =UPPER(D23) -> MALIKA APRILIA SYAFIUN | AT23: 15 | AU23: 0082984202 / 14765 | AV23: MALIKA APRILIA SYAFIUN | AW23: P
A24: 15 | B24: 14771 | C24: 0085989808 | D24: MEIDY ARYANTO WIGUNA | E24: L | AF24: KIP | AG24: 0091667325 | AH24: 20527202 | AI24: Naura Wilda Safitri | AJ24: P | AM24: =UPPER(D24) -> MEIDY ARYANTO WIGUNA | AT24: 16 | AU24: 0085989808 / 14771 | AV24: MEIDY ARYANTO WIGUNA | AW24: L
A25: 16 | B25: 14775 | C25: 0099315210 | D25: MIFTAHUL FADLI DANIAR | E25: L | AF25: RAPORT | AG25: 0097064727 | AH25: 20527197 | AI25: NAYLA SHAFA AZZAHRA | AJ25: P | AM25: =UPPER(D25) -> MIFTAHUL FADLI DANIAR | AT25: 17 | AU25: 0099315210 / 14775 | AV25: MIFTAHUL FADLI DANIAR | AW25: L
A26: 17 | B26: 14777 | C26: 0094896372 | D26: MIRANDA KUSUMA ATMAJA | E26: P | AF26: ZONASI | AG26: 0093422775 | AH26: 20527197 | AI26: RAFEYFA ZALFA ZAHIRA | AJ26: P | AM26: =UPPER(#REF!) -> #REF! | AT26: 18 | AU26: 0094896372 / 14777 | AV26: MIRANDA KUSUMA ATMAJA | AW26: P
A27: 18 | B27: 14794 | C27: 0087166431 | D27: MOH RAFI HIDAYATULLAH | E27: L | AF27: NON AKD | AG27: 3080968608 | AH27: 70027854 | AI27: RAFIF KEMAL AZIZI | AJ27: L | AM27: =UPPER(D27) -> MOH RAFI HIDAYATULLAH | AT27: 19 | AU27: 0087166431 / 14794 | AV27: MOH RAFI HIDAYATULLAH | AW27: L
A28: 19 | B28: 14798 | C28: 0093162650 | D28: MOHAMMAD DHORIF AFLAH FAISAL | E28: L | AF28: ZONASI | AG28: 0099672333 | AH28: 20527197 | AI28: RAHMI HUMAIRA | AJ28: P | AM28: =UPPER(D28) -> MOHAMMAD DHORIF AFLAH FAISAL | AT28: 20 | AU28: 0093162650 / 14798 | AV28: MOHAMMAD DHORIF AFLAH FAISAL | AW28: L
A29: 20 | B29: 14799 | C29: 0093901388 | D29: MOHAMMAD GHAVIN AZZARYA TAMRIN | E29: L | AF29: NON AKD | AG29: 0096094178 | AH29: 20527180 | AI29: RAIS AULIA ATTAMIMY WIJAYA | AJ29: L | AM29: =UPPER(D29) -> MOHAMMAD GHAVIN AZZARYA TAMRIN | AT29: 21 | AU29: 0093901388 / 14799 | AV29: MOHAMMAD GHAVIN AZZARYA TAMRIN | AW29: L
A30: 21 | B30: 14809 | C30: 0098327801 | D30: MUHAMMAD FAKHRULLAH AGIEL | E30: L | AF30: AKDMK | AG30: 0093455270 | AH30: 20527185 | AI30: REFATIA MIRZA VALENSI | AJ30: P | AM30: =UPPER(D30) -> MUHAMMAD FAKHRULLAH AGIEL | AT30: 22 | AU30: 0098327801 / 14809 | AV30: MUHAMMAD FAKHRULLAH AGIEL | AW30: L
A31: 22 | B31: 14826 | C31: 3099461393 | D31: MULIA ANNISA SETYA WARDANI | E31: P | AF31: ZONASI | AG31: 0086479528 | AH31: 20583411 | AI31: SELVIA RAMADHANI | AJ31: P | AM31: =UPPER(D31) -> MULIA ANNISA SETYA WARDANI | AT31: 24 | AU31: 3099461393 / 14826 | AV31: MULIA ANNISA SETYA WARDANI | AW31: P
A32: 23 | B32: 14831 | C32: 0098950100 | D32: NADIYAH ARINDA ALFIYANI | E32: P | AF32: ZONASI | AG32: 0087393847 | AH32: 20527185 | AI32: SHAHIBUL KAMALI RAHMAT HIDAYAT | AJ32: L | AM32: =UPPER(D32) -> NADIYAH ARINDA ALFIYANI | AT32: 25 | AU32: 0098950100 / 14831 | AV32: NADIYAH ARINDA ALFIYANI | AW32: P
A33: 24 | B33: 14838 | C33: 0095516794 | D33: NATHANIEL HIZKIA PANJAITAN | E33: L | AF33: ZONASI | AG33: 0097102519 | AH33: 20527180 | AI33: SHIVA MAULIDYA PRASETIYO | AJ33: P | AM33: =UPPER(D33) -> NATHANIEL HIZKIA PANJAITAN | AT33: 26 | AU33: 0095516794 / 14838 | AV33: NATHANIEL HIZKIA PANJAITAN | AW33: L
A34: 25 | B34: 14841 | C34: 0084036504 | D34: NAUFAL PUTRA HARDIANSYAH | E34: L | AF34: NON AKD | AG34: 0093962965 | AH34: 20583363 | AI34: SITI MAISHUROH ASSYIFA | AJ34: P | AM34: =UPPER(D34) -> NAUFAL PUTRA HARDIANSYAH | AT34: 27 | AU34: 0084036504 / 14841 | AV34: NAUFAL PUTRA HARDIANSYAH | AW34: L
A35: 26 | B35: 14853 | C35: 0085190125 | D35: NORUSSIFA NOVIYANA SYAFANI | E35: P | AM35: =UPPER(D35) -> NORUSSIFA NOVIYANA SYAFANI | AT35: 28 | AU35: 0085190125 / 14853 | AV35: NORUSSIFA NOVIYANA SYAFANI | AW35: P
A36: 27 | B36: 14872 | C36: 0088070697 | D36: R. AYU NOURA AZKIA | E36: P | AM36: =UPPER(D36) -> R. AYU NOURA AZKIA | AT36: 29 | AU36: 0088070697 / 14872 | AV36: R. AYU NOURA AZKIA | AW36: P
A37: 28 | B37: 14901 | C37: 0081550255 | D37: SABRINA YASMIN FIRYAL SISWANTO | E37: P | AM37: =UPPER(D37) -> SABRINA YASMIN FIRYAL SISWANTO | AT37: 30 | AU37: 0081550255 / 14901 | AV37: SABRINA YASMIN FIRYAL SISWANTO | AW37: P
A38: 29 | B38: 14908 | C38: 0088888355 | D38: SAVIRA ELDIANA | E38: P | AM38: =UPPER(D38) -> SAVIRA ELDIANA | AT38: 31 | AU38: 0088888355 / 14908 | AV38: SAVIRA ELDIANA | AW38: P
A39: 30 | B39: 14914 | C39: 0097120243 | D39: SHEBIA KINANTI AURELLUNA | E39: P | AM39: =UPPER(D39) -> SHEBIA KINANTI AURELLUNA | AT39: 32 | AU39: 0097120243 / 14914 | AV39: SHEBIA KINANTI AURELLUNA | AW39: P
A40: 31 | B40: 14928 | C40: 0085713874 | D40: TANIA KHANZA FIRNANDA RAMADHANI | E40: P | AM40: =UPPER(D40) -> TANIA KHANZA FIRNANDA RAMADHANI | AT40: 33 | AU40: 0085713874 / 14928 | AV40: TANIA KHANZA FIRNANDA RAMADHANI | AW40: P
...

Sheet XII-A-4
AE1: RAPORT | AF1: 0096776269 | AG1: 20527197 | AH1: AISYAH ANA HARIYANTO | AI1: P
AE2: ZONASI | AF2: 0084641835 | AG2: 20566545 | AH2: AKRAM ARKANANTA FIRDAUS | AI2: L
AE3: ZONASI | AF3: 0083172664 | AG3: 20527180 | AH3: AL FATIH WAHYU BASALAMAH | AI3: L
A4: Tahun Pelajaran 2026 / 2027 | AE4: KIP | AF4: 0089933258 | AG4: 20527166 | AH4: ANDREA NAUFAL SETIAWAN | AI4: L
AE5: AKDMK | AF5: 0095415650 | AG5: 20527197 | AH5: APRILIA NURIL QOMARI | AI5: P
AE6: ZONASI | AF6: 0094693693 | AG6: 20566545 | AH6: AURA NADHIF HENDRA SYAHPUTRA | AI6: P
A7: No | B7: NIS | C7: NISN | D7: Nama Siswa | E7: L/P | F7: Wali Kelas : | I7: CHIKI EVA KRISTIYARA, S.Pd | T7: NIP : | V7: 19861108 202321 2 036 | AE7: ZONASI | AF7: 0098143816 | AG7: 20527180 | AH7: AZIMU NASYWA YATRIN | AI7: P
F8: Tanggal | AE8: RAPORT | AF8: 0082558863 | AG8: 20527185 | AH8: Bambang Fariaji | AI8: L
AE9: RAPORT | AF9: 0083494373 | AG9: 20527197 | AH9: CARISSA DWI PUTRI LARASATI | AI9: P
A10: 1 | B10: 14595 | C10: 0097637507 | D10: ACHMAD RAFI AKBAR | E10: L | AE10: AKDMK | AF10: 0098040950 | AG10: 20527180 | AH10: CHRISTOFFER CONSTANTINE SANTOSO | AI10: L | AM10: =UPPER('XII-A-7'!D10) -> ACH NURUL HIDAYAT | AV10: 1 | AW10: 0097637507 / 14595 | AX10: ACHMAD RAFI AKBAR | AY10: L
A11: 2 | B11: 14597 | C11: 0091162442 | D11: ADELIA ZAHRA WIEGUNANDA | E11: P | AE11: ZONASI | AF11: 0091164419 | AG11: 20527197 | AH11: FATIMAH KASYAF FANIE WAHAB | AI11: P | AM11: =UPPER('XII-B-3'!D14) -> AMELIA HERIYANTO | AV11: 2 | AW11: 0091162442 / 14597 | AX11: ADELIA ZAHRA WIEGUNANDA | AY11: P
A12: 3 | B12: 14614 | C12: 0095256057 | D12: AKBAR RAHMATULLAH RAMADHAN | E12: L | AE12: ZONASI | AF12: 0086888062 | AG12: 20527197 | AH12: HUMAIR DZIKRI SYAHLANA | AI12: L | AM12: =UPPER('XII-A-7'!D12) -> ADINDA AYU RISTIANTI | AV12: 3 | AW12: 0095256057 / 14614 | AX12: AKBAR RAHMATULLAH RAMADHAN | AY12: L
A13: 4 | B13: 14638 | C13: 0095415650 | D13: APRILIA NURIL QOMARI | E13: P | AE13: ZONASI | AF13: 3089324280 | AG13: 20566545 | AH13: Keyzha Lucyana Adhia Rinda | AI13: P | AM13: =UPPER('XII-A-7'!D13) -> ADLYANSYAH BUDIMAN | AV13: 4 | AW13: 0095415650 / 14638 | AX13: APRILIA NURIL QOMARI | AY13: P
A14: 5 | B14: 14660 | C14: 0098143816 | D14: AZIMU NASYWA YATRIN | E14: P | AE14: ZONASI | AF14: 0084247358 | AG14: 20527197 | AH14: LINDHA SYAFITRI | AI14: P | AM14: =UPPER('XII-A-7'!D14) -> AHMAD FAIZ RAHMATILLAH | AV14: 5 | AW14: 0098143816 / 14660 | AX14: AZIMU NASYWA YATRIN | AY14: P
A15: 6 | B15: 14665 | C15: 0081890474 | D15: BERLIANA OKTAVIA BELA | E15: P | AE15: RAPORT | AF15: 0098583778 | AG15: 20583367 | AH15: LIVIA AURATUS ORYZA SATIVA | AI15: P | AM15: =UPPER('XII-A-7'!D15) -> AHMAD GHOSI AKBAR | AV15: 6 | AW15: 0081890474 / 14665 | AX15: BERLIANA OKTAVIA BELA | AY15: P
A16: 7 | B16: 14671 | C16: 0082665512 | D16: BRILLIANT BRAMARGANTARA PM | E16: L | AE16: RAPORT | AF16: 0084705460 | AG16: 20583367 | AH16: M ABYAN FAITH FAWAZEE | AI16: L | AM16: =UPPER('XII-B-3'!D36) -> OWEN FILIPO SANTOSO | AV16: 7 | AW16: 0082665512 / 14671 | AX16: BRILLIANT BRAMARGANTARA P.M. | AY16: L
A17: 8 | B17: 14676 | C17: 0092032751 | D17: CARISSA GUSTI PUTRI | E17: P | AE17: RAPORT | AF17: 0085989808 | AG17: 20527197 | AH17: MEIDY ARYANTO WIGUNA | AI17: L | AM17: =UPPER('XII-A-7'!D17) -> AKSA AHMAD | AV17: 8 | AW17: 0092032751 / 14676 | AX17: Carissa Gusti Putri | AY17: P
A18: 9 | B18: 14678 | C18: 0085720766 | D18: CHIKO HARDELIO TAHER | E18: L | AE18: ZONASI | AF18: 0092567020 | AG18: 20579418 | AH18: MOH ADITYA MAULANA PUTRA | AI18: L | AM18: =UPPER('XII-A-7'!D18) -> ALDO SUKMA MAULIDZI | AV18: 9 | AW18: 0085720766 / 14678 | AX18: CHIKO HARDELIO TAHER | AY18: L
A19: 10 | B19: 14690 | C19: 0086730733 | D19: DYAH AYU RAMADHANI | E19: P | AE19: ZONASI | AF19: 0089276032 | AG19: 20527197 | AH19: MOH AFGAN BARLIYANTO | AI19: L | AM19: =UPPER('XII-A-7'!D19) -> ALISHA RAMADHANI POERNOMO | AV19: 10 | AW19: 0086730733 / 14690 | AX19: DYAH AYU RAMADHANI | AY19: P
A20: 11 | B20: 14696 | C20: 0082153282 | D20: ELMAS SULTHON SALIM | E20: L | AE20: NON AKD | AF20: 0085784500 | AG20: 20527195 | AH20: MOH ALFAN KURNIAWAN | AI20: L | AM20: =UPPER('XII-A-7'!D20) -> ANGGUN KARUNIA PUTRI SASIKIRANA | AV20: 11 | AW20: 0082153282 / 14696 | AX20: ELMAS SULTHON SALIM | AY20: L
A21: 12 | B21: 14706 | C21: 0085164886 | D21: FATHIMAH AZ ZAHRA | E21: P | AE21: ZONASI | AF21: 0092307512 | AG21: 20527180 | AH21: MOH ARAFA DWI PURWANTO | AI21: L | AM21: =UPPER('XII-A-7'!D21) -> ARKAN QUVI RAHAGIS | AV21: 12 | AW21: 0085164886 / 14706 | AX21: FATHIMAH AZ ZAHRA | AY21: P
A22: 13 | B22: 14719 | C22: 0093695374 | D22: GILANG ALFAHRIZI | E22: L | AE22: RAPORT | AF22: 0095526227 | AG22: 20528625 | AH22: MOH REZA FEBRILIYANTO | AI22: L | AM22: =UPPER('XII-A-7'!D22) -> ASSHIFA MAGHFIRAH | AV22: 13 | AW22: 0093695374 / 14719 | AX22: GILANG ALFAHRIZI | AY22: L
A23: 14 | B23: 14723 | C23: 0096047605 | D23: HANIEF RIZKIANSYAH ARIEF | E23: L | AE23: ZONASI | AF23: 0093901388 | AG23: 20527180 | AH23: MOHAMMAD GHAVIN AZZARYA TAMRIN | AI23: L | AM23: =UPPER('XII-A-7'!D23) -> AYDIN NARARYA TARIQ | AV23: 14 | AW23: 0096047605 / 14723 | AX23: HANIEF RIZKIANSYAH ARIEF | AY23: L
A24: 15 | B24: 14729 | C24: 0088601519 | D24: HILMAN FUADI | E24: L | AE24: ZONASI | AF24: 0094661980 | AG24: 20527180 | AH24: MOHAMMAD RIZQI FADILAH | AI24: L | AM24: =UPPER('XII-A-7'!D24) -> BETARIA WIFAN AGUSTA | AV24: 15 | AW24: 0088601519 / 14729 | AX24: HILMAN FUADI | AY24: L
A25: 16 | B25: 14733 | C25: 0098205189 | D25: IBRAHIM PUTRA BUDIYANTO | E25: L | AE25: ZONASI | AF25: 0088261483 | AG25: 20566545 | AH25: MUHAMMAD IQBAL LISMARTA | AI25: L | AM25: =UPPER('XII-A-7'!D25) -> BILQIS NABILA ZAHROH | AV25: 16 | AW25: 0098205189 / 14733 | AX25: IBRAHIM PUTRA BUDIYANTO | AY25: L
A26: 17 | B26: 14737 | C26: 0079472704 | D26: INTAN TARI RAMADHANI | E26: P | AE26: RAPORT | AF26: 3099461393 | AG26: 20528625 | AH26: MULIA ANNISA SETYA WARDANI | AI26: P | AM26: =UPPER('XII-A-7'!#REF!) -> #REF! | AV26: 17 | AW26: 0079472704 / 14737 | AX26: INTAN TARI R | AY26: P
A27: 18 | B27: 14749 | C27: 0096323695 | D27: KHANSA BUNGA ADELIA RIJANI | E27: P | AE27: NON AKD | AF27: 0081535841 | AG27: 20527197 | AH27: NADHIFA SUCIANI HUWAIDA | AI27: P | AM27: =UPPER('XII-A-4'!D35) -> MOHAMMAD IQBAL RISTRIANTO | AV27: 18 | AW27: 0096323695 / 14749 | AX27: KHANSA BUNGA ADELIA RIJANI | AY27: P
A28: 19 | B28: 14756 | C28: 0098583778 | D28: LIVIA AURATUS ORYZA SATIVA | E28: P | AE28: RAPORT | AF28: 0083375001 | AG28: 20527197 | AH28: NAZIFA SALSABILA | AI28: P | AM28: =UPPER('XII-A-7'!D28) -> IRMA NOVIANTI PUTRI NASIR | AV28: 19 | AW28: 0098583778 / 14756 | AX28: LIVIA AURATUS ORYZA SATIVA | AY28: P
A29: 20 | B29: 14757 | C29: 0084839529 | D29: LIVINA DZAKIRA NUGRAHA | E29: P | AE29: ZONASI | AF29: 0087193172 | AG29: 20527197 | AH29: NUR SYARIF | AI29: L | AM29: =UPPER('XII-A-7'!D29) -> KHANSA AISYAH SHABRINA | AV29: 20 | AW29: 0084839529 / 14757 | AX29: LIVINA DZAKIRA NUGRAHA | AY29: P
A30: 21 | B30: 14758 | C30: 0087903138 | D30: LUNA ZAHRATUS SHITA | E30: P | AE30: A.GURU | AF30: 0088070697 | AG30: 20527197 | AH30: R AYU NOURA AZKIA | AI30: P | AM30: =UPPER('XII-A-5'!D13) -> AISYAH ANI HARIYANTO | AV30: 21 | AW30: 0087903138 / 14758 | AX30: LUNA ZAHRATUS SHITA | AY30: P
A31: 22 | B31: 14762 | C31: 0099059716 | D31: MAISYAR MAULI NABILA FP | E31: P | AE31: ZONASI | AF31: 0098997217 | AG31: 20527197 | AH31: R RAIHANUN FEBRIYANA SUGIHARTO | AI31: P | AM31: =UPPER('XII-B-2'!D19) -> CAROLINA AGUSTIN ARYA SARI | AV31: 22 | AW31: 0099059716 / 14762 | AX31: MAISYAR MAULI NABILA F.P. | AY31: P
A32: 23 | B32: 14776 | C32: 0093197545 | D32: MILZI ALIFIA MAULIDA | E32: P | AE32: AKDMK | AF32: 0083012066 | AG32: 20529915 | AH32: REISYA SATYA AYU PRAMESWARI | AI32: P | AM32: =UPPER('XII-A-7'!D33) -> MUHAMMAD FAKHRY HIDAYAT | AV32: 23 | AW32: 0093197545 / 14776 | AX32: MILZI ALIFIA MAULIDA | AY32: P
A33: 24 | B33: 14781 | C33: 0094346939 | D33: MOH ALFIAN ZAINAL ARIF | E33: L | AE33: ZONASI | AF33: 0088888355 | AG33: 20583367 | AH33: SAVIRA ELDIANA | AI33: P | AM33: =UPPER('XII-A-7'!D34) -> MUHAMMAD FRITZ ZAHRAN VIRODILA | AV33: 24 | AW33: 0094346939 / 14781 | AX33: MOH. ALFIAN ZAINAL ARIF | AY33: L
A34: 25 | B34: 14792 | C34: 0108459456 | D34: MOH WILDAN RADITYA | E34: L | AE34: KIP | AF34: 0099249982 | AG34: 20527202 | AH34: Selviana Febiyanti | AI34: P | AM34: =UPPER('XII-A-7'!D35) -> MUHAMMAD INDRA RIZKY FAHREZA | AV34: 25 | AW34: 0108459456 / 14792 | AX34: MOH. WILDAN RADITYA | AY34: L
