Workbook

Sheet XI-A1 
A4: Tahun Pelajaran 2026 / 2027
A7: No | B7: NISN / NIS | C7: Nama Siswa | D7: L/P | E7: Wali Kelas : | H7: YUSMIATI, S.Pd. | S7: NIP : | U7: 198708112024212000
E8: Tanggal
A10: 1 | B10: 0099058533 / 14952 | C10: ACH ALFIANSYA SEPTEO RAMADHANI | D10: L | AE10: 0094915611 | AF10: ABDU DAKAIL FATHON | AG10: 87.52 | AH10: A | AI10: L | AK10: =UPPER(AF10) -> ABDU DAKAIL FATHON
A11: 2 | B11: 0106096923 / 14954 | C11: ACH RAMZI ARIFANDI HABIBULLAH | D11: L | AE11: 0101733365 | AF11: AGUNG MULYA PRATAMA | AG11: 83.03 | AH11: A | AI11: L | AK11: =UPPER(AF11) -> AGUNG MULYA PRATAMA
A12: 3 | B12: 3092769358 / 15306 | C12: ACH. SHIDQI RAMADHANI | D12: L | AE12: 99620577 | AF12: AHMAD RAFA RAMADANI | AG12: 80.78 | AH12: A | AI12: L | AK12: =UPPER(AF12) -> AHMAD RAFA RAMADANI
A13: 4 | B13: 0103841370 / 14969 | C13: AISYAH FEBRIYANTI RIDWAN | D13: P | AE13: 94618904 | AF13: ALFIANA UTAMI PUTRI | AG13: 82.93 | AH13: A | AI13: P | AK13: =UPPER(AF13) -> ALFIANA UTAMI PUTRI
A14: 5 | B14: 0109722078 / 14972 | C14: ALF HAAFIZ AKBAR | D14: L | AE14: 0093576020 | AF14: ALYA MUKHBITA | AG14: 88.78 | AH14: A | AI14: p | AK14: =UPPER(AF14) -> ALYA MUKHBITA
A15: 6 | B15: 0102988393 / 14974 | C15: ALFINA DIAH ANGGRAINI | D15: P | AE15: 0108584503 | AF15: ANGELINA SYIFAAUR RAHMAH | AG15: 86.80 | AH15: A | AI15: P | AK15: =UPPER(AF15) -> ANGELINA SYIFAAUR RAHMAH
A16: 7 | B16: 0099550894 / 14980 | C16: ALMIRAH DISTI NAURA | D16: P | AE16: 105301544 | AF16: ASYAM ABQARI | AG16: 81.23 | AH16: A | AI16: L | AK16: =UPPER(AF16) -> ASYAM ABQARI
A17: 8 | B17: 0093576020 / 14982 | C17: ALYA MUKHBITA | D17: P | AE17: 104677265 | AF17: ASYIFA PUTRI AZIZAH | AG17: 84.49 | AH17: A | AI17: P | AK17: =UPPER(AF17) -> ASYIFA PUTRI AZIZAH
A18: 9 | B18: 0099897605 / 14983 | C18: ALYSA TUNGGA PRATIWI | D18: P | AE18: 0105311993 | AF18: ASYRAF KHAIRULLAH PRATAMA | AG18: 87.72 | AH18: A | AI18: L | AK18: =UPPER(AF18) -> ASYRAF KHAIRULLAH PRATAMA
A19: 10 | B19: 0109950311 / 14989 | C19: ANISA AMILIA AZZAHRA | D19: P | AE19: 0101428911 | AF19: AZKA DAHISY AMIN | AG19: 88.58 | AH19: A | AI19: L | AK19: =UPPER(AF19) -> AZKA DAHISY AMIN
A20: 11 | B20: 0095090304 / 14997 | C20: ARYATAMA REZA RAFAYENDRA | D20: L | AE20: 0093003989 | AF20: AZZAHRA ARIF DAMAYANTI | AG20: 83.31 | AH20: A | AI20: P | AK20: =UPPER(AF20) -> AZZAHRA ARIF DAMAYANTI
A21: 12 | B21: 0098598715 / 15013 | C21: AURA ZAHRIMA SALSABILA | D21: P | AE21: 0094840732 | AF21: CANTIKA SAFITRI WIJAYANTI | AG21: 86.9 | AH21: A | AI21: P | AK21: =UPPER(AF21) -> CANTIKA SAFITRI WIJAYANTI
A22: 13 | B22: 3103175403 / 15022 | C22: AZELIA EZAR ADHYASTA | D22: P | AE22: 0093782050 | AF22: DHAFINA PUTRI ARIFIN | AG22: 86.51 | AH22: A | AI22: P | AK22: =UPPER(AF22) -> DHAFINA PUTRI ARIFIN
A23: 14 | B23: 0101780275 / 15065 | C23: FINDY WAHYUNI | D23: P | AE23: 0103741538 | AF23: GEVAN DANIEL APRADINATA | AG23: 84.56 | AH23: A | AI23: L | AK23: =UPPER(AF23) -> GEVAN DANIEL APRADINATA
A24: 15 | B24: 0098686172 / 15069 | C24: FRISKA AULIA PUTRI | D24: P | AE24: 95217817 | AF24: HASNA ALGHINA RACHMAN | AG24: 84.21 | AH24: A | AI24: P | AK24: =UPPER(AF24) -> HASNA ALGHINA RACHMAN
A25: 16 | B25: 0107912441 / 15070 | C25: FRITZI RAFA ADITYA DHANA | D25: L | AE25: 0098447991 | AF25: IZZA BUNGA FAIRUZIA | AG25: 87.58 | AH25: A | AI25: p | AK25: =UPPER(AF25) -> IZZA BUNGA FAIRUZIA
A26: 17 | B26: 0104756008 / 15072 | C26: GESTA NOVANDA PUTRA GS | D26: L | AE26: 0103080501 | AF26: M DELFIAN ARIF PRATAMA | AG26: 87.30 | AH26: A | AI26: L | AK26: =UPPER(AF26) -> M DELFIAN ARIF PRATAMA
A27: 18 | B27: 0107815195 / 15078 | C27: HASSYA KANAYA TSABITAH | D27: P | AE27: 0099668691 | AF27: MILDY PRIO RUBIANTO | AG27: 85.97 | AH27: A | AI27: L | AK27: =UPPER(AF27) -> MILDY PRIO RUBIANTO
A28: 19 | B28: 0091669818 / 15081 | C28: IBRAHIM AZZAHEDY | D28: L | AE28: 102122050 | AF28: MOH NABIL KHUROZIM FANDY | AG28: 85.3 | AH28: A | AI28: L | AK28: =UPPER(AF28) -> MOH NABIL KHUROZIM FANDY
A29: 20 | B29: 0099606551 / 15092 | C29: IZZA AULIA SHOFA | D29: P | AE29: 91890772 | AF29: MOHAMMAD AKHDAN MAULADI | AG29: 86.39 | AH29: A | AI29: L | AK29: =UPPER(AF29) -> MOHAMMAD AKHDAN MAULADI
A30: 21 | B30: 0101127479 / 15311 | C30: KARIMAH NAJLA SHABIRA | D30: P | AE30: 3104234462 | AF30: MOHAMMAD RIZKY RAFIF TAMAM | AG30: 86.06 | AH30: A | AI30: L | AK30: =UPPER(AF30) -> MOHAMMAD RIZKY RAFIF TAMAM
A31: 22 | B31: 0109462096 / 15103 | C31: KHANSA APRILIA FILZAH | D31: P | AE31: 0097811869 | AF31: NADIF ABDILLAH | AG31: 87.19 | AH31: A | AI31: P | AK31: =UPPER(AF31) -> NADIF ABDILLAH
A32: 23 | B32: 0092179048 / 15121 | C32: MAQFIROH FITRIYAH | D32: P | AE32: 0096843896 | AF32: NAJWA ACHMAD | AG32: 82.13 | AH32: A | AI32: P | AK32: =UPPER(AF32) -> NAJWA ACHMAD
A33: 24 | B33: 0111441132 / 15128 | C33: MIRANDA PURNAMA DEWI | D33: P | AE33: 0094137933 | AF33: NAJWAS SHYFA | AG33: 89.58 | AH33: A | AI33: p | AK33: =UPPER(AF33) -> NAJWAS SHYFA
A34: 25 | B34: 0106569429 / 15129 | C34: MOH. AFIFUR RIZAL | D34: L | AE34: 0094814338 | AF34: NILA SARI AMINARTI | AG34: 86.72 | AH34: A | AI34: P | AK34: =UPPER(AF34) -> NILA SARI AMINARTI
A35: 26 | B35: 0094490553 / 15132 | C35: MOH. GHAZY ARYADHANA | D35: L | AE35: 91793849 | AF35: NINDY SAFIRA MAHARANI | AG35: 82.88 | AH35: A | AI35: P | AK35: =UPPER(AF35) -> NINDY SAFIRA MAHARANI
A36: 27 | B36: 0098648558 / 15137 | C36: MOH. RADITYA PRATAMA PUTRA | D36: L | AE36: 0095384163 | AF36: NUR FAIRATUR RAHMAN | AG36: 85.21 | AH36: A | AI36: P | AK36: =UPPER(AF36) -> NUR FAIRATUR RAHMAN
A37: 28 | B37: 0107990597 / 15167 | C37: NAFISA NISFU SYABANA | D37: P | AE37: 108367839 | AF37: RAFA SYAFRIYANDI | AG37: 79.15 | AH37: A | AI37: L | AK37: =UPPER(AF37) -> RAFA SYAFRIYANDI
A38: 29 | B38: 0108261287 / 15175 | C38: NASYWA | D38: P | AE38: 105266191 | AF38: RAFIIF ALLAAM AS SARIY | AG38: 83.85 | AH38: A | AI38: L | AK38: =UPPER(AF38) -> RAFIIF ALLAAM AS SARIY
A39: 30 | B39: 0094814338 / 15190 | C39: NILA SARI AMINARTI | D39: P | AE39: 99080907 | AF39: RANIAH | AG39: 83.49 | AH39: A | AI39: P | AK39: =UPPER(AF39) -> RANIAH
A40: 31 | B40: 0095384163 / 15196 | C40: NUR FAIRATUR RAHMAN | D40: P | AE40: 0095467404 | AF40: ROBIATUL WAHIDIYAH AL AMIR PUTRI | AG40: 83.74 | AH40: A | AI40: P | AK40: =UPPER(AF40) -> ROBIATUL WAHIDIYAH AL AMIR PUTRI
A41: 32 | B41: 3095038031 / 15232 | C41: REYNATA SAHIFA ALKALIFI | D41: P | AE41: 105240233 | AF41: ROBITH IMANI BILLAH | AG41: 84.81 | AH41: A | AI41: L | AK41: =UPPER(AF41) -> ROBITH IMANI BILLAH
A42: 33 | B42: 0108858362 / 15233 | C42: REZA ACHMAD PASHA ISLAMI | D42: L | AE42: 0101950178 | AF42: SHAFA AZIYAH PUTRI | AG42: 88.02 | AH42: A | AI42: P | AK42: =UPPER(AF42) -> SHAFA AZIYAH PUTRI
A43: 34 | B43: 0109277278 / 15247 | C43: SAFA NUR AQILAH RAHMAN | D43: P | AE43: 0094839217 | AF43: SHAFWAN AQILA GUSFA | AG43: 90.16 | AH43: A | AI43: P | AK43: =UPPER(AF43) -> SHAFWAN AQILA GUSFA
A44: 35 | B44: 0106159891 / 15260 | C44: SHAKILA AYODYA | D44: P | AE44: 0108382917 | AF44: SYARIFATUL AISYAH | AG44: 93.11 | AH44: A | AI44: p
A45: 36 | B45: 0108074622 / 15284 | C45: VINDYANA INDIRA OCTAVIA | D45: P | AE45: 0101166292 | AF45: UKHTI FARATINA NUR AFINY | AG45: 88.03 | AH45: A | AI45: p
A46: Paraf | C46: L : | D46: =COUNTIFS($D$10:$D$45,"L") -> 12 | AE46: 0103426345 | AF46: UMAMAH | AG46: 86.58 | AH46: A | AI46: P
...

Sheet XI-A2
A4: Tahun Pelajaran 2026 / 2027
A7: No | B7: NISN / NIS | C7: Nama Siswa | D7: L/P | E7: Wali Kelas : | H7: IRVAN RIZKANA YULIANTO, S.Pd | S7: NIP : | U7: 198007222024211006
E8: Tanggal
A10: 1 | B10: 0096571728 / 14950 | C10: ABDANIAR REGA PRATAMA | D10: L | AD10: 96571728 | AE10: ABDANIAR REGA PRATAMA | AF10: 82.93 | AG10: B | AH10: L | AJ10: ABDANIAR REGA PRATAMA | AK10: X.B | AL10: L | AM10: 635
A11: 2 | B11: 0098497655 / 14956 | C11: 'ADLY ROSYID PRATAMA | D11: L | AD11: 0103841370 | AE11: AISYAH FEBRIYANTI RIDWAN | AF11: 86.49 | AG11: B | AH11: P | AJ11: 'ADLY ROSYID PRATAMA | AK11: X.G | AL11: L | AM11: 628
A12: 3 | B12: 0096415363 / 14957 | C12: AFIA ZAFIRAH | D12: P | AD12: 0094361909 | AE12: ALIF PIRATA MUHAMMAD | AF12: 89.99 | AG12: B | AH12: L | AJ12: AFIA ZAFIRAH | AK12: X.F | AL12: P | AM12: 662
A13: 4 | B13: 0093002126 / 14960 | C13: AHMAD GHATAN AS SALAFI | D13: L | AD13: 0103673401 | AE13: AUDREY BELVA PUTRI PURNAMA | AF13: 87.5 | AG13: B | AH13: P | AJ13: AHMAD GHATAN AS SALAFI | AK13: X.G | AL13: L | AM13: 638
A14: 5 | B14: 0093742373 / 14981 | C14: ALVINA NIKMATUR RAIFA | D14: P | AD14: 106949166 | AE14: AULIA SHAFAURA ALAM | AF14: 84.47 | AG14: B | AH14: P | AJ14: ALVINA NIKMATUR RAIFA | AK14: X.G | AL14: P | AM14: 635
A15: 6 | B15: 0094292240 / 14988 | C15: ANIN WIDIA PUTRI | D15: P | AD15: 0119779058 | AE15: BALQIS MAULIDIA AZHAR | AF15: 88.01 | AG15: B | AH15: P | AJ15: ANIN WIDIA PUTRI | AK15: X.I | AL15: P | AM15: 624
A16: 7 | B16: 0103293275 / 14998 | C16: ASHYLA NURI ADISTY | D16: P | AD16: 0095885819 | AE16: BILQIS AL ARIF | AF16: 83.63 | AG16: B | AH16: P | AJ16: ASHYLA NURI ADISTY | AK16: X.I | AL16: P | AM16: 629
A17: 8 | B17: 0098345910 / 15012 | C17: AURA SUCI RAMADHANI | D17: P | AD17: 109075817 | AE17: CILA ADINDA SUDIBYO | AF17: 83.48 | AG17: B | AH17: P | AJ17: AURA SUCI RAMADHANI | AK17: X.I | AL17: P | AM17: 664
A18: 9 | B18: 0092822070 / 15021 | C18: AZARINE BELVINA WAHYUDI | D18: P | AD18: 0092553825 | AE18: DESWITAPUTRI DAYANTI | AF18: 83.30 | AG18: B | AH18: P | AJ18: AZARINE BELVINA WAHYUDI | AK18: X.H | AL18: P | AM18: 708
A19: 10 | B19: 0101428911 / 15024 | C19: AZKA DAHISY AMIN | D19: L | AD19: 0102283509 | AE19: Dzaky Almair El Rafif | AF19: 88.02 | AG19: B | AH19: L | AJ19: AZKA DAHISY AMIN | AK19: X.A | AL19: L | AM19: 715
A20: 11 | B20: 0105465852 / 15027 | C20: BALQIS KIRANA LARASATI | D20: P | AD20: 0101780275 | AE20: FINDY WAHYUNI | AF20: 86.80 | AG20: B | AH20: P | AJ20: BALQIS KIRANA LARASATI | AK20: X.G | AL20: P | AM20: 702
A21: 12 | B21: 0109534778 / 15036 | C21: BUNGA MAULIDIA | D21: P | AD21: 0109681159 | AE21: IQON ARICTA KHAIRANI | AF21: 86.89 | AG21: B | AH21: P | AJ21: CLARISSA AZZAHRA PUTRI | AK21: X.D | AL21: P | AM21: 729
A22: 13 | B22: 0099679063 / 15042 | C22: CLARISSA AZZAHRA PUTRI | D22: P | AD22: 0099606551 | AE22: IZZA AULIA SHOFA | AF22: 84.49 | AG22: B | AH22: P | AJ22: DIMAS SYAFIQY AFDILLAH | AK22: X.I | AL22: L | AM22: 638
A23: 14 | B23: 0096346576 / 15309 | C23: DIMAS SYAFIQY AFDILLAH | D23: L | AD23: 109511029 | AE23: JIMLY ARAFAT ASSIDDIQIE | AF23: 80.31 | AG23: B | AH23: L | AJ23: EKA AGUSTINA ANGGRAINI | AK23: X.F | AL23: P | AM23: 655
A24: 15 | B24: 0102616675 / 15053 | C24: EKA AGUSTINA ANGGRAINI | D24: P | AD24: 104825564 | AE24: KEVIN PUTRA NIRWANA | AF24: 81.05 | AG24: B | AH24: L
A25: 16 | B25: 0103496356 / 15079 | C25: HUGA ZAMRONI AJI | D25: L
A26: 17 | B26: '0105586723 / 15089 | C26: ISMA AMALINA | D26: P | AD26: 98740585 | AE26: M SEPTYAN DAFI RAMADHAN | AF26: 83.83 | AG26: B | AH26: L | AJ26: HUGA ZAMRONI AJI | AK26: X.H | AL26: L | AM26: 637
A27: 18 | B27: 0098447991 / 15094 | C27: IZZA BUNGA FAIRUZIA | D27: P | AD27: 97013302 | AE27: MOH YARDAN XAFIER | AF27: 78.74 | AG27: B | AH27: L | AJ27: IZZA BUNGA FAIRUZIA | AK27: X.A | AL27: P | AM27: 636
A28: 19 | B28: 0109511029 / 15097 | C28: JIMLY ARAFAT ASSIDDIQIE | D28: L | AD28: 107990597 | AE28: NAFISA NISFU SYABANA | AF28: 86.36 | AG28: B | AH28: P | AJ28: JIMLY ARAFAT ASSIDDIQIE | AK28: X.B | AL28: P | AM28: 680
A29: 20 | B29: 0092295934 / 15104 | C29: KHANSA NUR FARITA | D29: P | AD29: 0106501012 | AE29: NAJWA IZDAHARA RIZALDI | AF29: 87.28 | AG29: B | AH29: P | AJ29: KHANSA NUR FARITA | AK29: X.J | AL29: L | AM29: 624
A30: 21 | B30: 0096310303 / 15110 | C30: LAILY RIZQIYATIN EFENDY | D30: P | AD30: 0106124368 | AE30: NENSI MELANI PUTRI | AF30: 89.51 | AG30: B | AH30: P | AJ30: LAILY RIZQIYATIN EFENDY | AK30: X.I | AL30: P | AM30: 634
A31: 22 | B31: 0103080501 / 15113 | C31: M. DELFIAN ARIF PRATAMA | D31: L | AD31: 93601353 | AE31: NUR ARINI ISLAWATI | AF31: 84.13 | AG31: B | AH31: P | AJ31: M. DELFIAN ARIF PRATAMA | AK31: X.H | AL31: P | AM31: 682
A32: 23 | B32: 0106969520 / 15305 | C32: MAHREZA RIZQI MAULANA | D32: L | AD32: 0099209612 | AE32: NUR JANNATUR RAHMAN | AF32: 85.16 | AG32: B | AH32: P | AJ32: MAHREZA RIZQI MAULANA | AK32: X.J | AL32: L | AM32: 634
A33: 24 | B33: 0096139555 / 15119 | C33: MARIA SALSABILA HUDA | D33: P | AD33: 0099209612 | AE33: NUR JANNATUR RAHMAN | AF33: 85.16 | AG33: B | AH33: P | AJ33: MARIA SALSABILA HUDA | AK33: X.D | AL33: L | AM33: 670
A34: 25 | B34: 0099087085 / 15150 | C34: MOHAMMAD REZA PRAYOGA | D34: L | AD34: 0106880225 | AE34: NUR ZAHIRA ANSORULLAH | AF34: 87.19 | AG34: B | AH34: P | AJ34: MOHAMMAD REZA PRAYOGA | AK34: X.I | AL34: P | AM34: 647
A35: 26 | B35: 0097811869 / 15164 | C35: NADIF ABDILLAH | D35: L | AD35: 91509133 | AE35: Oktavia Kirana Dewi | AF35: 82.84 | AG35: B | AH35: P | AJ35: NADIF ABDILLAH | AK35: X.A | AL35: L | AM35: 631
A36: 27 | B36: 0094586702 / 15165 | C36: NADYA ALFAIDA | D36: P | AD36: 0094061017 | AE36: PRADITYA IHSAN NIZAR | AF36: 88.74 | AG36: B | AH36: L | AJ36: NADYA ALFAIDA | AK36: X.E | AL36: L | AM36: 693
A37: 28 | B37: 0095485235 / 1524 | C37: SAADATUDDARAINI | D37: P | AD37: 0091436068 | AE37: QUEEN TSABITA WIBOWO | AF37: 91.77 | AG37: B | AH37: P | AM37: 650
A38: 29 | B38: 0091417231 / 15180 | C38: NAYAKA AULIA HARIYANTO | D38: P | AD38: 0106832560 | AE38: RAJA ALFARONI PAHING | AF38: 85.86 | AG38: B | AH38: L | AJ38: NAYAKA AULIA HARIYANTO | AK38: X.F | AL38: P | AM38: 641
A39: 30 | B39: 0115565645 / 15199 | C39: NURI JANUARITA PUTRI | D39: P | AD39: 0096041224 | AE39: RAKA TARUNA PERMANA | AF39: 88.46 | AG39: B | AH39: L | AJ39: NURI JANUARITA PUTRI | AK39: X.J | AL39: P | AM39: 647
A40: 31 | B40: 0095654087 / 15207 | C40: PUTRI AGUSTINA MAHARDIKA | D40: P | AD40: 98500710 | AE40: ROFIENDRA ZACKY AHMAD | AF40: 85.21 | AG40: B | AH40: L | AJ40: PUTRI AGUSTINA MAHARDIKA | AK40: X.G | AL40: P | AM40: 647
A41: 32 | B41: 0098990180 / 15228 | C41: R.CHELSYANA RAMADHANI J | D41: P | AD41: 0102088023 | AE41: SITTI RISQI ISNAINI | AF41: 82.09 | AG41: B | AH41: P | AJ41: R.CHELSYANA RAMADHANI J | AK41: X.G | AL41: P | AM41: 675
A42: 33 | B42: 0094839217 / 15259 | C42: SHAFWAN AQILA GUSFA | D42: L | AD42: 0094963582 | AE42: SURYA HADI WIJAYA | AF42: 83.03 | AG42: B | AH42: L | AJ42: SHAFWAN AQILA GUSFA | AK42: X.A | AL42: L | AM42: 645
A43: 34 | B43: 0093921653 / 15262 | C43: SILVI AGUSTIANA | D43: P | AD43: 93167720 | AE43: SYADID AULIA FAIZAL | AF43: 86.04 | AG43: B | AH43: L | AJ43: SILVI AGUSTIANA | AK43: X.E | AL43: P | AM43: 649
A44: 35 | B44: 0103426345 / 15283 | C44: UMAMAH | D44: P | AD44: 96046595 | AE44: SYAFANIA KIRANA PUTRI S | AF44: 84.79 | AG44: B | AH44: P | AJ44: UMAMAH | AK44: X.A | AL44: P | AM44: 643
A45: 36 | B45: 0103920766 / 15286 | C45: WIHDA DZIKRIA A'YUNI | D45: P | AJ45: WIHDA DZIKRIA A'YUNI | AK45: X.D | AL45: P | AM45: 656
B46: Paraf | C46: L : | D46: =COUNTIFS($D$10:$D$45,"L") -> 12 | AD46: 0103417543 | AE46: ZAHIERA YASMIN IMANI | AF46: 86.58 | AG46: B | AH46: P
...

Sheet XI-A3
A4: Tahun Pelajaran 2026 / 2027
A7: No | B7: NISN / NIS | C7: Nama Siswa | D7: L/P | E7: Wali Kelas : | H7: EKA JUWITA WIJDANIYAH, S.Pd | S7: NIP : | U7: 199501282020122020
E8: Tanggal
A10: 1 | B10: 0094618904 / 14973 | C10: ALFIANA UTAMI PUTRI | D10: P | AD10: 1 | AE10: ALFIANA UTAMI PUTRI | AF10: X.A | AG10: P | AH10: 637
A11: 2 | B11: 0109297123 / 14991 | C11: APRILIYA ANGELICA CAHYANI | D11: P | AD11: 2 | AE11: APRILIYA ANGELICA CAHYANI | AF11: X.F | AG11: P | AH11: 650
A12: 3 | B12: 0109410681 / 14994 | C12: ARLKA WISNU WARDANA | D12: L | AD12: 3 | AE12: ARLKA WISNU WARDANA | AF12: X.H | AG12: L | AH12: 632
A13: 4 | B13: 0094556159 / 15004 | C13: AUFA NADHIF | D13: P | AD13: 4 | AE13: AUFA NADHIF | AF13: X.C | AG13: p | AH13: 643
A14: 5 | B14: 0102322274 / 15019 | C14: AYU RIZKI PUJI LESTARI | D14: P | AD14: 5 | AE14: AURELIA RAISSA APRIANDYTA | AF14: X.H | AG14: P | AH14: 634
A15: 6 | B15: 0104385803 / 15023 | C15: AZIZA CAHYA NING TIAS | D15: P | AD15: 6 | AE15: AYU RIZKI PUJI LESTARI | AF15: X.H | AG15: P | AH15: 630
A16: 7 | B16: 0105382139 / 15034 | C16: BILQIS FATHIYA MARTHA D | D16: P | AD16: 7 | AE16: AZIZA CAHYA NING TIAS | AF16: X.E | AG16: P | AH16: 645
A17: 8 | B17: 0092836765 / 15035 | C17: BRILLIAN HADE PAMUNGKAS | D17: L | AD17: 8 | AE17: BILQIS FATHIYA MARTHA D | AF17: X.H | AG17: P | AH17: 679
A18: 9 | B18: 0093756454 / 15043 | C18: DENIEL CAHYA RAHMAN PRATAMA | D18: L | AD18: 9 | AE18: BRILLIAN HADE PAMUNGKAS | AF18: X.D | AG18: L
A19: 10 | B19: 0102283509 / 15052 | C19: DZAKY ALMAIR EL-RAFIF | D19: L | AD19: 10 | AE19: DENIEL CAHYA RAHMAN PRATAMA | AF19: X.I | AG19: L | AH19: 634
A20: 11 | B20: 0094950484 / 15056 | C20: ENZA SABRINA HERYANTO | D20: P | AD20: 11 | AE20: DZAKY ALMAIR EL-RAFIF | AF20: X.B | AG20: L
A21: 12 | B21: 0102661592 / 15058 | C21: FAKHIRA INAS | D21: P | AD21: 12 | AE21: ENZA SABRINA HERYANTO | AF21: X.G | AG21: P | AH21: 628
A22: 13 | B22: 0107735504 / 15071 | C22: GADIS OKTAVIANA WAHYUDI | D22: P | AD22: 13 | AE22: FAKHIRA INAS | AF22: X.I | AG22: P | AH22: 710
A23: 14 | B23: 0091386648 / 15310 | C23: GHILAN AL DIMIZYQY | D23: L | AD23: 14 | AE23: GADIS OKTAVIANA WAHYUDI | AF23: X.D | AG23: P | AH23: 645
A24: 15 | B24: 0109018947 / 15082 | C24: IKSYA ALFIALFUN AZKA ALIMI | D24: L | AD24: 15 | AE24: GHILAN AL DIMIZYQY | AF24: X.I | AG24: L | AH24: 640
A25: 16 | B25: 0091308783 / 15093 | C25: IZZA AULIA SHOFI | D25: P | AD25: 16 | AE25: IKSYA ALFIALFUN AZKA ALIMI | AF25: X.D | AG25: P | AH25: 702
A26: 17 | B26: 0117862295 / 15095 | C26: JANEETA IZZAH INSYIRAH | D26: P | AD26: 17 | AE26: IZZA AULIA SHOFI | AF26: X.I | AG26: P | AH26: 637
A27: 18 | B27: 0098798782 / 15112 | C27: LINDA YOHANA MAULINA | D27: P | AD27: 18 | AE27: JANEETA IZZAH INSYIRAH | AF27: X.D | AG27: P | AH27: 647
A28: 19 | B28: 0107399996 / 15131 | C28: MOH. BAGUS AKBAR | D28: L | AD28: 19 | AE28: JANUAR RAFI GUNAWAN | AF28: X.H | AG28: L | AH28: 662
A29: 20 | B29: 0094399729 / 15139 | C29: MOH. REFAN DANIYAL ARIF | D29: L
A30: 21 | B30: 3104234462 / 15151 | C30: MOHAMMAD RIZKY RAFIF TAMAM | D30: L | AD30: 21 | AE30: MOH. BAGUS AKBAR | AF30: X.H | AG30: L | AH30: 636
A31: 22 | B31: 0092206920 / 15166 | C31: NAFIL FAYYADH NAZHIFILLAH | D31: L | AD31: 22 | AE31: MOH. REFAN DANIYAL ARIF | AF31: X.I | AG31: L | AH31: 728
A32: 23 | B32: 0106501012 / 15171 | C32: NAJWA IZDAHARA RIZALDI | D32: P | AD32: 23 | AE32: MOHAMMAD RIZKY RAFIF TAMAM | AF32: X.A | AG32: L | AH32: 641
A33: 24 | B33: 0106063120 / 15189 | C33: NIKEISHA RAYYA SANDRICA | D33: P | AD33: 24 | AE33: NAFIL FAYYADH NAZHIFILLAH | AF33: X.F | AG33: L | AH33: 669
A34: 25 | B34: 0095917604 / 15312 | C34: NIKEN DWI PUJI HASTUTI | D34: P | AD34: 25 | AE34: NAJWA IZDAHARA RIZALDI | AF34: X.B | AG34: P | AH34: 682
A35: 26 | B35: 0107213872 / 15201 | C35: NURIN ALAMSYAH | D35: P | AD35: 26 | AE35: NIKEN DWI PUJI HASTUTI | AF35: X.H | AG35: P | AH35: 676
A36: 27 | B36: 0091509133 / 15204 | C36: OKTAVIA KIRANA DEWI | D36: P | AD36: 27 | AE36: NURIN ALAMSYAH | AF36: X.H | AG36: P | AH36: 626
A37: 28 | B37: 0094061017 / 15206 | C37: PRADITYA IHSAN NIZAR | D37: L | AD37: 28 | AE37: OKTAVIA KIRANA DEWI | AF37: X.B | AG37: P | AH37: 646
A38: 29 | B38: 0091436068 / 15208 | C38: QUEEN TSABITA WIBOWO | D38: P | AD38: 29 | AE38: PRADITYA IHSAN NIZAR | AF38: X.B | AG38: L | AH38: 643
A39: 30 | B39: 0104164486 / 15214 | C39: RAFI ADI CAHYONO | D39: L | AD39: 30 | AE39: QUEEN TSABITA WIBOWO | AF39: X.B | AG39: P | AH39: 714
A40: 31 | B40: 0107765646 / 15221 | C40: RANIA DWI AMYRA PUTRI | D40: P | AD40: 31 | AE40: RAFI ADI CAHYONO | AF40: X.G | AG40: L | AH40: 629
A41: 32 | B41: 0102391972 / 15245 | C41: SABRINA FADILA BAHRI | D41: P | AD41: 32 | AE41: RANIA DWI AMYRA PUTRI | AF41: X.E | AG41: P | AH41: 693
... A45: 36 | B45: 0101261269 / 15300 | C45: ZIYADATU NAJAHATIN | D45: P | AD45: 36 | AE45: ZIYADATU NAJAHATIN | AF45: X.C | AG45: P | AH45: 666
A46: Paraf | C46: L : | D46: =COUNTIFS($D$10:$D$45,"L") -> 12
A47: Guru | C47: P : | D47: =COUNTIFS($D$10:$D$45,"P") -> 24
D48: =SUM(D46:D47) -> 36

Sheet XI-A4
A4: Tahun Pelajaran 2026 / 2027
A7: No | B7: NISN / NIS | C7: Nama Siswa | D7: L/P | E7: Wali Kelas : | H7: HENNY FITRIYANTI, S.Pd | S7: NIP : | U7: 198506232022212035
E8: Tanggal
A10: 1 | B10: 0102753361 / 14961 | C10: AHMAD IRFAN AMRULLAH | D10: L | AD10: 101958421 | AE10: Akbar Maulana | AF10: 78.28 | AG10: D | AH10: L | AJ10: 1 | AK10: AHMAD IRFAN AMRULLAH | AL10: X.F | AM10: L
A11: 2 | B11: 0097947151 / 14966 | C11: AIDAN LUTFAN RAMADAN IDOFI | D11: L | AD11: 102964984 | AE11: ALDAFA ZACKY AGUSTIAN | AF11: 83.42 | AG11: D | AH11: L | AJ11: 2 | AK11: AIDAN LUTFAN RAMADAN IDOFI | AL11: X.E | AM11: L
A12: 3 | B12: 0091251777 / 14984 | C12: AMIRAH DHIYA HANUN | D12: P | AD12: 0091251777 | AE12: Amirah Dhiya Hanun | AF12: 87.85 | AG12: D | AH12: P | AJ12: 3 | AK12: AMIRAH DHIYA HANUN | AL12: X.D | AM12: P
A13: 4 | B13: 0107938836 / 14985 | C13: ANA ALTHAFUNNISA HIDAYATI | D13: P | AD13: 0109950311 | AE13: Anisa Amilia Azzahra | AF13: 90.86 | AG13: D | AH13: P | AJ13: 4 | AK13: ANA ALTHAFUNNISA HIDAYATI | AL13: X.E | AM13: P
A14: 5 | B14: 0105301544 / 14999 | C14: ASYAM ABQARI | D14: L | AD14: 0104805741 | AE14: APRILIA NURISTIGFARAH ARIFIN | AF14: 83.25 | AG14: D | AH14: P | AJ14: 5 | AK14: ASYAM ABQARI | AL14: X.A | AM14: L
A15: 6 | B15: 0105311993 / 15002 | C15: ASYRAF KHAIRULLAH PRATAMA | D15: L | AD15: 0107357333 | AE15: AULIA DIKKRI SHAFIALLAH | AF15: 78.66 | AG15: D | AH15: P | AJ15: 6 | AK15: ASYRAF KHAIRULLAH PRATAMA | AL15: X.A | AM15: L
A16: 7 | B16: 0096329996 / 15005 | C16: AULIA AGUSTININGTIYAS SUMANTRI | D16: P | AD16: 0092807579 | AE16: Aura Dieva Bilquizt | AF16: 85.71 | AG16: D | AH16: P | AJ16: 7 | AK16: AULIA AGUSTININGTIYAS SUMANTRI | AL16: X.I | AM16: P
A17: 8 | B17: 0105865356 / 15030 | C17: BELA DWIGINA AFRILIA | D17: P | AD17: 3102130692 | AE17: AURIZKIAN WIDAD ALIM PRANATA | AF17: 82.55 | AG17: D | AH17: L | AJ17: 8 | AK17: BELA DWIGINA AFRILIA | AL17: X.C | AM17: P
A18: 9 | B18: 0095885819 / 15033 | C18: BILQIS AL-ARIF | D18: P | AD18: 0098967601 | AE18: AYUDITA SANTINOVA SETIAWAN | AF18: 83.57 | AG18: D | AH18: P | AJ18: 9 | AK18: BILQIS AL-ARIF | AL18: X.B | AM18: P
A19: 10 | B19: 0107129633 / 15040 | C19: CHIKA NANDA FEBRIO | D19: P | AD19: 0092836765 | AE19: BRILLIAN HADE PAMUNGKAS | AF19: 88.48 | AG19: D | AH19: L | AJ19: 10 | AK19: CHIKA NANDA FEBRIO | AL19: X.G | AM19: P
A20: 11 | B20: 0106940001 / 15046 | C20: DEVI TAZKIYATUNNAFSI HADI | D20: P | AD20: 109534778 | AE20: BUNGA MAULIDIA | AF20: 84.74 | AG20: D | AH20: P | AJ20: 11 | AK20: DEVI TAZKIYATUNNAFSI HADI | AL20: X.D | AM20: P
A21: 12 | B21: 0092986195 / 15062 | C21: FIEDA SARI NUR HIDAYAH | D21: P | AD21: 0099679063 | AE21: Clarissa Azzahra Putri | AF21: 87.25 | AG21: D | AH21: P | AJ21: 12 | AK21: FIEDA SARI NUR HIDAYAH | AL21: X.J | AM21: P
A22: 13 | B22: 0117501391 / 15064 | C22: FIKRI AKMAL ASYROFI | D22: L | AJ22: 13 | AK22: FIKRI AKMAL ASYROFI | AL22: X.D | AM22: L
A23: 14 | B23: 0099513497 / 15083 | C23: IMROATUL AZIZAH | D23: P | AD23: 92564881 | AE23: FIKI PUTRA RAMADHON | AF23: 79.09 | AG23: D | AH23: L | AJ23: 14 | AK23: IMROATUL AZIZAH | AL23: X.C | AM23: P
A24: 15 | B24: 0101930964 / 15088 | C24: IRDHA ANDINI ISLAMI | D24: P | AD24: 0117501391 | AE24: fikri akmal asyrofi | AF24: 89.62 | AG24: D | AH24: P | AJ24: 15 | AK24: INTAN NOVI DWIARINI | AL24: X.H | AM24: P
A25: 16 | B25: 0092754004 / 15090 | C25: ISNATA MALA ABRARA | D25: P | AD25: 0107735504 | AE25: GADIS OKTAVIANA WAHYUDI | AF25: 87.67 | AG25: D | AH25: P | AJ25: 16 | AK25: IRDHA ANDINI ISLAMI | AL25: X.E | AM25: P
A26: 17 | B26: 0102330056 / 15126 | C26: MIEZA ARDANIA LINNAS | D26: P | AD26: 0099405271 | AE26: HARYA PANDU ELYANTA PIO | AF26: 87.82 | AG26: D | AH26: L | AJ26: 17 | AK26: ISNATA MALA ABRARA | AL26: X.F | AM26: P
A27: 18 | B27: 0092469073 / 15142 | C27: MOH. SYAFRUDIN SYAFRI AZIZ | D27: L | AD27: 0109018947 | AE27: IKSYA ALFIALFUN AZKA ALIMI | AF27: 87.46 | AG27: D | AH27: P | AJ27: 18 | AK27: MIEZA ARDANIA LINNAS | AL27: X.C | AM27: P
A28: 19 | B28: 0103586895 / 15145 | C28: MOHAMAD SYAUQII AL FALAH | D28: L | AD28: 117862295 | AE28: JANEETA IZZAH INSYIRAH | AF28: 85.09 | AG28: D | AH28: P | AJ28: 19 | AK28: MOH. SYAFRUDIN SYAFRI AZIZ | AL28: X.J | AM28: L
A29: 20 | B29: 0099801880 / 15161 | C29: NABILY RIZKY RAHMADANI | D29: L | AD29: 0107631527 | AE29: M GHIBRAN IMAS SYAHPUTRA | AF29: 89.37 | AG29: D | AH29: L | AJ29: 20 | AK29: MOHAMAD SYAUQII AL FALAH | AL29: X.D | AM29: L
A30: 21 | B30: 0094137933 / 15174 | C30: NAJWAS SHYFA | D30: P | AD30: 0096139555 | AE30: MARIA SALSABILA HUDA | AF30: 82.82 | AG30: D | AH30: P | AJ30: 21 | AK30: NABILY RIZKY RAHMADANI | AL30: X.I | AM30: L
A31: 22 | B31: 0095576452 / 15182 | C31: NAYLA NAZHIRANUHA | D31: P | AD31: 107743638 | AE31: MOH NAZRUL PRAMANA | AF31: 80.44 | AG31: D | AH31: L | AJ31: 22 | AK31: NAJWAS SHYFA | AL31: X.B | AM31: P
A32: 23 | B32: 0093664932 / 15183 | C32: NAYLA ZAGITA NURELIZA | D32: P | AD32: 103586895 | AE32: MOHAMAD SYAUQII AL FALAH | AF32: 85.94 | AG32: D | AH32: L | AJ32: 23 | AK32: NAYLA ZAGITA NURELIZA | AL32: X.D | AM32: P
A33: 24 | B33: 0092003280 / 15184 | C33: NAZRIL RADITYA ABDI | D33: L | AD33: 96668989 | AE33: NADA SYAHRIA THALLIB | AF33: 86.27 | AG33: D | AH33: P | AJ33: 24 | AK33: NAZRIL RADITYA ABDI | AL33: X.C | AM33: L
A34: 25 | B34: 0099209612 / 15197 | C34: NUR JANNATUR RAHMAN | D34: P | AD34: 0093664932 | AE34: NAYLA ZAGITA NURELIZA | AF34: 86.84 | AG34: D | AH34: P | AJ34: 25 | AK34: NUR JANNATUR RAHMAN | AL34: X.B | AM34: P
A35: 26 | B35: 0106844824 / 15205 | C35: ORIBEL ALMIRA AZ ZAHRA | D35: P | AD35: 3098293614 | AE35: NAZWA NURAISYAH | AF35: 85.12 | AG35: D | AH35: P | AJ35: 26 | AK35: ORIBEL ALMIRA AZ ZAHRA | AL35: X.I | AM35: P
A36: 27 | B36: 0108025210 / 15308 | C36: PUTRI AMELIA LAUDANIA | D36: P | AD36: 96501202 | AE36: NUR AFNI MARISA HENDRI | AF36: 83.75 | AG36: D | AH36: P | AJ36: 27 | AK36: PUTRI AMELIA LAUDANIA | AL36: X.G | AM36: P
A37: 28 | B37: 0106832560 / 15217 | C37: RAJA ALFARONI PAHING | D37: L | AD37: 0103191587 | AE37: NUR ASHFA AZKIYAH SISWAJI | AF37: 87.49 | AG37: D | AH37: P | AJ37: 28 | AK37: RAJA ALFARONI PAHING | AL37: X.B | AM37: L
A38: 29 | B38: 0097533193 / 15224 | C38: RANITA DWI CAHYANI | D38: P | AD38: 0099202101 | AE38: OKTAVIA AYU NINGTIYAS | AF38: 86.35 | AG38: D | AH38: P | AJ38: 29 | AK38: RANITA DWI CAHYANI | AL38: X.I | AM38: P
A39: 30 | B39: 0105240233 / 15238 | C39: ROBITH IMANI BILLAH | D39: L | AD39: 3095038031 | AE39: REYNATA SAHIFA ALKALIFI | AF39: 88.36 | AG39: D | AH39: P | AJ39: 30 | AK39: ROBITH IMANI BILLAH | AL39: X.A | AM39: L
A40: 31 | B40: 0093702483 / 15241 | C40: ROSA AYU WANDIRA | D40: P | AD40: 93702483 | AE40: ROSA AYU WANDIRA | AF40: 82.36 | AG40: D | AH40: P | AJ40: 31 | AK40: ROSA AYU WANDIRA | AL40: X.D | AM40: P
A41: 32 | B41: 3092351249 / 15246 | C41: SABRINA RAMADHANI | D41: P | AD41: 0094659446 | AE41: Rumania Salsabila | AF41: 84.39 | AG41: D | AH41: P | AJ41: 32 | AK41: SABRINA RAMADHANI | AL41: X.J | AM41: P
A42: 33 | B42: 0093167720 / 15269 | C42: SYADID AULIA FAIZAL | D42: P | AD42: 0099585326 | AE42: Septia Ramadina Nursyamsi | AF42: 86.55 | AG42: D | AH42: P | AJ42: 33 | AK42: SYADID AULIA FAIZAL | AL42: X.B | AM42: P
A43: 34 | B43: 0097450728 / 15273 | C43: SYIFA ANISATUL AMALIYA SATAR | D43: P | AD43: 101345533 | AE43: SILVINA APRILIANI | AF43: 83.99 | AG43: D | AH43: P | AJ43: 34 | AK43: SYIFA ANISATUL AMALIYA SATAR | AL43: X.H | AM43: P
A44: 35 | B44: 0093642477 / 15282 | C44: ULIN NIAMI | D44: P | AD44: 102567048 | AE44: Syahdienda Meizyra Maskur | AF44: 84.37 | AG44: D | AH44: P | AJ44: 35 | AK44: ULIN NIAMI | AL44: X.C | AM44: P
A45: 36 | B45: 0098138581 / 15299 | C45: ZATRYA WAHYU PRATAMA | D45: L | AD45: 0092307178 | AE45: TSURAYA SHINTA RAMADHANI | AF45: 86.66 | AG45: D | AH45: P | AJ45: 36 | AK45: ZATRYA WAHYU PRATAMA | AL45: X.F | AM45: L
A46: Paraf | C46: L : | D46: =COUNTIFS($D$10:$D$45,"L") -> 12 | AD46: 0103920766 | AE46: WIHDA DZIKRIA AYUNI | AF46: 86.69 | AG46: D | AH46: P
...

Sheet XI-A5
AK3: ABDU DAKAIL FATHON
A4: Tahun Pelajaran 2026 / 2027
A7: No | B7: NISN / NIS | C7: Nama Siswa | D7: L/P | E7: Wali Kelas : | H7: AGUNG TRI PRASETYO, ST | S7: NIP : | U7: 198101042024211006
E8: Tanggal
A10: 1 | B10: 0094915611 / 14951 | C10: ABDU DAKAIL FATHON | D10: L | AD10: 106096923 | AE10: Ach Ramzi Arifandi Habibullah | AF10: 85.06 | AG10: E | AH10: L | AJ10: 1 | AL10: X.A | AM10: L
A11: 2 | B11: 0099620577 / 14964 | C11: AHMAD RAFA RAMADANI | D11: L | AD11: 0097947151 | AE11: AIDAN LUTFAN RAMADAN IDOFI | AF11: 88.34 | AG11: E | AH11: L | AJ11: 2 | AK11: AISYAH DWIANA PRIYUDHA | AL11: X.E | AM11: P
A12: 3 | B12: 0101534636 / 14968 | C12: AISYAH DWIANA PRIYUDHA | D12: P | AD12: 101534636 | AE12: AISYAH DWIANA PRIYUDHA | AF12: 83.95 | AG12: E | AH12: P | AJ12: 3 | AK12: ALIF PIRATA MUHAMMAD | AL12: X.B | AM12: L
A13: 4 | B13: 0094361909 / 14976 | C13: ALIF PIRATA MUHAMMAD | D13: L | AD13: 109722078 | AE13: ALF HAAFIZ AKBAR | AF13: 85.89 | AG13: E | AH13: L | AJ13: 4 | AK13: ALIYYA WAHYU SHOFIYANI | AL13: X.G | AM13: P
A14: 5 | B14: 0091486816 / 14978 | C14: ALIYYA WAHYU SHOFIYANI | D14: P | AD14: 106420698 | AE14: ALMIRA CINTA CAHYADEWI | AF14: 83.72 | AG14: E | AH14: P | AJ14: 5 | AK14: ALMIRA CINTA CAHYADEWI | AL14: X.E | AM14: P
A15: 6 | B15: 0106420698 / 14979 | C15: ALMIRA CINTA CAHYADEWI | D15: P | AD15: 0107938836 | AE15: ANA ALTHAFUNNISA HIDAYATI | AF15: 90.54 | AG15: E | AH15: P | AJ15: 6 | AK15: ANGELINA SYIFAAUR RAHMAH | AL15: X.A | AM15: P
A16: 7 | B16: 0108584503 / 14987 | C16: ANGELINA SYIFAAUR RAHMAH | D16: P | AD16: 0091345116 | AE16: AVISA DWI AURELIA | AF16: 87.85 | AG16: E | AH16: P | AJ16: 7 | AK16: ARISTA DWI SHABRINA | AL16: X.J | AM16: P
A17: 8 | B17: 0096939540 / 14993 | C17: ARISTA DWI SHABRINA | D17: P | AD17: 0104385803 | AE17: AZIZA CAHYA NING TIAS | AF17: 84.26 | AG17: E | AH17: P | AJ17: 8 | AK17: ASYIFA PUTRI AZIZAH | AL17: X.A | AM17: P
A18: 9 | B18: 0104677265 / 15000 | C18: ASYIFA PUTRI AZIZAH | D18: P | AD18: 95911412 | AE18: BERLIAN CALLISTA MAHERA | AF18: 83.42 | AG18: E | AH18: P | AJ18: 9 | AK18: AULIYATUL RAZNI AMALIYA | AL18: X.F | AM18: P
A19: 10 | B19: 0095005653 / 15009 | C19: AULIYATUL RAZNI AMALIYA | D19: P | AD19: 0093334062 | AE19: Cantika Putri Oktaviana | AF19: 86.66 | AG19: E | AH19: P | AJ19: 10 | AK19: AVISA DWI AURELIA | AL19: X.E | AM19: P
A20: 11 | B20: 0091345116 / 15018 | C20: AVISA DWI AURELIA | D20: P | AD20: 109089490 | AE20: DIAH KANZA NAILA | AF20: 82.34 | AG20: E | AH20: P | AJ20: 11 | AK20: BHAGAS TAQDIR RIFSYAHBANA | AL20: X.J | AM20: L
A21: 12 | B21: 0092924660 / 15032 | C21: BHAGAS TAQDIR RIFSYAHBANA | D21: L | AD21: 0169517134 | AE21: DIAYU ALUNA HANY | AF21: 85.65 | AG21: E | AH21: P | AJ21: 12 | AK21: CANTIKA PUTRI OKTAVIANA | AL21: X.E
A22: 13 | B22: 0093334062 / 15038 | C22: CANTIKA PUTRI OKTAVIANA | D22: P | AD22: 0092760546 | AE22: FIDELA SUCI RAMADHANI | AF22: 88.37 | AG22: E | AH22: P | AJ22: 13 | AK22: DEWI ARDHANARESWARI P | AL22: X.G | AM22: P
A23: 14 | B23: 0106425839 / 15047 | C23: DEWI ARDHANARESWARI P | D23: P | AD23: 0091669818 | AE23: IBRAHIM AZZAHEDY | AF23: 87.72 | AG23: E | AH23: L | AJ23: 14 | AK23: IQON ARICTA KHAIRANI | AL23: X.B | AM23: P
A24: 15 | B24: 0109681159 / 15087 | C24: IQON ARICTA KHAIRANI | D24: P | AD24: 0101930964 | AE24: Irdha Andini Islami | AF24: 87.58 | AG24: E | AH24: P | AJ24: 15 | AK24: KANZA NABILA KHAIRANI IMRAN | AL24: X.F | AM24: P
A25: 16 | B25: 0108350178 / 15096 | C25: JANUAR RAFI GUNAWAN | D25: L | AD25: 0093300658 | AE25: Khairil Firdaus Alfarisi | AF25: 87.06 | AG25: E | AH25: L | AJ25: 16 | AK25: LAURA NURMAULIDATUL FEBRIANI | AL25: X.J | AM25: P
A26: 17 | B26: 0095532922 / 15098 | C26: KANZA NABILA KHAIRANI IMRAN | D26: P | AD26: 0092687403 | AE26: KHALILA DHIA SYARAFANA | AF26: 86.81 | AG26: E | AH26: P | AJ26: 17 | AK26: M. GHIBRAN IMAS SYAHPUTRA | AL26: X.D | AM26: P
A27: 18 | B27: 0105498897 / 15111 | C27: LAURA NURMAULIDATUL FEBRIANI | D27: P | AD27: 92101230 | AE27: KHARISMA SALSABILA IZZATI | AF27: 82.46 | AG27: E | AH27: P | AJ27: 18 | AK27: M. ZULFAN FAHLEVI | AL27: X.J | AM27: L
A28: 19 | B28: 0107631527 / 15114 | C28: M. GHIBRAN IMAS SYAHPUTRA | D28: L | AD28: 0093620132 | AE28: Mierelda Virginia Utami | AF28: 86.65 | AG28: E | AH28: P | AJ28: 19 | AK28: MOH. ALFAREZA BASUKI | AL28: X.F | AM28: L
A29: 20 | B29: 0106819845 / 15118 | C29: M. ZULFAN FAHLEVI | D29: L | AD29: 0106569429 | AE29: MOH AFIFUR RIZAL | AF29: 83.56 | AG29: E | AH29: L | AJ29: 20 | AK29: MOH. NABIL KHUROZIM FANDY | AL29: X.G | AM29: L
A30: 21 | B30: 0093599464 / 15130 | C30: MOH. ALFAREZA BASUKI | D30: L | AD30: 0098648558 | AE30: MOH RADITYA PRATAMA PUTRA | AF30: 85.07 | AG30: E | AH30: L | AJ30: 21 | AK30: MUHAMMAD ROYHAN ABRORI | AL30: X.J | AM30: L
A31: 22 | B31: 0102122050 / 15135 | C31: MOH. NABIL KHUROZIM FANDY | D31: L | AD31: 0099738844 | AE31: MOH SAHLAN | AF31: 82.66 | AG31: E | AH31: L | AJ31: 22 | AK31: MUTIA FAHRUNNISA | AL31: X.G | AM31: L
A32: 23 | B32: 0093475325 / 15157 | C32: MUHAMMAD ROYHAN ABRORI | D32: L | AD32: 0106779710 | AE32: MOH ZULFIKAR MASA BAKTI | AF32: 86.26 | AG32: E | AH32: L | AJ32: 23 | AK32: NAJMA KHUMAIROH RIYADI | AL32: X.J | AM32: P
A33: 24 | B33: 0094231988 / 15307 | C33: MUTIA FAHRUNNISA | D33: P | AD33: 98252155 | AE33: MUHAMMAD AFDHAN SYAQURO | AF33: 80.35 | AG33: E | AH33: L | AJ33: 24 | AK33: NIDYA RAMADITA | AL33: X.I | AM33: P
A34: 25 | B34: 0105675978 / 15168 | C34: NAJMA KHUMAIROH RIYADI | D34: P | AD34: 0095324478 | AE34: NABILA HASNA IZZATY EFENDY | AF34: 87.42 | AG34: E | AH34: P | AJ34: 25 | AK34: NUR ASHFA AZKIYAH SISWAJI | AL34: X.D | AM34: P
A35: 26 | B35: 0107423174 / 15188 | C35: NIDYA RAMADITA | D35: P | AD35: 0094586702 | AE35: NADYA ALFAIDA | AF35: 89.54 | AG35: E | AH35: P | AJ35: 26 | AK35: RAFA ALCANDER AZKARASHYA | AL35: X.J | AM35: P
A36: 27 | B36: 0103191587 / 15195 | C36: NUR ASHFA AZKIYAH SISWAJI | D36: P | AD36: 0096561228 | AE36: NAURAH AMBAR LAILA | AF36: 87.48 | AG36: E | AH36: P | AJ36: 27 | AK36: REGINA KIRANA LARASATI | AL36: X.J | AM36: L
A37: 28 | B37: 0101455019 / 15212 | C37: RAFA ALCANDER AZKARASHYA | D37: L | AD37: 0096593023 | AE37: NAUREHAL PASAI | AF37: 83.18 | AG37: E | AH37: L | AJ37: 28 | AK37: REYHAN DWI PUTRA WAHYUDI | AL37: X.J | AM37: P
A38: 29 | B38: 0101227457 / 15229 | C38: REGINA KIRANA LARASATI | D38: P | AD38: 0107765646 | AE38: RANIA DWI AMYRA PUTRI | AF38: 89.34 | AG38: E | AH38: P | AJ38: 29 | AK38: RIVA ARRIDHO MAULANA | AL38: X.F | AM38: L
A39: 30 | B39: 0094658320 / 15231 | C39: REYHAN DWI PUTRA WAHYUDI | D39: L | AD39: 0107040234 | AE39: RATU KAYYISAH YAMANIYYAH BUDIARTA | AF39: 87.15 | AG39: E | AH39: P | AJ39: 30 | AK39: ROBIATUL WAHIDIYAH AL-AMIR PUTRI | AL39: X.A | AM39: L
A40: 31 | B40: 0101073797 / 15236 | C40: RIVA ARRIDHO MAULANA | D40: L | AD40: 103816414 | AE40: ROZITA AMALINA DINI | AF40: 86.17 | AG40: E | AH40: P | AJ40: 31 | AK40: SABRINA FADILA BAHRI | AL40: X.C | AM40: P
A41: 32 | B41: 0095467404 / 15237 | C41: ROBIATUL WAHIDIYAH AL-AMIR PUTRI | D41: P | AD41: 0093921653 | AE41: SILVI AGUSTIANA | AF41: 86.54 | AG41: E | AH41: P | AJ41: 32 | AK41: SEPTIAZHA BILQIST PUTRI LILYANA | AL41: X.D | AM41: P
A42: 33 | B42: 0092876045 / 15254 | C42: SEPTIAZHA BILQIST PUTRI LILYANA | D42: P | AD42: 96256266 | AE42: SURYA DAFFA MAHARDHIKA ALY | AF42: 84.34 | AG42: E | AH42: L | AJ42: 33 | AK42: SHAFA AZIYAH PUTRI | AL42: X.A | AM42: P
A43: 34 | B43: 0101950178 / 15257 | C43: SHAFA AZIYAH PUTRI | D43: P | AD43: 106598961 | AE43: TALITA LUQYANA AISYAH | AF43: 84.73 | AG43: E | AH43: P | AJ43: 34 | AK43: SITTI RISQI ISNAINI | AL43: X.B | AM43: P
A44: 35 | B44: 0102088023 / 15264 | C44: SITTI RISQI ISNAINI | D44: P | AJ44: 35 | AK44: SULTAN KAFA RASTRA SUGIANTO | AL44: X.G | AM44: P
A45: 36 | B45: 0103239495 / 15266 | C45: SULTAN KAFA RASTRA SUGIANTO | D45: L | AJ45: 36 | AM45: L
...

Sheet XI-B
A4: Tahun Pelajaran 2026 / 2027
A7: No | B7: NISN / NIS | C7: Nama Siswa | D7: L/P | E7: Wali Kelas : | H7: UMARUL FARUQ, S.Pd | S7: NIP : | U7: 1.9880715e+17
E8: Tanggal | AK8: 0105049596 / 15075
A10: 1 | B10: 0093442626 / 14986 | C10: ANDINI CLARESTA PUTRI WAHYUDI | D10: P | AD10: 0096415363 | AE10: AFIA ZAFIRAH | AF10: 89.47 | AG10: F | AH10: P | AK10: 0093442626 / 14986 | AL10: ANDINI CLARESTA PUTRI WAHYUDI | AM10: P | AN10: X.C
A11: 2 | B11: 0106949166 / 15008 | C11: AULIA SHAFAURA ALAM | D11: P | AD11: 102753361 | AE11: AHMAD IRFAN AMRULLAH | AF11: 82.33 | AG11: F | AH11: L | AK11: 0106949166 / 15008 | AL11: AULIA SHAFAURA ALAM | AM11: P | AN11: X.B
A12: 3 | B12: 0092807579 / 15010 | C12: AURA DIEVA BILQUIZT | D12: P | AD12: 0109297123 | AE12: APRILIYA ANGELICA CAHYANI | AF12: 87.01 | AG12: F | AH12: P | AK12: 0092807579 / 15010 | AL12: Aura Dieva Bilquizt | AM12: P | AN12: X.F
A13: 4 | B13: 0105174754 / 15015 | C13: AURELIA RAISSA APRIANDYTA | D13: P | AD13: 0095090304 | AE13: ARYATAMA REZA RAFAYENDRA | AF13: 87.69 | AG13: F | AH13: L | AK13: 0099364614 / 15025 | AL13: Azriel Sabilillah Arkana | AM13: L | AN13: X.H
A14: 5 | B14: 0099364614 / 15025 | C14: AZRIEL SABILILLAH ARKANA | D14: L | AD14: 98598715 | AE14: AURA ZAHRIMA SALSABILA | AF14: 83.68 | AG14: F | AH14: P | AK14: 0119779058 / 15028 | AL14: BALQIS MAULIDIA AZHAR | AM14: P | AN14: X.F
A15: 6 | B15: 0119779058 / 15028 | C15: BALQIS MAULIDIA AZHAR | D15: P | AD15: 97582178 | AE15: BARA PRAMUDYA PUTRA NUGRAHA | AF15: 83.41 | AG15: F | AH15: L | AK15: 0169517134 / 15051 | AL15: DIAYU ALUNA HANY | AM15: P | AN15: X.E
A16: 7 | B16: 0109075817 / 15041 | C16: CILA ADINDA SUDIBYO | D16: P | AD16: 0098060781 | AE16: DHIYA SYAHIRA ATIKA RIZKY | AF16: 87.43 | AG16: F | AH16: P | AK16: 0109363761 / 15059 | AL16: Fakhira Maulida Algifari | AM16: P | AN16: X.H
A17: 8 | B17: 0169517134 / 15051 | C17: DIAYU ALUNA HANY | D17: P | AD17: 0102616675 | AE17: EKA AGUSTINA ANGGRAINI | AF17: 86.53 | AG17: F | AH17: P | AK17: 0103019259 / 15060 | AL17: Fathan Athaya Infaner | AM17: L | AN17: X.I
A18: 9 | B18: 0109363761 / 15059 | C18: FAKHIRA MAULIDA ALGIFARI | D18: P | AD18: 102498373 | AE18: FIRSYA RAMANSYAH PUTRI R | AF18: 84.29 | AG18: F | AH18: P | AK18: 0092760546 / 15061 | AL18: FIDELA SUCI RAMADHANI | AM18: P | AN18: X.E
A19: 10 | B19: 0103019259 / 15060 | C19: FATHAN ATHAYA INFANER | D19: L | AD19: 0107912441 | AE19: FRITZI RAFA ADITYA DHANA | AF19: 89.29 | AG19: F | AH19: L | AK19: 0101780275 / 15065 | AL19: FINDY WAHYUNI | AM19: P | AN19: X.B
A20: 11 | B20: 0092760546 / 15061 | C20: FIDELA SUCI RAMADHANI | D20: P | AD20: 0108325753 | AE20: INDAH MAULIDIYA | AF20: 84.91 | AG20: F | AH20: P | AK20: 0092687403 / 15102 | AL20: KHALILA DHIA SYARAFANA | AM20: P | AN20: X.E
A21: 12 | B21: 0098243995 / 15086 | C21: INTAN NOVI DWIARINI | D21: P | AD21: 0092754004 | AE21: ISNATA MALA ABRARA | AF21: 86.64 | AG21: F | AH21: P | AK21: 0098740585 / 15117 | AL21: M. SEPTYAN DAFI RAMADHAN | AM21: L | AN21: X.B
A22: 13 | B22: 0092687403 / 15102 | C22: KHALILA DHIA SYARAFANA | D22: P | AD22: 0095532922 | AE22: KANZA NABILA KHAIRANI IMRAN | AF22: 86.18 | AG22: F | AH22: P | AK22: 0094332428 / 15147 | AL22: MOHAMMAD AQIL RAYHAN AL-ARIF | AM22: L | AN22: X.I
A23: 14 | B23: 0098740585 / 15117 | C23: M. SEPTYAN DAFI RAMADHAN | D23: L | AD23: 95739171 | AE23: Keyrani Larasati Ningrum | AF23: 82.09 | AG23: F | AH23: P | AK23: 0101068410 / 15149 | AL23: MOHAMMAD RAMA ADITYA PRATAMA | AM23: L | AN23: X.I
A24: 15 | B24: 0094332428 / 15147 | C24: MOHAMMAD AQIL RAYHAN AL-ARIF | D24: L | AD24: 0111441132 | AE24: MIRANDA PURNAMA DEWI | AF24: 85.64 | AG24: F | AH24: P | AK24: 0095324478 / 15159 | AL24: NABILA HASNA IZZATY EFENDY | AM24: P | AN24: X.E
A25: 16 | B25: 0101068410 / 15149 | C25: MOHAMMAD RAMA ADITYA PRATAMA | D25: L | AD25: 0093599464 | AE25: MOH ALFAREZA BASUKI | AF25: 87.34 | AG25: F | AH25: L | AK25: 0097758689 / 15160 | AL25: NABILA OKTAVIANI REFTI | AM25: P | AN25: X.F
A26: 17 | B26: 0095324478 / 15159 | C26: NABILA HASNA IZZATY EFENDY | D26: P | AD26: 0094490553 | AE26: MOH GHAZY ARYADHANA | AF26: 84.20 | AG26: F | AH26: L | AK26: 0107990597 / 15167 | AL26: NAFISA NISFU SYABANA | AM26: P | AN26: X.B
A27: 18 | B27: 0097758689 / 15160 | C27: NABILA OKTAVIANI REFTI | D27: P | AD27: 0098735792 | AE27: Muh Arjuna Rifqi Oktavian | AF27: 87.09 | AG27: F | AH27: L | AK27: 0096843896 / 15170 | AL27: NAJWA ACHMAD | AM27: P | AN27: X.A
A28: 19 | B28: 0096843896 / 15170 | C28: NAJWA ACHMAD | D28: P | AD28: 0104230146 | AE28: MUHAMMAD KHAN | AF28: 86.64 | AG28: F | AH28: L | AK28: 0109049440 / 15173 | AL28: NAJWA NAYLA NURRAMADHANI | AM28: P | AN28: X.C
A29: 20 | B29: 0097537767 / 15172 | C29: NAJWA MALAIKA NUR SHAFA | D29: P | AD29: 0092206920 | AE29: NAFIL FAYYADH NAZHIFILLAH | AF29: 87.85 | AG29: F | AH29: P | AK29: 0093300159 / 15176 | AL29: NAURA ASTILA BELINDA | AM29: P | AN29: X.C
A30: 21 | B30: 0109049440 / 15173 | C30: NAJWA NAYLA NURRAMADHANI | D30: P | AD30: 94576750 | AE30: NAURA SYAWALIA AZMI | AF30: 85.02 | AG30: F | AH30: P | AK30: 0095576452 / 15182 | AL30: NAYLA NAZHIRANUHA | AM30: P | AN30: X.H
A31: 22 | B31: 0093300159 / 15176 | C31: NAURA ASTILA BELINDA | D31: P | AD31: 0091417231 | AE31: Nayaka Aulia Hariyanto | AF31: 88.34 | AG31: F | AH31: P | AK31: 0106124368 / 15186 | AL31: NENSI MELANI PUTRI | AM31: P | AN31: X.B
A32: 23 | B32: 0106124368 / 15186 | C32: NENSI MELANI PUTRI | D32: P | AD32: 0094659505 | AE32: NOVEL ALFIAN | AF32: 83.51 | AG32: F | AH32: L | AK32: 0106063120 / 15189 | AL32: NIKEISHA RAYYA SANDRICA | AM32: P | AN32: X.J
A33: 24 | B33: 0096501202 / 15193 | C33: NUR AFNI MARISA HENDRI | D33: P | AD33: 0109931684 | AE33: Raka Febrianto Chairul Putra | AF33: 86.81 | AG33: F | AH33: L | AK33: 0096501202 / 15193 | AL33: NUR AFNI MARISA HENDRI | AM33: P | AN33: X.E
A34: 26 | B34: 0095712895 / 15202 | C34: NURUS SAFIROTUR ROHMAH | D34: P | AD34: 101073797 | AE34: RIVA ARRIDHO MAULANA | AF34: 84.72 | AG34: F | AH34: L | AK34: 0095712895 / 15202 | AL34: NURUS SAFIROTUR ROHMAH | AM34: P | AN34: X.C
A35: 27 | B35: 0096041224 / 15219 | C35: RAKA TARUNA PERMANA | D35: L | AD35: 97996968 | AE35: SEPTIAN CAHYA RAMADHAN | AF35: 80.23 | AG35: F | AH35: L | AK35: 0096041224 / 15219 | AL35: RAKA TARUNA PERMANA | AM35: L | AN35: X.B
A36: 28 | B36: 0104297817 / 15223 | C36: RANINDEA PUTRI ARIFIN | D36: P | AD36: 92876045 | AE36: SEPTIAZHA BILQIST PUTRI LILYANA | AF36: 85.84 | AG36: F | AH36: P | AK36: 0104297817 / 15223 | AL36: RANINDEA PUTRI ARIFIN | AM36: P | AN36: X.I
A37: 29 | B37: 0107810106 / 15225 | C37: RATIH PRATIDINA ISHAK | D37: P | AD37: 106287537 | AE37: SERLIN MARWAH AYUNINGTYAS | AF37: 83.93 | AG37: F | AH37: P | AK37: 0107810106 / 15225 | AL37: Ratih Pratidina Ishak | AM37: P | AN37: X.J
A38: 30 | B38: 0109273017 / 15226 | C38: RATNADEWATI FREDLINA PUTRI | D38: P | AD38: 0102160338 | AE38: Walidatul Istianah Mannan | AF38: 88.34 | AG38: F | AH38: P | AK38: 0109273017 / 15226 | AL38: Ratnadewati Fredlina Putri | AM38: P | AN38: X.H
A39: 31 | B39: 0098500710 / 15239 | C39: ROFIENDRA ZACKY AHMAD | D39: L | AD39: 0107029603 | AE39: Wilbert Wang | AF39: 87.57 | AG39: F | AH39: L | AK39: 0098500710 / 15239 | AL39: ROFIENDRA ZACKY AHMAD | AM39: L | AN39: X.B
A40: 32 | B40: 0103816414 / 15242 | C40: ROZITA AMALINA DINI | D40: P | AD40: 0101495303 | AE40: WILDA FAGARINA | AF40: 82.58 | AG40: F | AH40: P | AK40: 0103816414 / 15242 | AL40: ROZITA AMALINA DINI | AM40: P | AN40: X.E
A41: 33 | B41: 0106287537 / 15255 | C41: SERLIN MARWAH AYUNINGTYAS | D41: P | AD41: 97549501 | AE41: YORIS APRILIA NINGTYAS | AF41: 86.15 | AG41: F | AH41: P
A42: 34 | B42: 0096046595 / 15270 | C42: SYAFANIA KIRANA PUTRI S. | D42: P | AD42: 0098425168 | AE42: ZAHRA NURANI FARIZA | AF42: 83.18 | AG42: F | AH42: P | AK42: 0106287537 / 15255 | AL42: SERLIN MARWAH AYUNINGTYAS | AM42: P | AN42: X.F
A43: 35 | B43: 0096659826 / 15276 | C43: SYIRIN | D43: P | AD43: 0098138581 | AE43: ZATRYA WAHYU PRATAMA | AF43: 90.11 | AG43: F | AH43: L | AK43: 0096046595 / 15270 | AL43: SYAFANIA KIRANA PUTRI S. | AM43: P | AN43: X.B
A44: 25 | B44: 0107029603 / 15287 | C44: WILBERT WANG | D44: L | AK44: 0107029603 / 15287 | AL44: Wilbert Wang | AM44: L | AN44: X.F
A45: 36 | B45: 0099410638 / 15297 | C45: ZALFA AULIA GAMILA | D45: P | AK45: 0099410638 / 15297 | AL45: ZALFA AULIA GAMILA | AM45: P | AN45: X.B
A46: Paraf | C46: L : | D46: =COUNTIFS($D$10:$D$45,"L") -> 8
...

Sheet XI-C
A4: Tahun Pelajaran 2026 / 2027
A7: No | B7: NISN/ NIS | C7: Nama Siswa | D7: L/P | E7: Wali Kelas : | H7: RIZKY SAPUTRA MARIYONO, M.Pd | S7: NIP : | U7: 199403262025211098
E8: Tanggal
A10: 1 | B10: 0106246139 / 14963 | C10: AHMAD NAJIBUL KHAIR | D10: L | AD10: 93002126 | AE10: AHMAD GHATAN AS SALAFI | AF10: 83.92 | AG10: G | AH10: L | AK10: 1 | AL10: 0106246139 / 14963 | AM10: Ahmad Najibul Khair | AN10: L
A11: 2 | B11: 0095982980 / 14965 | C11: AHMAD RAYHAN WICAKSONO | D11: L | AD11: 0095982980 | AE11: Ahmad Rayhan Wicaksono | AF11: 88.32 | AG11: G | AH11: L | AK11: 2 | AL11: 0095982980 / 14965 | AM11: Ahmad Rayhan Wicaksono | AN11: L
A12: 3 | B12: 0106042238 / 15011 | C12: AURA PRIYA GANGGA PRAKUSYA | D12: P | AD12: 0091486816 | AE12: ALIYYA WAHYU SHOFIYANI | AF12: 86.61 | AG12: G | AH12: P | AK12: 3 | AL12: 0106042238 / 15011 | AM12: AURA PRIYA GANGGA PRAKUSYA | AN12: P
A13: 4 | B13: 0101272695 / 15014 | C13: AURELIA FIRMANSYAH | D13: P | AD13: 0099550894 | AE13: ALMIRAH DISTI NAURA | AF13: 86.52 | AG13: G | AH13: P | AK13: 4 | AL13: 0101272695 / 15014 | AM13: AURELIA FIRMANSYAH | AN13: P
A14: 5 | B14: 0097582178 / 15029 | C14: BARA PRAMUDYA PUTRA NUGRAHA | D14: L | AD14: 0093742373 | AE14: ALVINA NIKMATUR RAIFA | AF14: 86.58 | AG14: G | AH14: P | AK14: 5 | AL14: 0094840732 / 15039 | AM14: Cantika Safitri Wijayanti | AN14: P
A15: 6 | B15: 0094840732 / 15039 | C15: CANTIKA SAFITRI WIJAYANTI | D15: P | AD15: 97551688 | AE15: AR RASYA YAHYA HUDAYA | AF15: 81.98 | AG15: G | AH15: L | AK15: 6 | AL15: 0098060781 / 15049 | AM15: DHIYA SYAHIRA ATIKA RIZKY | AN15: P
A16: 7 | B16: 0098060781 / 15049 | C16: DHIYA SYAHIRA ATIKA RIZKY | D16: P | AD16: 106587992 | AE16: ASYRAF ABDILLAH MOHALLIS | AF16: 80.17 | AG16: G | AH16: L | AK16: 7 | AL16: 0096480979 / 15067 | AM16: FIQRI ZULKIFLI ROFIQIN SYAH | AN16: L
A17: 8 | B17: 0096480979 / 15067 | C17: FIQRI ZULKIFLI ROFIQIN SYAH | D17: L | AD17: 0094556159 | AE17: AUFA NADHIF | AF17: 89.43 | AG17: G | AH17: L | AK17: 8 | AL17: 0102498373 / 15068 | AM17: FIRSYA RAMANSYAH PUTRI R | AN17: P
A18: 9 | B18: 0103741538 / 15073 | C18: GEVAN DANIEL APRADINATA | D18: L | AD18: 109396702 | AE18: AULIA KASIH MAULIDATURROHMAH | AF18: 83.2 | AG18: G | AH18: P | AK18: 9 | AL18: 0103741538 / 15073 | AM18: Gevan Daniel Apradinata | AN18: L
A19: 10 | B19: 0105049596 / 15075 | C19: HAFIZA HUMAIRA WACHDIN | D19: P | AD19: 0105465852 | AE19: BALQIS KIRANA LARASATI | AF19: 89.26 | AG19: G | AH19: P | AK19: 10 | AL19: 0105049596 / 15075 | AM19: HAFIZA HUMAIRA WACHDIN | AN19: P
A20: 11 | B20: 0099405271 / 15076 | C20: HARYA PANDU ELYANTA PIO | D20: L | AD20: 0107129633 | AE20: CHIKA NANDA FEBRIO | AF20: 86.92 | AG20: G | AH20: P | AK20: 11 | AL20: 0099405271 / 15076 | AM20: HARYA PANDU ELYANTA PIO | AN20: L
A21: 12 | B21: 0108325753 / 15085 | C21: INDAH MAULIDIYA | D21: P | AD21: 0106425839 | AE21: DEWI ARDHANARESWARI P | AF21: 87.56 | AG21: G | AH21: P | AK21: 12 | AL21: 0108325753 / 15085 | AM21: INDAH MAULIDIYA | AN21: P
A22: 13 | B22: 0094023023 / 15091 | C22: IVA NUR AULYANA REZA | D22: P | AD22: 91699738 | AE22: EKA SUSANTI | AF22: 84.27 | AG22: G | AH22: P | AK22: 13 | AL22: 0094023023 / 15091 | AM22: IVA NUR AULYANA REZA | AN22: P
A23: 14 | B23: 0092041781 / 15106 | C23: KHANZA HUMAIRA AZZAHWA | D23: P | AD23: 0094950484 | AE23: Enza Sabrina Heryanto | AF23: 84.11 | AG23: G | AH23: P | AK23: 14 | AL23: 0092041781 / 15106 | AM23: KHANZA HUMAIRA AZZAHWA | AN23: P
A24: 15 | B24: 0094213234 / 15120 | C24: MARSYA YULIA PUTRI | D24: P | AD24: 0096040095 | AE24: Finza Ayu Gusti Arini Putri S | AF24: 86.78 | AG24: G | AH24: P | AK24: 15 | AL24: 0094213234 / 15120 | AM24: Marsya Yulia Putri | AN24: P
A25: 16 | B25: 0109850534 / 15122 | C25: MAULANI CHAIMI MOCHSIM | D25: P | AD25: 104756008 | AE25: GESTA NOVANDA PUTRA GS | AF25: 82.01 | AG25: G | AH25: L | AK25: 16 | AL25: 0109850534 / 15122 | AM25: MAULANI CHAIMI MOCHSIM | AN25: P
A26: 17 | B26: 0106391246 / 15123 | C26: MAULIDYA DWI MAHARANI | D26: P | AD26: 0094505361 | AE26: HUMAIRA INDA NALA ZULFA | AF26: 84.87 | AG26: G | AH26: P | AK26: 17 | AL26: 0106391246 / 15123 | AM26: MAULIDYA DWI MAHARANI | AN26: P
A27: 18 | B27: 0099668691 / 15127 | C27: MILDY PRIO RUBIANTO | D27: L | AD27: 0092118447 | AE27: Indah Mailatus Syafa | AF27: 87.66 | AG27: G | AH27: P | AK27: 18 | AL27: 0099668691 / 15127 | AM27: MILDY PRIO RUBIANTO | AN27: L
A28: 19 | B28: 0093877127 / 15133 | C28: MOH. GILANG ERLANGGA | D28: L | AD28: 0093953878 | AE28: KHANSA VITA HARIJATNO | AF28: 83.51 | AG28: G | AH28: P | AK28: 19 | AL28: 0093877127 / 15133 | AM28: Moh. Gilang Erlangga | AN28: L
A29: 20 | B29: 0098777177 / 15140 | C29: MOH. RIFAL UKROMULLAH | D29: L | AD29: 94683167 | AE29: LADY HARI KHADIJAH | AF29: 84.61 | AG29: G | AH29: P | AK29: 20 | AL29: 0098777177 / 15140 | AM29: MOH. RIFAL UKROMULLAH | AN29: L
A30: 21 | B30: 0101099158 / 15152 | C30: MOHAMMAD ULUL AZMI | D30: L | AD30: 0109850534 | AE30: MAULANI CHAIMI MOCHSIM | AF30: 90.11 | AG30: G | AH30: P | AK30: 21 | AL30: 0101099158 / 15152 | AM30: MOHAMMAD ULUL AZMI | AN30: L
A31: 22 | B31: 0108486609 / 15158 | C31: MUSDALIFAH | D31: P | AD31: 0101141245 | AE31: NAJMIA ISNAINI APRILIA | AF31: 87.33 | AG31: G | AH31: P | AK31: 22 | AL31: 0108486609 / 15158 | AM31: MUSDALIFAH | AN31: P
A32: 23 | B32: 0096593023 / 15179 | C32: NAUREHAL PASAI | D32: P | AD32: 0099599176 | AE32: NURIL AKMAL FIRDAUS | AF32: 88.34 | AG32: G | AH32: L | AK32: 23 | AL32: 0096593023 / 15179 | AM32: NAUREHAL PASAI | AN32: P
A33: 24 | B33: 3098293614 / 15185 | C33: NAZWA NURAISYAH | D33: P | AD33: 95654087 | AE33: PUTRI AGUSTINA MAHARDIKA | AF33: 85.81 | AG33: G | AH33: P | AK33: 24 | AL33: 3098293614 / 15185 | AM33: NAZWA NURAISYAH | AN33: P
A34: 25 | B34: 0105111329 / 15187 | C34: NESYALIENA ALIFIA RASYIDI | D34: P | AD34: 104164486 | AE34: Rafi Adi Cahyono | AF34: 86.12 | AG34: G | AH34: L | AK34: 25 | AL34: 0105111329 / 15187 | AM34: NESYALIENA ALIFIA RASYIDI | AN34: P
A35: 26 | B35: 0106880225 / 15198 | C35: NUR ZAHIRA ANSORULLAH | D35: P | AD35: 102676748 | AE35: Rameyza Chayyira | AF35: 84.97 | AG35: G | AH35: P | AK35: 26 | AL35: 0106880225 / 15198 | AM35: NUR ZAHIRA ANSORULLAH | AN35: P
A36: 27 | B36: 0099202101 / 15203 | C36: OKTAVIA AYU NINGTIYAS | D36: P | AD36: 0098990180 | AE36: RChelsyana Ramadhani J | AF36: 87.83 | AG36: G | AH36: P | AJ36: ada di nomor29 | AK36: 27 | AL36: 0099202101 / 15203 | AM36: OKTAVIA AYU NINGTIYAS | AN36: P
A37: 28 | B37: 0097120646 / 15211 | C37: RACHMANISYA APRILYA | D37: P | AD37: 94577372 | AE37: RIO INDRA PRATAMA | AF37: 83.68 | AG37: G | AH37: L | AJ37: rolling ke no 27 | AK37: 28 | AL37: 0097120646 / 15211 | AM37: RACHMANISYA APRILYA | AN37: P
A38: 29 | B38: 0107040234 / 15227 | C38: RATU KAYYISAH YAMANIYYAH BUDIARTA | D38: P | AD38: 0102393499 | AE38: RONA BARIZAH NAFISAH SALSABILA | AF38: 87.41 | AG38: G | AH38: P | AK38: 29 | AL38: 0107040234 / 15227 | AM38: RATU KAYYISAH YAMANIYYAH BUDIARTA | AN38: P
A39: 30 | B39: 0094493950 / 15258 | C39: SHAFIRA HAMID | D39: P | AD39: 0109277278 | AE39: SAFA NUR AQILAH RAHMAN | AF39: 86.98 | AG39: G | AH39: P | AK39: 30 | AL39: 0094493950 / 15258 | AM39: SHAFIRA HAMID | AN39: P
A40: 31 | B40: 0093872317 / 15261 | C40: SHANDHY AULIYA LESTARY | D40: P | AD40: 0092933531 | AE40: SALWA RAHMA MYLINDA | AF40: 83.17 | AG40: G | AH40: P | AK40: 31 | AL40: 0093872317 / 15261 | AM40: SHANDHY AULIYA LESTARY | AN40: P
A41: 32 | B41: 0096615983 / 15265 | C41: SITTI SHOFIA | D41: P | AD41: 0093872317 | AE41: SHANDHY AULIYA LESTARY | AF41: 82.57 | AG41: G | AH41: P | AK41: 32 | AL41: 0096615983 / 15265 | AM41: SITTI SHOFIA | AN41: P
A42: 33 | B42: 0096256266 / 15267 | C42: SURYA DAFFA MAHARDHIKA ALY | D42: L | AL42: 0096256266 / 15267 | AM42: SURYA DAFFA MAHARDHIKA ALY | AN42: L
A43: 34 | B43: 0108382917 / 15272 | C43: SYARIFATUL AISYAH | D43: P | AL43: 0108382917 / 15272 | AM43: SYARIFATUL AISYAH | AN43: P
A44: 35 | B44: 0101166292 / 15281 | C44: UKHTI FARATINA NUR AFINY | D44: P | AD44: 0103239495 | AE44: SULTAN KAFA RASTRA SUGIANTO | AF44: 86.06 | AG44: G | AH44: L | AK44: 33 | AL44: 0101166292 / 15281 | AM44: UKHTI FARATINA NUR AFINY | AN44: P
A45: 36 | B45: 0103002672 / 15292 | C45: YUSRIZAL TAUFIQ ABDILLAH | D45: L | AD45: 0091987933 | AE45: WILDA AFRILIA | AF45: 85.63 | AG45: G | AH45: P | AK45: 34 | AL45: 0103002672 / 15292 | AM45: YUSRIZAL TAUFIQ ABDILLAH | AN45: L
B46: Paraf | C46: L : | D46: =COUNTIFS($D$10:$D$45,"L") -> 12
...

Sheet XI-D
A4: Tahun Pelajaran 2026 / 2027
A7: No | B7: NISN / NIS | C7: Nama Siswa | D7: L/P | E7: Wali Kelas : | H7: RACHMI SYAFARIN, S.Pd | S7: NIP : | U7: 1.9720407e+17
E8: Tanggal
AC9: 8
A10: 1 | B10: 0103387807 / 14955 | C10: ACHMAD WILDAN CAHYA SANUBARI | D10: L | AE10: 0099058533 | AF10: ACH ALFIANSYA SEPTEO RAMADHANI | AG10: 86.92 | AH10: H | AI10: L
A11: 2 | B11: 0101733365 / 14958 | C11: AGUNG MULYA PRATAMA | D11: L | AE11: 0102988393 | AF11: ALFINA DIAH ANGGRAINI | AG11: 87.38 | AH11: H | AI11: P
A12: 3 | B12: 0106556562 / 14962 | C12: AHMAD KUSWANDI | D12: L | AE12: 94851511 | AF12: ALI RIDHO FATHORRAHMAN | AG12: 81.88 | AH12: H | AI12: L
A13: 4 | B13: 0108003625 / 14967 | C13: AINUR FADYLA | D13: P | AE13: 0109410681 | AF13: ARLKA WISNU WARDANA | AG13: 86.53 | AH13: H | AI13: L
A14: 5 | B14: 0102964984 / 14971 | C14: ALDAFA ZACKY AGUSTIAN | D14: L | AE14: 0095005653 | AF14: AULIYATUL RAZNI AMALIYA | AG14: 897.59 | AH14: H | AI14: P
A15: 6 | B15: 0094851511 / 14975 | C15: ALI RIDHO FATHORRAHMAN | D15: L | AE15: 105174754 | AF15: AURELIA RAISSA APRIANDYTA | AG15: 83.9 | AH15: H | AI15: P
A16: 7 | B16: 0097551688 / 14992 | C16: AR RASYA YAHYA HUDAYA | D16: L | AE16: 0102322274 | AF16: AYU RIZKI PUJI LESTARI | AG16: 86.76 | AH16: H | AI16: P
A17: 8 | B17: 0107357333 / 15006 | C17: AULIA DIKKRI SHAFIALLAH | D17: L | AE17: 0092822070 | AF17: AZARINE BELVINA WAHYUDI | AG17: 87.64 | AH17: H | AI17: P
A18: 9 | B18: 0098648934 / 15017 | C18: AURYN NUR ANABELA | D18: P | AE18: 0099364614 | AF18: Azriel Sabilillah Arkana | AG18: 88.85 | AH18: H | AI18: L
A19: 10 | B19: 0093003989 / 15026 | C19: AZZAHRA ARIF DAMAYANTI | D19: P | AE19: 0105382139 | AF19: Bilqis Fathiya Martha D | AG19: 88.14 | AH19: H | AI19: P
A20: 11 | B20: 0096559029 / 15037 | C20: CAMILIA LUQYANA ZULFA | D20: P | AE20: 96559029 | AF20: CAMILIA LUQYANA ZULFA | AG20: 84.26 | AH20: H | AI20: P
A21: 12 | B21: 0093782050 / 15048 | C21: DHAFINA PUTRI ARIFIN | D21: P | AE21: 0096183358 | AF21: EKA PUTRI INDAH AYU LESTARI | AG21: 85.50 | AH21: H | AI21: P
A22: 13 | B22: 0109089490 / 15050 | C22: DIAH KANZA NAILA | D22: P | AE22: 0109363761 | AF22: Fakhira Maulida Algifari | AG22: 86.48 | AH22: H | AI22: P
A23: 14 | B23: 0091699738 / 15055 | C23: EKA SUSANTI | D23: P | AE23: 103496356 | AF23: HUGA ZAMRONI AJI | AG23: 86.1 | AH23: H | AI23: L
A24: 15 | B24: 0091889511 / 15057 | C24: ERINA BALQIS SABITA | D24: P
A25: 16 | B25: 0095217817 / 15077 | C25: HASNA ALGHINA RACHMAN | D25: P | AE25: 98243995 | AF25: INTAN NOVI DWIARINI | AG25: 84.92 | AH25: H | AI25: P
A26: 17 | B26: 0092118447 / 15084 | C26: INDAH MAILATUS SYAFA | D26: P | AE26: 94023023 | AF26: IVA NUR AULYANA REZA | AG26: 83.65 | AH26: H | AI26: P
A27: 18 | B27: 0104825564 / 15099 | C27: KEVIN PUTRA NIRWANA | D27: L | AE27: 0108350178 | AF27: JANUAR RAFI GUNAWAN | AG27: 86.97 | AH27: H | AI27: L
A28: 19 | B28: 0095739171 / 15100 | C28: KEYRANI LARASATI NINGRUM | D28: P | AE28: 0092041781 | AF28: KHANZA HUMAIRA AZZAHWA | AG28: 88.29 | AH28: H | AI28: P
A29: 20 | B29: 0093300658 / 15101 | C29: KHAIRIL FIRDAUS ALFARISI | D29: L | AE29: 0101240753 | AF29: M SAFARIL IDHOM | AG29: 87.32 | AH29: H | AI29: L
A30: 21 | B30: 0093953878 / 15105 | C30: KHANSA VITA HARIJATNO | D30: P | AE30: 106391246 | AF30: MAULIDYA DWI MAHARANI | AG30: 83.18 | AH30: H | AI30: P
A31: 22 | B31: 0099738844 / 15141 | C31: MOH. SAHLAN | D31: L | AE31: 0107399996 | AF31: MOH BAGUS AKBAR | AG31: 83.14 | AH31: H | AI31: L
A32: 23 | B32: 0106779710 / 15144 | C32: MOH. ZULFIKAR MASA BAKTI | D32: L | AE32: 0098021802 | AF32: MOH RAFI NUR HIDAYAT | AG32: 82.47 | AH32: H | AI32: L
A33: 24 | B33: 0098735792 / 15153 | C33: MUH. ARJUNA RIFQI OKTAVIAN | D33: L | AE33: 108486609 | AF33: MUSDALIFAH | AG33: 81.84 | AH33: H | AI33: P
A34: 25 | B34: 0098252155 / 15154 | C34: MUHAMMAD AFDHAN SYAQURO | D34: L | AE34: 0097758689 | AF34: NABILA OKTAVIANI REFTI | AG34: 83.45 | AH34: H | AI34: P
A35: 26 | B35: 0106600416 / 15163 | C35: NADHIFIA AZZAHRA ANUGRAINI | D35: P | AE35: 0095576452 | AF35: NAYLA NAZHIRANUHA | AG35: 89.18 | AH35: H | AI35: P
A36: 27 | B36: 0093307160 / 15181 | C36: NAYLA KHANZA SYAZTIAN | D36: P | AE36: 0105111329 | AF36: NESYALIENA ALIFIA RASYIDI | AG36: 86.06 | AH36: H | AI36: P
A37: 28 | B37: 0094659505 / 15192 | C37: NOVEL ALFIAN | D37: L | AE37: 0107213872 | AF37: NURIN ALAMSYAH | AG37: 86.6 | AH37: H | AI37: P
A38: 29 | B38: 0094577372 / 15235 | C38: RIO INDRA PRATAMA | D38: L | AE38: 0109273017 | AF38: Ratnadewati Fredlina Putri | AG38: 84.05 | AH38: H | AI38: P
A39: 30 | B39: 0106201622 / 15251 | C39: SATRIA ZETA PUTRA ARDYANZAH | D39: L | AE39: 0108858362 | AF39: REZA ACHMAD PASHA ISLAMI | AG39: 87.79 | AH39: H | AI39: L
A40: 31 | B40: 0099585326 / 15252 | C40: SEPTIA RAMADINA NURSYAMSI | D40: P | AE40: 94493950 | AF40: SHAFIRA HAMID | AG40: 84.61 | AH40: H | AI40: P
A41: 32 | B41: 0102316553 / 15274 | C41: SYIFA ATI RATNADUHITA WIJAYANTI | D41: P | AE41: 97450728 | AF41: SYIFA ANISATUL AMALIYA | AG41: 85.62 | AH41: H | AI41: P
A42: 33 | B42: 0108698195 / 15278 | C42: TANTRA AUFAREZKA MULIAWAN | D42: L
A43: 34 | B43: 0104446871 / 15279 | C43: TRIANA AYU DIYA SAFITRI | D43: P
A44: 35 | B44: 0102160338 / 15285 | C44: WALIDATUL ISTI'ANAH MANNAN | D44: P | AE44: 0108074622 | AF44: VINDYANA INDIRA OCTAVIA | AG44: 87.55 | AH44: H | AI44: P
A45: 36 | B45: 0108323553 / 15290 | C45: WIRA REDIKA PRATAMA | D45: L | AE45: 108323553 | AF45: WIRA REDIKA PRATAMA | AG45: 80.15 | AH45: H | AI45: L
...

Sheet XI-E
A4: Tahun Pelajaran 2026 / 2027
A7: No | B7: NISN / NIS | C7: Nama Siswa | D7: L/P | E7: Wali Kelas : | H7: MISNADI, S.Pd.I | S7: NIP : | U7: 197310012024211002
E8: Tanggal
AC9: 8
A10: 1 | B10: 0101958421 / 14970 | C10: AKBAR MAULANA | D10: L | AE10: 95345053 | AF10: AHMAD FAHRI | AG10: 84.24 | AH10: I | AI10: L
A11: 2 | B11: 0104665288 / 14995 | C11: ARSYA DAYU AZAHRA | D11: P | AE11: 0106556562 | AF11: AHMAD KUSWANDI | AG11: 86.47 | AH11: I | AI11: L
A12: 3 | B12: 0101774043 / 14996 | C12: ARTI QURROTUL HASANAH | D12: P | AE12: 108003625 | AF12: AINUR FADYLA | AG12: 83.59 | AH12: I | AI12: P
A13: 4 | B13: 0106587992 / 15001 | C13: ASYRAF ABDILLAH MOHALLIS | D13: L | AE13: 99897605 | AF13: ALYSA TUNGGA PRATIWI | AG13: 81.73 | AH13: I | AI13: P
A14: 5 | B14: 0095911412 / 15031 | C14: BERLIAN CALLISTA MAHERA | D14: P | AE14: 94292240 | AF14: ANIN WIDIA PUTRI | AG14: 84.56 | AH14: I | AI14: P
A15: 6 | B15: 0092553825 / 15045 | C15: DESWITA PUTRI DAYANTI | D15: P | AE15: 0103293275 | AF15: ASHYLA NURI ADISTY | AG15: 87.75 | AH15: I | AI15: P
A16: 7 | B16: 0096040095 / 15066 | C16: FINZA AYU GUSTI ARINI PUTRI S | D16: P | AE16: 0096329996 | AF16: AULIA AGUSTINING TIYAS SUMANTRI | AG16: 82.31 | AH16: I | AI16: P
A17: 8 | B17: 0102498373 / 15068 | C17: FIRSYA RAMANSYAH PUTRI R | D17: P | AE17: 0098345910 | AF17: Aura Suci Ramadhani | AG17: 88.16 | AH17: I | AI17: P
A18: 9 | B18: 0094505361 / 15080 | C18: HUMAIRA INDA NALA ZULFA | D18: P | AE18: 0093756454 | AF18: DENIEL CAHYA RAHMAN PRATAMA | AG18: 86.74 | AH18: I | AI18: L
A19: 10 | B19: 0094683167 / 15108 | C19: LADY HARI KHADIJAH | D19: P | AE19: 0102661592 | AF19: FAKHIRA INAS | AG19: 87.53 | AH19: I | AI19: P
